Workbook

Sheet 使用说明
A1: 个人财务分析模板：极简输入 + 加拿大消费税估算版
A2: 只填写总支出、总收入、输入设置、税费设置；其他页面自动计算。
A3: 项目 | B3: 说明
A4: 使用目标 | B4: 用最少输入列记录个人收支，并自动生成月度现金流、类别占比、年度消费预测、备用金、可投资资金与消费税估算。
A5: 每月维护 | B5: 只追加新支出、新收入；必要时更新当前现金、备用金月数、税率或是否启用消费税估算。
A6: 金额规则 | B6: 支出页与收入页均填正数。
A7: 税费规则 | B7: 税费类型可选“自动”，也可手动选择零税率、应税、免税、含税不明、不适用。
A8: 示例数据 | B8: 内置2026年1月与2月示例样本；1月总支出5000，房租3000，占本月支出60%。
A10: 日常维护流程
A11: 1. 在“总支出”追加支出记录，金额填正数。
A12: 2. 在“总收入”追加收入记录，金额填正数。
A13: 3. 如现金余额、备用金月数或税率变化，更新“输入设置”和“税费设置”。
A14: 4. 查看“总览”；若需要排查，再看“公式枢纽”“税费计算明细”。
A15: 5. 消费税估算是近似分析，不等于实际退税、抵扣或福利金额。

Sheet 总览
A1: 个人财务分析总览
A2: 本页是主要查看页面；所有数字均引用公式枢纽。
A3: 平均月支出 | D3: 必要月支出 | G3: 弹性月支出 | J3: 正常一年储备
A4: =公式枢纽!$B$7 -> 5150 | D4: =公式枢纽!$B$8 -> 4000 | G4: =公式枢纽!$B$9 -> 1150 | J4: =公式枢纽!$B$17 -> 61800
A7: 现金覆盖月数 | D7: 建议可投资资金 | G7: 全年估算消费税 | J7: 消费税估算状态
A8: =公式枢纽!$B$16 -> 5.8252427 | D8: =公式枢纽!$B$21 -> 0 | G8: =公式枢纽!$B$24 -> 318.45075 | J8: =公式枢纽!$B$25 -> 已启用
A12: 判断摘要
A13: 现金安全等级 | B13: =公式枢纽!$B$23 -> 偏紧张
A14: 资金建议 | B14: =IF(公式枢纽!$B$22>0,"当前现金储备仍有缺口，优先补足备用金",IF(公式枢纽!$B$21>0,"有可考虑分批投资的资金区间","请先在输入设置填入当前现金")) -> 当前现金储备仍有缺口，优先补足备用金
A15: 消费税说明 | B15: =IF(税费设置!$B$5="是","消费税估算已启用；请注意该估算不等于实际退税或抵扣金额","消费税估算未启用") -> 消费税估算已启用；请注意该估算不等于实际退税或抵扣金额
A19: 图表数据索引：月度收支与消费税 | G19: 图表数据索引：类别月均与占比
A20: 月份 | B20: 收入 | C20: 个人支出 | D20: 估算消费税 | E20: 净现金流 | G20: 类别 | H20: 月均 | I20: 占比
A21: =每月总结!A4 -> 2026-01 | B21: =每月总结!B4 -> 6000 | C21: =每月总结!C4 -> 5000 | D21: =公式枢纽!O28 -> 148.4801 | E21: =公式枢纽!J28 -> 1000 | G21: =各类别总结!A4 -> 住房 | H21: =各类别总结!N4 -> 3000 | I21: =各类别总结!P4 -> 0.58252427
A22: =每月总结!A5 -> 2026-02 | B22: =每月总结!B5 -> 6900 | C22: =每月总结!C5 -> 5300 | D22: =公式枢纽!O29 -> 169.97065 | E22: =公式枢纽!J29 -> 1600 | G22: =各类别总结!A5 -> 餐饮 | H22: =各类别总结!N5 -> 820 | I22: =各类别总结!P5 -> 0.1592233
A23: =每月总结!A6 -> 2026-03 | B23: =每月总结!B6 -> 0 | C23: =每月总结!C6 -> 0 | D23: =公式枢纽!O30 -> 0 | E23: =公式枢纽!J30 -> 0 | G23: =各类别总结!A6 -> 交通 | H23: =各类别总结!N6 -> 240 | I23: =各类别总结!P6 -> 0.046601942
A24: =每月总结!A7 -> 2026-04 | B24: =每月总结!B7 -> 0 | C24: =每月总结!C7 -> 0 | D24: =公式枢纽!O31 -> 0 | E24: =公式枢纽!J31 -> 0 | G24: =各类别总结!A7 -> 通讯 | H24: =各类别总结!N7 -> 60 | I24: =各类别总结!P7 -> 0.011650485
A25: =每月总结!A8 -> 2026-05 | B25: =每月总结!B8 -> 0 | C25: =每月总结!C8 -> 0 | D25: =公式枢纽!O32 -> 0 | E25: =公式枢纽!J32 -> 0 | G25: =各类别总结!A8 -> 订阅 | H25: =各类别总结!N8 -> 37.5 | I25: =各类别总结!P8 -> 0.0072815534
A26: =每月总结!A9 -> 2026-06 | B26: =每月总结!B9 -> 0 | C26: =每月总结!C9 -> 0 | D26: =公式枢纽!O33 -> 0 | E26: =公式枢纽!J33 -> 0 | G26: =各类别总结!A9 -> 购物 | H26: =各类别总结!N9 -> 275 | I26: =各类别总结!P9 -> 0.053398058
A27: =每月总结!A10 -> 2026-07 | B27: =每月总结!B10 -> 0 | C27: =每月总结!C10 -> 0 | D27: =公式枢纽!O34 -> 0 | E27: =公式枢纽!J34 -> 0 | G27: =各类别总结!A10 -> 医疗 | H27: =各类别总结!N10 -> 90 | I27: =各类别总结!P10 -> 0.017475728
A28: =每月总结!A11 -> 2026-08 | B28: =每月总结!B11 -> 0 | C28: =每月总结!C11 -> 0 | D28: =公式枢纽!O35 -> 0 | E28: =公式枢纽!J35 -> 0 | G28: =各类别总结!A11 -> 运动 | H28: =各类别总结!N11 -> 70 | I28: =各类别总结!P11 -> 0.013592233
A29: =每月总结!A12 -> 2026-09 | B29: =每月总结!B12 -> 0 | C29: =每月总结!C12 -> 0 | D29: =公式枢纽!O36 -> 0 | E29: =公式枢纽!J36 -> 0 | G29: =各类别总结!A12 -> 学习 | H29: =各类别总结!N12 -> 130 | I29: =各类别总结!P12 -> 0.025242718
A30: =每月总结!A13 -> 2026-10 | B30: =每月总结!B13 -> 0 | C30: =每月总结!C13 -> 0 | D30: =公式枢纽!O37 -> 0 | E30: =公式枢纽!J37 -> 0 | G30: =各类别总结!A13 -> 宠物 | H30: =各类别总结!N13 -> 95 | I30: =各类别总结!P13 -> 0.018446602
A31: =每月总结!A14 -> 2026-11 | B31: =每月总结!B14 -> 0 | C31: =每月总结!C14 -> 0 | D31: =公式枢纽!O38 -> 0 | E31: =公式枢纽!J38 -> 0 | G31: =各类别总结!A14 -> 娱乐 | H31: =各类别总结!N14 -> 110 | I31: =各类别总结!P14 -> 0.021359223
A32: =每月总结!A15 -> 2026-12 | B32: =每月总结!B15 -> 0 | C32: =每月总结!C15 -> 0 | D32: =公式枢纽!O39 -> 0 | E32: =公式枢纽!J39 -> 0 | G32: =各类别总结!A15 -> 税费 | H32: =各类别总结!N15 -> 125 | I32: =各类别总结!P15 -> 0.024271845
G33: =各类别总结!A16 -> 其他 | H33: =各类别总结!N16 -> 97.5 | I33: =各类别总结!P16 -> 0.018932039

Sheet 总支出
A1: 总支出
A2: 用户只需要填写本页作为支出页。支出金额请输入正数；依据分析口径、类别和税费类型完成统计。
A3: 记录编号 | B3: 日期 | C3: 支出内容 | D3: 支出金额 | E3: 主类别 | F3: 支出性质 | G3: 必要程度 | H3: 分析口径 | I3: 税费类型 | J3: 备注
A4: 支出-0001 | B4: 46023 | C4: 房租 | D4: 3000 | E4: 住房 | F4: 固定 | G4: 必要 | H4: 个人支出 | I4: 免税 | J4: 示例：1月总支出约5000，房租占60%
A5: 支出-0002 | B5: 46025 | C5: 超市基础食品：鸡蛋、蔬菜、牛奶 | D5: 450 | E5: 餐饮 | F5: 可变 | G5: 必要 | H5: 个人支出 | I5: 零税率 | J5: 基础食品通常按零税率演示
A6: 支出-0003 | B6: 46027 | C6: 餐厅外食 | D6: 320 | E6: 餐饮 | F6: 可变 | G6: 弹性 | H6: 个人支出 | I6: 应税 | J6: 餐厅和外卖通常应税
A7: 支出-0004 | B7: 46029 | C7: 加油 | D7: 220 | E7: 交通 | F7: 可变 | G7: 必要 | H7: 个人支出 | I7: 应税 | J7: 交通相关应税示例
A8: 支出-0005 | B8: 46030 | C8: 手机通讯费 | D8: 60 | E8: 通讯 | F8: 固定 | G8: 必要 | H8: 个人支出 | I8: 应税
A9: 支出-0006 | B9: 46031 | C9: 云服务订阅 | D9: 30 | E9: 订阅 | F9: 固定 | G9: 弹性 | H9: 个人支出 | I9: 应税
A10: 支出-0007 | B10: 46032 | C10: 衣物与日用品购物 | D10: 250 | E10: 购物 | F10: 可变 | G10: 弹性 | H10: 个人支出 | I10: 应税
A11: 支出-0008 | B11: 46034 | C11: 药品和医疗用品 | D11: 80 | E11: 医疗 | F11: 可变 | G11: 必要 | H11: 个人支出 | I11: 免税 | J11: 仅作模板示例，实际以收据为准
A12: 支出-0009 | B12: 46037 | C12: 健身房月费 | D12: 70 | E12: 运动 | F12: 固定 | G12: 弹性 | H12: 个人支出 | I12: 应税
A13: 支出-0010 | B13: 46038 | C13: 课程与书籍 | D13: 120 | E13: 学习 | F13: 一次性 | G13: 弹性 | H13: 个人支出 | I13: 含税不明 | J13: 学习类税费取决于具体项目
A14: 支出-0011 | B14: 46040 | C14: 宠物食品和用品 | D14: 90 | E14: 宠物 | F14: 可变 | G14: 弹性 | H14: 个人支出 | I14: 应税
A15: 支出-0012 | B15: 46042 | C15: 电影和游戏娱乐 | D15: 100 | E15: 娱乐 | F15: 可变 | G15: 弹性 | H15: 个人支出 | I15: 应税
A16: 支出-0013 | B16: 46047 | C16: 政府费用 | D16: 100 | E16: 税费 | F16: 一次性 | G16: 必要 | H16: 个人支出 | I16: 不适用 | J16: 政府收费不纳入消费税估算
A17: 支出-0014 | B17: 46050 | C17: 其他杂项 | D17: 110 | E17: 其他 | F17: 可变 | G17: 弹性 | H17: 个人支出 | I17: 含税不明
A18: 支出-0015 | B18: 46054 | C18: 房租 | D18: 3000 | E18: 住房 | F18: 固定 | G18: 必要 | H18: 个人支出 | I18: 免税 | J18: 示例：2月有一定波动
A19: 支出-0016 | B19: 46056 | C19: 超市基础食品：水果、蔬菜、面包 | D19: 520 | E19: 餐饮 | F19: 可变 | G19: 必要 | H19: 个人支出 | I19: 零税率
A20: 支出-0017 | B20: 46058 | C20: 餐厅聚餐 | D20: 350 | E20: 餐饮 | F20: 可变 | G20: 弹性 | H20: 个人支出 | I20: 应税
A21: 支出-0018 | B21: 46059 | C21: 车辆加油与停车 | D21: 260 | E21: 交通 | F21: 可变 | G21: 必要 | H21: 个人支出 | I21: 应税
A22: 支出-0019 | B22: 46061 | C22: 手机通讯费 | D22: 60 | E22: 通讯 | F22: 固定 | G22: 必要 | H22: 个人支出 | I22: 应税
A23: 支出-0020 | B23: 46063 | C23: 软件订阅 | D23: 45 | E23: 订阅 | F23: 固定 | G23: 弹性 | H23: 个人支出 | I23: 应税
A24: 支出-0021 | B24: 46064 | C24: 衣物购物 | D24: 300 | E24: 购物 | F24: 可变 | G24: 弹性 | H24: 个人支出 | I24: 应税
A25: 支出-0022 | B25: 46066 | C25: 医疗用品 | D25: 100 | E25: 医疗 | F25: 可变 | G25: 必要 | H25: 个人支出 | I25: 免税
A26: 支出-0023 | B26: 46068 | C26: 健身房月费 | D26: 70 | E26: 运动 | F26: 固定 | G26: 弹性 | H26: 个人支出 | I26: 应税
A27: 支出-0024 | B27: 46070 | C27: 线上课程 | D27: 140 | E27: 学习 | F27: 一次性 | G27: 弹性 | H27: 个人支出 | I27: 含税不明
A28: 支出-0025 | B28: 46072 | C28: 宠物用品 | D28: 100 | E28: 宠物 | F28: 可变 | G28: 弹性 | H28: 个人支出 | I28: 应税
A29: 支出-0026 | B29: 46074 | C29: 娱乐活动 | D29: 120 | E29: 娱乐 | F29: 可变 | G29: 弹性 | H29: 个人支出 | I29: 应税
A30: 支出-0027 | B30: 46076 | C30: 政府费用 | D30: 150 | E30: 税费 | F30: 一次性 | G30: 必要 | H30: 个人支出 | I30: 不适用
A31: 支出-0028 | B31: 46079 | C31: 其他杂项 | D31: 85 | E31: 其他 | F31: 可变 | G31: 弹性 | H31: 个人支出 | I31: 含税不明
I32: 自动

Sheet 总收入
A1: 总收入
A2: 用户只需要填写本页作为收入页。收入金额请输入正数；
A3: 记录编号 | B3: 日期 | C3: 收入来源 | D3: 收入金额 | E3: 收入类型 | F3: 备注
A4: 收入-0001 | B4: 46030 | C4: 工资 | D4: 6000 | E4: 工资 | F4: 示例收入
A5: 收入-0002 | B5: 46061 | C5: 工资 | D5: 6700 | E5: 工资 | F5: 示例收入
A6: 收入-0003 | B6: 46073 | C6: 退款 | D6: 200 | E6: 退款 | F6: 示例：退款收入

Sheet 输入设置
A1: 输入设置
A2: 手动变量区。日常使用时主要更新当前可动用现金、额外缓冲、备用金月数等。
A4: 设置项 | B4: 当前值 | C4: 说明
A5: 当前可动用现金 | B5: 30000 | C5: 用于计算现金覆盖月数与可投资资金
A6: 额外安全缓冲 | B6: 1000 | C6: 在推荐现金储备之外额外保留的现金
A7: 风险偏好 | B7: 平衡 | C7: 仅用于说明；可填写保守、平衡、成长
A8: 备用金月数 | B8: 12 | C8: 推荐现金储备 = 月均支出 × 备用金月数，再考虑最低下限与额外缓冲
A9: 最低现金储备下限 | B9: 15000 | C9: 即使公式算出较低储备，也保留此下限
A12: 可选：每月住房底盘
B13: 2026-01 | C13: 2026-02 | D13: 2026-03 | E13: 2026-04 | F13: 2026-05 | G13: 2026-06 | H13: 2026-07 | I13: 2026-08 | J13: 2026-09 | K13: 2026-10 | L13: 2026-11 | M13: 2026-12
A14: 住房底盘 | B14: 3000 | C14: 3000 | D14: 3000 | E14: 3000 | F14: 3000 | G14: 3000 | H14: 3000 | I14: 3000 | J14: 3000 | K14: 3000 | L14: 3000 | M14: 3000

Sheet 税费设置
A1: 税费设置
A2: 消费税估算为近似分析。用户可选择是否启用，并可自行调整税率、地区和分类规则。
A4: 设置项 | B4: 当前值 | C4: 说明
A5: 是否启用消费税估算 | B5: 是 | C5: 选择“否”后，所有估算税额显示为0
A6: 支出金额是否为含税价 | B6: 是 | C6: 多数个人记账记录的是信用卡实际扣款，通常视为含税价
A7: 所在地区 | B7: 魁北克 | C7: 默认以魁北克消费税做示例，可手动修改税率
A8: 联邦消费税率 | B8: 0.05 | C8: 示例：5%
A9: 省级消费税率 | B9: 0.09975 | C9: 示例：魁北克省级销售税9.975%
A10: 合计消费税率 | B10: =B8+B9 -> 0.14975 | C10: 用于含税价倒推税额
A13: 主类别默认税费类型
A14: 主类别 | B14: 默认税费类型 | C14: 说明
A15: 住房 | B15: 免税 | C15: 居住租金等通常不纳入消费税估算
A16: 餐饮 | B16: 应税 | C16: 餐厅、外卖、热食通常应税；基础食品请手动改为零税率
A17: 交通 | B17: 应税 | C17: 加油、停车、维修等通常应税；公共交通请按实际情况调整
A18: 通讯 | B18: 应税 | C18: 手机、网络、通信服务通常应税
A19: 订阅 | B19: 应税 | C19: 软件、流媒体等订阅通常应税
A20: 购物 | B20: 应税 | C20: 衣物、日用品、电子产品等通常应税
A21: 医疗 | B21: 免税 | C21: 医疗类项目差异较大，示例按免税处理
A22: 运动 | B22: 应税 | C22: 健身房、运动服务通常应税
A23: 学习 | B23: 含税不明 | C23: 书籍、课程、学费等差异较大
A24: 宠物 | B24: 应税 | C24: 宠物食品和用品通常应税
A25: 娱乐 | B25: 应税 | C25: 电影、游戏、活动等通常应税
... A27: 其他 | B27: 含税不明 | C27: 未知项目需按收据判断
A30: 资料来源
A31: 主题 | B31: 链接
A32: 魁北克消费税计算规则 | B32: https://www.revenuquebec.ca/en/businesses/consumption-taxes/gsthst-and-qst/collecting-gst-and-qst/calculating-the-taxes/
A33: 魁北克消费税税率表 | B33: https://www.revenuquebec.ca/en/businesses/consumption-taxes/gsthst-and-qst/basic-rules-for-applying-the-gsthst-and-qst/tables-of-gst-and-qst-rates/
A34: 应税供应示例 | B34: https://www.revenuquebec.ca/en/businesses/consumption-taxes/gsthst-and-qst/basic-rules-for-applying-the-gsthst-and-qst/types-of-supplies/taxable-supplies/
A35: 联邦消费税抵免说明 | B35: https://www.canada.ca/en/revenue-agency/services/child-family-benefits/gst-hst-credit.html

Sheet 每月总结
A1: 每月总结
A2: 展示页：引用公式枢纽的月度汇总。
A3: 月份 | B3: 总收入 | C3: 个人支出 | D3: 必要支出 | E3: 弹性支出 | F3: 固定支出 | G3: 可变支出 | H3: 一次性支出 | I3: 住房支出 | J3: 净现金流 | K3: 是否纳入平均 | L3: 房产支出 | M3: 投资转账 | N3: 内部转账 | O3: 估算消费税
A4: =公式枢纽!A28 -> 2026-01 | B4: =公式枢纽!B28 -> 6000 | C4: =公式枢纽!C28 -> 5000 | D4: =公式枢纽!D28 -> 3910 | E4: =公式枢纽!E28 -> 1090 | F4: =公式枢纽!F28 -> 3160 | G4: =公式枢纽!G28 -> 1620 | H4: =公式枢纽!H28 -> 220 | ... O4: =公式枢纽!O28 -> 148.4801
A5: =公式枢纽!A29 -> 2026-02 | B5: =公式枢纽!B29 -> 6900 | C5: =公式枢纽!C29 -> 5300 | D5: =公式枢纽!D29 -> 4090 | E5: =公式枢纽!E29 -> 1210 | F5: =公式枢纽!F29 -> 3175 | G5: =公式枢纽!G29 -> 1835 | H5: =公式枢纽!H29 -> 290 | ... O5: =公式枢纽!O29 -> 169.97065
A6: =公式枢纽!A30 -> 2026-03 | B6: =公式枢纽!B30 -> 0 | C6: =公式枢纽!C30 -> 0 | D6: =公式枢纽!D30 -> 0 | E6: =公式枢纽!E30 -> 0 | F6: =公式枢纽!F30 -> 0 | G6: =公式枢纽!G30 -> 0 | H6: =公式枢纽!H30 -> 0 | ... O6: =公式枢纽!O30 -> 0
A7: =公式枢纽!A31 -> 2026-04 | B7: =公式枢纽!B31 -> 0 | C7: =公式枢纽!C31 -> 0 | D7: =公式枢纽!D31 -> 0 | E7: =公式枢纽!E31 -> 0 | F7: =公式枢纽!F31 -> 0 | G7: =公式枢纽!G31 -> 0 | H7: =公式枢纽!H31 -> 0 | ... O7: =公式枢纽!O31 -> 0
A8: =公式枢纽!A32 -> 2026-05 | B8: =公式枢纽!B32 -> 0 | C8: =公式枢纽!C32 -> 0 | D8: =公式枢纽!D32 -> 0 | E8: =公式枢纽!E32 -> 0 | F8: =公式枢纽!F32 -> 0 | G8: =公式枢纽!G32 -> 0 | H8: =公式枢纽!H32 -> 0 | ... O8: =公式枢纽!O32 -> 0
A9: =公式枢纽!A33 -> 2026-06 | B9: =公式枢纽!B33 -> 0 | C9: =公式枢纽!C33 -> 0 | D9: =公式枢纽!D33 -> 0 | E9: =公式枢纽!E33 -> 0 | F9: =公式枢纽!F33 -> 0 | G9: =公式枢纽!G33 -> 0 | H9: =公式枢纽!H33 -> 0 | ... O9: =公式枢纽!O33 -> 0
A10: =公式枢纽!A34 -> 2026-07 | B10: =公式枢纽!B34 -> 0 | C10: =公式枢纽!C34 -> 0 | D10: =公式枢纽!D34 -> 0 | E10: =公式枢纽!E34 -> 0 | F10: =公式枢纽!F34 -> 0 | G10: =公式枢纽!G34 -> 0 | H10: =公式枢纽!H34 -> 0 | ... O10: =公式枢纽!O34 -> 0
A11: =公式枢纽!A35 -> 2026-08 | B11: =公式枢纽!B35 -> 0 | C11: =公式枢纽!C35 -> 0 | D11: =公式枢纽!D35 -> 0 | E11: =公式枢纽!E35 -> 0 | F11: =公式枢纽!F35 -> 0 | G11: =公式枢纽!G35 -> 0 | H11: =公式枢纽!H35 -> 0 | ... O11: =公式枢纽!O35 -> 0
A12: =公式枢纽!A36 -> 2026-09 | B12: =公式枢纽!B36 -> 0 | C12: =公式枢纽!C36 -> 0 | D12: =公式枢纽!D36 -> 0 | E12: =公式枢纽!E36 -> 0 | F12: =公式枢纽!F36 -> 0 | G12: =公式枢纽!G36 -> 0 | H12: =公式枢纽!H36 -> 0 | ... O12: =公式枢纽!O36 -> 0
A13: =公式枢纽!A37 -> 2026-10 | B13: =公式枢纽!B37 -> 0 | C13: =公式枢纽!C37 -> 0 | D13: =公式枢纽!D37 -> 0 | E13: =公式枢纽!E37 -> 0 | F13: =公式枢纽!F37 -> 0 | G13: =公式枢纽!G37 -> 0 | H13: =公式枢纽!H37 -> 0 | ... O13: =公式枢纽!O37 -> 0
A14: =公式枢纽!A38 -> 2026-11 | B14: =公式枢纽!B38 -> 0 | C14: =公式枢纽!C38 -> 0 | D14: =公式枢纽!D38 -> 0 | E14: =公式枢纽!E38 -> 0 | F14: =公式枢纽!F38 -> 0 | G14: =公式枢纽!G38 -> 0 | H14: =公式枢纽!H38 -> 0 | ... O14: =公式枢纽!O38 -> 0
A15: =公式枢纽!A39 -> 2026-12 | B15: =公式枢纽!B39 -> 0 | C15: =公式枢纽!C39 -> 0 | D15: =公式枢纽!D39 -> 0 | E15: =公式枢纽!E39 -> 0 | F15: =公式枢纽!F39 -> 0 | G15: =公式枢纽!G39 -> 0 | H15: =公式枢纽!H39 -> 0 | ... O15: =公式枢纽!O39 -> 0

Sheet 各类别总结
A1: 各类别总结
A2: 展示页：按主类别汇总月均、年化金额和占比。
A3: 主类别 | B3: 2026-01 | C3: 2026-02 | D3: 2026-03 | E3: 2026-04 | F3: 2026-05 | G3: 2026-06 | H3: 2026-07 | I3: 2026-08 | J3: 2026-09 | K3: 2026-10 | L3: 2026-11 | M3: 2026-12 | N3: 月均 | O3: 年化 | P3: 占个人月支出比例
A4: =公式枢纽!A45 -> 住房 | B4: =公式枢纽!B45 -> 3000 | C4: =公式枢纽!C45 -> 3000 | D4: =公式枢纽!D45 -> 0 | E4: =公式枢纽!E45 -> 0 | F4: =公式枢纽!F45 -> 0 | G4: =公式枢纽!G45 -> 0 | H4: =公式枢纽!H45 -> 0 | ... P4: =公式枢纽!P45 -> 0.58252427
A5: =公式枢纽!A46 -> 餐饮 | B5: =公式枢纽!B46 -> 770 | C5: =公式枢纽!C46 -> 870 | D5: =公式枢纽!D46 -> 0 | E5: =公式枢纽!E46 -> 0 | F5: =公式枢纽!F46 -> 0 | G5: =公式枢纽!G46 -> 0 | H5: =公式枢纽!H46 -> 0 | ... P5: =公式枢纽!P46 -> 0.1592233
A6: =公式枢纽!A47 -> 交通 | B6: =公式枢纽!B47 -> 220 | C6: =公式枢纽!C47 -> 260 | D6: =公式枢纽!D47 -> 0 | E6: =公式枢纽!E47 -> 0 | F6: =公式枢纽!F47 -> 0 | G6: =公式枢纽!G47 -> 0 | H6: =公式枢纽!H47 -> 0 | ... P6: =公式枢纽!P47 -> 0.046601942
A7: =公式枢纽!A48 -> 通讯 | B7: =公式枢纽!B48 -> 60 | C7: =公式枢纽!C48 -> 60 | D7: =公式枢纽!D48 -> 0 | E7: =公式枢纽!E48 -> 0 | F7: =公式枢纽!F48 -> 0 | G7: =公式枢纽!G48 -> 0 | H7: =公式枢纽!H48 -> 0 | ... P7: =公式枢纽!P48 -> 0.011650485
A8: =公式枢纽!A49 -> 订阅 | B8: =公式枢纽!B49 -> 30 | C8: =公式枢纽!C49 -> 45 | D8: =公式枢纽!D49 -> 0 | E8: =公式枢纽!E49 -> 0 | F8: =公式枢纽!F49 -> 0 | G8: =公式枢纽!G49 -> 0 | H8: =公式枢纽!H49 -> 0 | ... P8: =公式枢纽!P49 -> 0.0072815534
A9: =公式枢纽!A50 -> 购物 | B9: =公式枢纽!B50 -> 250 | C9: =公式枢纽!C50 -> 300 | D9: =公式枢纽!D50 -> 0 | E9: =公式枢纽!E50 -> 0 | F9: =公式枢纽!F50 -> 0 | G9: =公式枢纽!G50 -> 0 | H9: =公式枢纽!H50 -> 0 | ... P9: =公式枢纽!P50 -> 0.053398058
A10: =公式枢纽!A51 -> 医疗 | B10: =公式枢纽!B51 -> 80 | C10: =公式枢纽!C51 -> 100 | D10: =公式枢纽!D51 -> 0 | E10: =公式枢纽!E51 -> 0 | F10: =公式枢纽!F51 -> 0 | G10: =公式枢纽!G51 -> 0 | H10: =公式枢纽!H51 -> 0 | ... P10: =公式枢纽!P51 -> 0.017475728
A11: =公式枢纽!A52 -> 运动 | B11: =公式枢纽!B52 -> 70 | C11: =公式枢纽!C52 -> 70 | D11: =公式枢纽!D52 -> 0 | E11: =公式枢纽!E52 -> 0 | F11: =公式枢纽!F52 -> 0 | G11: =公式枢纽!G52 -> 0 | H11: =公式枢纽!H52 -> 0 | ... P11: =公式枢纽!P52 -> 0.013592233
A12: =公式枢纽!A53 -> 学习 | B12: =公式枢纽!B53 -> 120 | C12: =公式枢纽!C53 -> 140 | D12: =公式枢纽!D53 -> 0 | E12: =公式枢纽!E53 -> 0 | F12: =公式枢纽!F53 -> 0 | G12: =公式枢纽!G53 -> 0 | H12: =公式枢纽!H53 -> 0 | ... P12: =公式枢纽!P53 -> 0.025242718
A13: =公式枢纽!A54 -> 宠物 | B13: =公式枢纽!B54 -> 90 | C13: =公式枢纽!C54 -> 100 | D13: =公式枢纽!D54 -> 0 | E13: =公式枢纽!E54 -> 0 | F13: =公式枢纽!F54 -> 0 | G13: =公式枢纽!G54 -> 0 | H13: =公式枢纽!H54 -> 0 | ... P13: =公式枢纽!P54 -> 0.018446602
A14: =公式枢纽!A55 -> 娱乐 | B14: =公式枢纽!B55 -> 100 | C14: =公式枢纽!C55 -> 120 | D14: =公式枢纽!D55 -> 0 | E14: =公式枢纽!E55 -> 0 | F14: =公式枢纽!F55 -> 0 | G14: =公式枢纽!G55 -> 0 | H14: =公式枢纽!H55 -> 0 | ... P14: =公式枢纽!P55 -> 0.021359223
A15: =公式枢纽!A56 -> 税费 | B15: =公式枢纽!B56 -> 100 | C15: =公式枢纽!C56 -> 150 | D15: =公式枢纽!D56 -> 0 | E15: =公式枢纽!E56 -> 0 | F15: =公式枢纽!F56 -> 0 | G15: =公式枢纽!G56 -> 0 | H15: =公式枢纽!H56 -> 0 | ... P15: =公式枢纽!P56 -> 0.024271845
A16: =公式枢纽!A57 -> 其他 | B16: =公式枢纽!B57 -> 110 | C16: =公式枢纽!C57 -> 85 | D16: =公式枢纽!D57 -> 0 | E16: =公式枢纽!E57 -> 0 | F16: =公式枢纽!F57 -> 0 | G16: =公式枢纽!G57 -> 0 | H16: =公式枢纽!H57 -> 0 | ... P16: =公式枢纽!P57 -> 0.018932039

Sheet 消费税分析
A1: 消费税分析
A2: 按月份汇总估算消费税。该页是估算工具，不等同于实际可抵扣或可退税金额。
A3: 月份 | B3: 应税消费 | C3: 零税率消费 | D3: 免税消费 | E3: 其他/不适用 | F3: 税前金额 | G3: 联邦税估算 | H3: 省级税估算 | I3: 消费税合计 | J3: 说明
A4: 2026-01 | B4: =SUMIFS(税费计算明细!$L$4:$L$5000,税费计算明细!$C$4:$C$5000,$A4) -> 1140 | C4: =SUMIFS(税费计算明细!$M$4:$M$5000,税费计算明细!$C$4:$C$5000,$A4) -> 450 | D4: =SUMIFS(税费计算明细!$N$4:$N$5000,税费计算明细!$C$4:$C$5000,$A4) -> 3080 | E4: =SUMIFS(税费计算明细!$O$4:$O$5000,税费计算明细!$C$4:$C$5000,$A4) -> 330 | F4: =SUMIFS(税费计算明细!$P$4:$P$5000,税费计算明细!$C$4:$C$5000,$A4) -> 991.5199 | G4: =SUMIFS(税费计算明细!$Q$4:$Q$5000,税费计算明细!$C$4:$C$5000,$A4) -> 49.575995 | H4: =SUMIFS(税费计算明细!$R$4:$R$5000,税费计算明细!$C$4:$C$5000,$A4) -> 98.90411 | I4: =SUMIFS(税费计算明细!$S$4:$S$5000,税费计算明细!$C$4:$C$5000,$A4) -> 148.4801 | J4: =IF($I4=0,"无估算税额","已估算") -> 已估算
A5: 2026-02 | B5: =SUMIFS(税费计算明细!$L$4:$L$5000,税费计算明细!$C$4:$C$5000,$A5) -> 1305 | C5: =SUMIFS(税费计算明细!$M$4:$M$5000,税费计算明细!$C$4:$C$5000,$A5) -> 520 | D5: =SUMIFS(税费计算明细!$N$4:$N$5000,税费计算明细!$C$4:$C$5000,$A5) -> 3100 | E5: =SUMIFS(税费计算明细!$O$4:$O$5000,税费计算明细!$C$4:$C$5000,$A5) -> 375 | F5: =SUMIFS(税费计算明细!$P$4:$P$5000,税费计算明细!$C$4:$C$5000,$A5) -> 1135.0294 | G5: =SUMIFS(税费计算明细!$Q$4:$Q$5000,税费计算明细!$C$4:$C$5000,$A5) -> 56.751468 | H5: =SUMIFS(税费计算明细!$R$4:$R$5000,税费计算明细!$C$4:$C$5000,$A5) -> 113.21918 | I5: =SUMIFS(税费计算明细!$S$4:$S$5000,税费计算明细!$C$4:$C$5000,$A5) -> 169.97065 | J5: =IF($I5=0,"无估算税额","已估算") -> 已估算
A6: 2026-03 | B6: =SUMIFS(税费计算明细!$L$4:$L$5000,税费计算明细!$C$4:$C$5000,$A6) -> 0 | C6: =SUMIFS(税费计算明细!$M$4:$M$5000,税费计算明细!$C$4:$C$5000,$A6) -> 0 | D6: =SUMIFS(税费计算明细!$N$4:$N$5000,税费计算明细!$C$4:$C$5000,$A6) -> 0 | E6: =SUMIFS(税费计算明细!$O$4:$O$5000,税费计算明细!$C$4:$C$5000,$A6) -> 0 | F6: =SUMIFS(税费计算明细!$P$4:$P$5000,税费计算明细!$C$4:$C$5000,$A6) -> 0 | G6: =SUMIFS(税费计算明细!$Q$4:$Q$5000,税费计算明细!$C$4:$C$5000,$A6) -> 0 | H6: =SUMIFS(税费计算明细!$R$4:$R$5000,税费计算明细!$C$4:$C$5000,$A6) -> 0 | I6: =SUMIFS(税费计算明细!$S$4:$S$5000,税费计算明细!$C$4:$C$5000,$A6) -> 0 | J6: =IF($I6=0,"无估算税额","已估算") -> 无估算税额
A7: 2026-04 | B7: =SUMIFS(税费计算明细!$L$4:$L$5000,税费计算明细!$C$4:$C$5000,$A7) -> 0 | C7: =SUMIFS(税费计算明细!$M$4:$M$5000,税费计算明细!$C$4:$C$5000,$A7) -> 0 | D7: =SUMIFS(税费计算明细!$N$4:$N$5000,税费计算明细!$C$4:$C$5000,$A7) -> 0 | E7: =SUMIFS(税费计算明细!$O$4:$O$5000,税费计算明细!$C$4:$C$5000,$A7) -> 0 | F7: =SUMIFS(税费计算明细!$P$4:$P$5000,税费计算明细!$C$4:$C$5000,$A7) -> 0 | G7: =SUMIFS(税费计算明细!$Q$4:$Q$5000,税费计算明细!$C$4:$C$5000,$A7) -> 0 | H7: =SUMIFS(税费计算明细!$R$4:$R$5000,税费计算明细!$C$4:$C$5000,$A7) -> 0 | I7: =SUMIFS(税费计算明细!$S$4:$S$5000,税费计算明细!$C$4:$C$5000,$A7) -> 0 | J7: =IF($I7=0,"无估算税额","已估算") -> 无估算税额
A8: 2026-05 | B8: =SUMIFS(税费计算明细!$L$4:$L$5000,税费计算明细!$C$4:$C$5000,$A8) -> 0 | C8: =SUMIFS(税费计算明细!$M$4:$M$5000,税费计算明细!$C$4:$C$5000,$A8) -> 0 | D8: =SUMIFS(税费计算明细!$N$4:$N$5000,税费计算明细!$C$4:$C$5000,$A8) -> 0 | E8: =SUMIFS(税费计算明细!$O$4:$O$5000,税费计算明细!$C$4:$C$5000,$A8) -> 0 | F8: =SUMIFS(税费计算明细!$P$4:$P$5000,税费计算明细!$C$4:$C$5000,$A8) -> 0 | G8: =SUMIFS(税费计算明细!$Q$4:$Q$5000,税费计算明细!$C$4:$C$5000,$A8) -> 0 | H8: =SUMIFS(税费计算明细!$R$4:$R$5000,税费计算明细!$C$4:$C$5000,$A8) -> 0 | I8: =SUMIFS(税费计算明细!$S$4:$S$5000,税费计算明细!$C$4:$C$5000,$A8) -> 0 | J8: =IF($I8=0,"无估算税额","已估算") -> 无估算税额
A9: 2026-06 | B9: =SUMIFS(税费计算明细!$L$4:$L$5000,税费计算明细!$C$4:$C$5000,$A9) -> 0 | C9: =SUMIFS(税费计算明细!$M$4:$M$5000,税费计算明细!$C$4:$C$5000,$A9) -> 0 | D9: =SUMIFS(税费计算明细!$N$4:$N$5000,税费计算明细!$C$4:$C$5000,$A9) -> 0 | E9: =SUMIFS(税费计算明细!$O$4:$O$5000,税费计算明细!$C$4:$C$5000,$A9) -> 0 | F9: =SUMIFS(税费计算明细!$P$4:$P$5000,税费计算明细!$C$4:$C$5000,$A9) -> 0 | G9: =SUMIFS(税费计算明细!$Q$4:$Q$5000,税费计算明细!$C$4:$C$5000,$A9) -> 0 | H9: =SUMIFS(税费计算明细!$R$4:$R$5000,税费计算明细!$C$4:$C$5000,$A9) -> 0 | I9: =SUMIFS(税费计算明细!$S$4:$S$5000,税费计算明细!$C$4:$C$5000,$A9) -> 0 | J9: =IF($I9=0,"无估算税额","已估算") -> 无估算税额
A10: 2026-07 | B10: =SUMIFS(税费计算明细!$L$4:$L$5000,税费计算明细!$C$4:$C$5000,$A10) -> 0 | C10: =SUMIFS(税费计算明细!$M$4:$M$5000,税费计算明细!$C$4:$C$5000,$A10) -> 0 | D10: =SUMIFS(税费计算明细!$N$4:$N$5000,税费计算明细!$C$4:$C$5000,$A10) -> 0 | E10: =SUMIFS(税费计算明细!$O$4:$O$5000,税费计算明细!$C$4:$C$5000,$A10) -> 0 | F10: =SUMIFS(税费计算明细!$P$4:$P$5000,税费计算明细!$C$4:$C$5000,$A10) -> 0 | G10: =SUMIFS(税费计算明细!$Q$4:$Q$5000,税费计算明细!$C$4:$C$5000,$A10) -> 0 | H10: =SUMIFS(税费计算明细!$R$4:$R$5000,税费计算明细!$C$4:$C$5000,$A10) -> 0 | I10: =SUMIFS(税费计算明细!$S$4:$S$5000,税费计算明细!$C$4:$C$5000,$A10) -> 0 | J10: =IF($I10=0,"无估算税额","已估算") -> 无估算税额
A11: 2026-08 | B11: =SUMIFS(税费计算明细!$L$4:$L$5000,税费计算明细!$C$4:$C$5000,$A11) -> 0 | C11: =SUMIFS(税费计算明细!$M$4:$M$5000,税费计算明细!$C$4:$C$5000,$A11) -> 0 | D11: =SUMIFS(税费计算明细!$N$4:$N$5000,税费计算明细!$C$4:$C$5000,$A11) -> 0 | E11: =SUMIFS(税费计算明细!$O$4:$O$5000,税费计算明细!$C$4:$C$5000,$A11) -> 0 | F11: =SUMIFS(税费计算明细!$P$4:$P$5000,税费计算明细!$C$4:$C$5000,$A11) -> 0 | G11: =SUMIFS(税费计算明细!$Q$4:$Q$5000,税费计算明细!$C$4:$C$5000,$A11) -> 0 | H11: =SUMIFS(税费计算明细!$R$4:$R$5000,税费计算明细!$C$4:$C$5000,$A11) -> 0 | I11: =SUMIFS(税费计算明细!$S$4:$S$5000,税费计算明细!$C$4:$C$5000,$A11) -> 0 | J11: =IF($I11=0,"无估算税额","已估算") -> 无估算税额
A12: 2026-09 | B12: =SUMIFS(税费计算明细!$L$4:$L$5000,税费计算明细!$C$4:$C$5000,$A12) -> 0 | C12: =SUMIFS(税费计算明细!$M$4:$M$5000,税费计算明细!$C$4:$C$5000,$A12) -> 0 | D12: =SUMIFS(税费计算明细!$N$4:$N$5000,税费计算明细!$C$4:$C$5000,$A12) -> 0 | E12: =SUMIFS(税费计算明细!$O$4:$O$5000,税费计算明细!$C$4:$C$5000,$A12) -> 0 | F12: =SUMIFS(税费计算明细!$P$4:$P$5000,税费计算明细!$C$4:$C$5000,$A12) -> 0 | G12: =SUMIFS(税费计算明细!$Q$4:$Q$5000,税费计算明细!$C$4:$C$5000,$A12) -> 0 | H12: =SUMIFS(税费计算明细!$R$4:$R$5000,税费计算明细!$C$4:$C$5000,$A12) -> 0 | I12: =SUMIFS(税费计算明细!$S$4:$S$5000,税费计算明细!$C$4:$C$5000,$A12) -> 0 | J12: =IF($I12=0,"无估算税额","已估算") -> 无估算税额
A13: 2026-10 | B13: =SUMIFS(税费计算明细!$L$4:$L$5000,税费计算明细!$C$4:$C$5000,$A13) -> 0 | C13: =SUMIFS(税费计算明细!$M$4:$M$5000,税费计算明细!$C$4:$C$5000,$A13) -> 0 | D13: =SUMIFS(税费计算明细!$N$4:$N$5000,税费计算明细!$C$4:$C$5000,$A13) -> 0 | E13: =SUMIFS(税费计算明细!$O$4:$O$5000,税费计算明细!$C$4:$C$5000,$A13) -> 0 | F13: =SUMIFS(税费计算明细!$P$4:$P$5000,税费计算明细!$C$4:$C$5000,$A13) -> 0 | G13: =SUMIFS(税费计算明细!$Q$4:$Q$5000,税费计算明细!$C$4:$C$5000,$A13) -> 0 | H13: =SUMIFS(税费计算明细!$R$4:$R$5000,税费计算明细!$C$4:$C$5000,$A13) -> 0 | I13: =SUMIFS(税费计算明细!$S$4:$S$5000,税费计算明细!$C$4:$C$5000,$A13) -> 0 | J13: =IF($I13=0,"无估算税额","已估算") -> 无估算税额
A14: 2026-11 | B14: =SUMIFS(税费计算明细!$L$4:$L$5000,税费计算明细!$C$4:$C$5000,$A14) -> 0 | C14: =SUMIFS(税费计算明细!$M$4:$M$5000,税费计算明细!$C$4:$C$5000,$A14) -> 0 | D14: =SUMIFS(税费计算明细!$N$4:$N$5000,税费计算明细!$C$4:$C$5000,$A14) -> 0 | E14: =SUMIFS(税费计算明细!$O$4:$O$5000,税费计算明细!$C$4:$C$5000,$A14) -> 0 | F14: =SUMIFS(税费计算明细!$P$4:$P$5000,税费计算明细!$C$4:$C$5000,$A14) -> 0 | G14: =SUMIFS(税费计算明细!$Q$4:$Q$5000,税费计算明细!$C$4:$C$5000,$A14) -> 0 | H14: =SUMIFS(税费计算明细!$R$4:$R$5000,税费计算明细!$C$4:$C$5000,$A14) -> 0 | I14: =SUMIFS(税费计算明细!$S$4:$S$5000,税费计算明细!$C$4:$C$5000,$A14) -> 0 | J14: =IF($I14=0,"无估算税额","已估算") -> 无估算税额
A15: 2026-12 | B15: =SUMIFS(税费计算明细!$L$4:$L$5000,税费计算明细!$C$4:$C$5000,$A15) -> 0 | C15: =SUMIFS(税费计算明细!$M$4:$M$5000,税费计算明细!$C$4:$C$5000,$A15) -> 0 | D15: =SUMIFS(税费计算明细!$N$4:$N$5000,税费计算明细!$C$4:$C$5000,$A15) -> 0 | E15: =SUMIFS(税费计算明细!$O$4:$O$5000,税费计算明细!$C$4:$C$5000,$A15) -> 0 | F15: =SUMIFS(税费计算明细!$P$4:$P$5000,税费计算明细!$C$4:$C$5000,$A15) -> 0 | G15: =SUMIFS(税费计算明细!$Q$4:$Q$5000,税费计算明细!$C$4:$C$5000,$A15) -> 0 | H15: =SUMIFS(税费计算明细!$R$4:$R$5000,税费计算明细!$C$4:$C$5000,$A15) -> 0 | I15: =SUMIFS(税费计算明细!$S$4:$S$5000,税费计算明细!$C$4:$C$5000,$A15) -> 0 | J15: =IF($I15=0,"无估算税额","已估算") -> 无估算税额
A17: 全年合计 | B17: =SUM(B4:B15) -> 2445 | C17: =SUM(C4:C15) -> 970 | D17: =SUM(D4:D15) -> 6180 | E17: =SUM(E4:E15) -> 705 | F17: =SUM(F4:F15) -> 2126.5492 | G17: =SUM(G4:G15) -> 106.32746 | H17: =SUM(H4:H15) -> 212.12329 | I17: =SUM(I4:I15) -> 318.45075
A18: 消费税占个人支出比例 | B18: =IFERROR(I17/公式枢纽!$B$6,0) -> 0.030917549

Sheet 公式枢纽
A1: 公式枢纽
A2: 所有核心计算集中在本页。展示页只引用本页，用户通常不需要修改。
A4: 已纳入分析月份数 | B4: =SUM($K$28:$K$39) -> 2
A5: 总收入 | B5: =SUM($B$28:$B$39) -> 12900
A6: 个人支出合计 | B6: =SUM($C$28:$C$39) -> 10300
A7: 平均每月个人支出 | B7: =IF($B$4=0,0,$B$6/$B$4) -> 5150
A8: 平均每月必要支出 | B8: =IF($B$4=0,0,SUM($D$28:$D$39)/$B$4) -> 4000
A9: 平均每月弹性支出 | B9: =IF($B$4=0,0,SUM($E$28:$E$39)/$B$4) -> 1150
A10: 平均每月固定支出 | B10: =IF($B$4=0,0,SUM($F$28:$F$39)/$B$4) -> 3167.5
A11: 平均每月可变支出 | B11: =IF($B$4=0,0,SUM($G$28:$G$39)/$B$4) -> 1727.5
A12: 平均每月一次性支出 | B12: =IF($B$4=0,0,SUM($H$28:$H$39)/$B$4) -> 255
A13: 平均每月住房支出 | B13: =IF($B$4=0,0,SUM($I$28:$I$39)/$B$4) -> 3000
A14: 住房支出占比 | B14: =IFERROR($B$13/$B$7,0) -> 0.58252427
A15: 储蓄率 | B15: =IFERROR(($B$5-$B$6)/$B$5,0) -> 0.20155039
A16: 当前现金可覆盖月数 | B16: =IFERROR(输入设置!$B$5/$B$7,0) -> 5.8252427
A17: 正常一年生活储备 | B17: =$B$7*12 -> 61800
A18: 必要一年生活储备 | B18: =$B$8*12 -> 48000
A19: 保守一年生活储备 | B19: =MAX($C$28:$C$39)*12 -> 63600
A20: 推荐现金储备 | B20: =MAX($B$7*输入设置!$B$8,输入设置!$B$9)+输入设置!$B$6 -> 62800
A21: 建议可投资资金 | B21: =MAX(0,输入设置!$B$5-$B$20) -> 0
A22: 现金缺口 | B22: =MAX(0,$B$20-输入设置!$B$5) -> 32800
A23: 现金安全等级 | B23: =IF($B$16>=12,"较安全",IF($B$16>=6,"中等安全","偏紧张")) -> 偏紧张
A24: 全年估算消费税 | B24: =消费税分析!$I$17 -> 318.45075
A25: 消费税估算状态 | B25: =IF(税费设置!$B$5="是","已启用","未启用") -> 已启用
A27: 月份 | B27: 总收入 | C27: 个人支出 | D27: 必要支出 | E27: 弹性支出 | F27: 固定支出 | G27: 可变支出 | H27: 一次性支出 | I27: 住房支出 | J27: 净现金流 | K27: 是否纳入平均 | L27: 房产支出 | M27: 投资转账 | N27: 内部转账 | O27: 估算消费税
A28: 2026-01 | B28: =SUMIFS(总收入!$D$4:$D$5000,总收入!$B$4:$B$5000,">="&DATE(VALUE(LEFT($A28,4)),VALUE(RIGHT($A28,2)),1),总收入!$B$4:$B$5000,"<"&DATE(VALUE(LEFT($A28,4)),VALUE(RIGHT($A28,2))+1,1)) -> 6000 | C28: =SUMIFS(总支出!$D$4:$D$5000,总支出!$B$4:$B$5000,">="&DATE(VALUE(LEFT($A28,4)),VALUE(RIGHT($A28,2)),1),总支出!$B$4:$B$5000,"<"&DATE(VALUE(LEFT($A28,4)),VALUE(RIGHT($A28,2))+1,1),总支出!$H$4:$H$5000,"个人支出") -> 5000 | D28: =SUMIFS(总支出!$D$4:$D$5000,总支出!$B$4:$B$5000,">="&DATE(VALUE(LEFT($A28,4)),VALUE(RIGHT($A28,2)),1),总支出!$B$4:$B$5000,"<"&DATE(VALUE(LEFT($A28,4)),VALUE(RIGHT($A28,2))+1,1),总支出!$H$4:$H$5000,"个人支出",总支出!$G$4:$G$5000,"必要") -> 3910 | E28: =SUMIFS(总支出!$D$4:$D$5000,总支出!$B$4:$B$5000,">="&DATE(VALUE(LEFT($A28,4)),VALUE(RIGHT($A28,2)),1),总支出!$B$4:$B$5000,"<"&DATE(VALUE(LEFT($A28,4)),VALUE(RIGHT($A28,2))+1,1),总支出!$H$4:$H$5000,"个人支出",总支出!$G$4:$G$5000,"弹性") -> 1090 | F28: =SUMIFS(总支出!$D$4:$D$5000,总支出!$B$4:$B$5000,">="&DATE(VALUE(LEFT($A28,4)),VALUE(RIGHT($A28,2)),1),总支出!$B$4:$B$5000,"<"&DATE(VALUE(LEFT($A28,4)),VALUE(RIGHT($A28,2))+1,1),总支出!$H$4:$H$5000,"个人支出",总支出!$F$4:$F$5000,"固定") -> 3160 | G28: =SUMIFS(总支出!$D$4:$D$5000,总支出!$B$4:$B$5000,">="&DATE(VALUE(LEFT($A28,4)),VALUE(RIGHT($A28,2)),1),总支出!$B$4:$B$5000,"<"&DATE(VALUE(LEFT($A28,4)),VALUE(RIGHT($A28,2))+1,1),总支出!$H$4:$H$5000,"个人支出",总支出!$F$4:$F$5000,"可变") -> 1620 | H28: =SUMIFS(总支出!$D$4:$D$5000,总支出!$B$4:$B$5000,">="&DATE(VALUE(LEFT($A28,4)),VALUE(RIGHT($A28,2)),1),总支出!$B$4:$B$5000,"<"&DATE(VALUE(LEFT($A28,4)),VALUE(RIGHT($A28,2))+1,1),总支出!$H$4:$H$5000,"个人支出",总支出!$F$4:$F$5000,"一次性") -> 220 | I28: =SUMIFS(总支出!$D$4:$D$5000,总支出!$B$4:$B$5000,">="&DATE(VALUE(LEFT($A28,4)),VALUE(RIGHT($A28,2)),1),总支出!$B$4:$B$5000,"<"&DATE(VALUE(LEFT($A28,4)),VALUE(RIGHT($A28,2))+1,1),总支出!$H$4:$H$5000,"个人支出",总支出!$E$4:$E$5000,"住房") -> 3000 | J28: =B28-C28 -> 1000 | K28: =IF(OR(B28>0,C28>0),1,0) -> 1 | L28: =SUMIFS(总支出!$D$4:$D$5000,总支出!$B$4:$B$5000,">="&DATE(VALUE(LEFT($A28,4)),VALUE(RIGHT($A28,2)),1),总支出!$B$4:$B$5000,"<"&DATE(VALUE(LEFT($A28,4)),VALUE(RIGHT($A28,2))+1,1),总支出!$H$4:$H$5000,"房产支出") -> 0 | M28: =SUMIFS(总支出!$D$4:$D$5000,总支出!$B$4:$B$5000,">="&DATE(VALUE(LEFT($A28,4)),VALUE(RIGHT($A28,2)),1),总支出!$B$4:$B$5000,"<"&DATE(VALUE(LEFT($A28,4)),VALUE(RIGHT($A28,2))+1,1),总支出!$H$4:$H$5000,"投资转账") -> 0 | N28: =SUMIFS(总支出!$D$4:$D$5000,总支出!$B$4:$B$5000,">="&DATE(VALUE(LEFT($A28,4)),VALUE(RIGHT($A28,2)),1),总支出!$B$4:$B$5000,"<"&DATE(VALUE(LEFT($A28,4)),VALUE(RIGHT($A28,2))+1,1),总支出!$H$4:$H$5000,"内部转账") -> 0 | O28: =SUMIFS(税费计算明细!$S$4:$S$5000,税费计算明细!$C$4:$C$5000,$A28) -> 148.4801
A29: 2026-02 | B29: =SUMIFS(总收入!$D$4:$D$5000,总收入!$B$4:$B$5000,">="&DATE(VALUE(LEFT($A29,4)),VALUE(RIGHT($A29,2)),1),总收入!$B$4:$B$5000,"<"&DATE(VALUE(LEFT($A29,4)),VALUE(RIGHT($A29,2))+1,1)) -> 6900 | C29: =SUMIFS(总支出!$D$4:$D$5000,总支出!$B$4:$B$5000,">="&DATE(VALUE(LEFT($A29,4)),VALUE(RIGHT($A29,2)),1),总支出!$B$4:$B$5000,"<"&DATE(VALUE(LEFT($A29,4)),VALUE(RIGHT($A29,2))+1,1),总支出!$H$4:$H$5000,"个人支出") -> 5300 | D29: =SUMIFS(总支出!$D$4:$D$5000,总支出!$B$4:$B$5000,">="&DATE(VALUE(LEFT($A29,4)),VALUE(RIGHT($A29,2)),1),总支出!$B$4:$B$5000,"<"&DATE(VALUE(LEFT($A29,4)),VALUE(RIGHT($A29,2))+1,1),总支出!$H$4:$H$5000,"个人支出",总支出!$G$4:$G$5000,"必要") -> 4090 | E29: =SUMIFS(总支出!$D$4:$D$5000,总支出!$B$4:$B$5000,">="&DATE(VALUE(LEFT($A29,4)),VALUE(RIGHT($A29,2)),1),总支出!$B$4:$B$5000,"<"&DATE(VALUE(LEFT($A29,4)),VALUE(RIGHT($A29,2))+1,1),总支出!$H$4:$H$5000,"个人支出",总支出!$G$4:$G$5000,"弹性") -> 1210 | F29: =SUMIFS(总支出!$D$4:$D$5000,总支出!$B$4:$B$5000,">="&DATE(VALUE(LEFT($A29,4)),VALUE(RIGHT($A29,2)),1),总支出!$B$4:$B$5000,"<"&DATE(VALUE(LEFT($A29,4)),VALUE(RIGHT($A29,2))+1,1),总支出!$H$4:$H$5000,"个人支出",总支出!$F$4:$F$5000,"固定") -> 3175 | G29: =SUMIFS(总支出!$D$4:$D$5000,总支出!$B$4:$B$5000,">="&DATE(VALUE(LEFT($A29,4)),VALUE(RIGHT($A29,2)),1),总支出!$B$4:$B$5000,"<"&DATE(VALUE(LEFT($A29,4)),VALUE(RIGHT($A29,2))+1,1),总支出!$H$4:$H$5000,"个人支出",总支出!$F$4:$F$5000,"可变") -> 1835 | H29: =SUMIFS(总支出!$D$4:$D$5000,总支出!$B$4:$B$5000,">="&DATE(VALUE(LEFT($A29,4)),VALUE(RIGHT($A29,2)),1),总支出!$B$4:$B$5000,"<"&DATE(VALUE(LEFT($A29,4)),VALUE(RIGHT($A29,2))+1,1),总支出!$H$4:$H$5000,"个人支出",总支出!$F$4:$F$5000,"一次性") -> 290 | I29: =SUMIFS(总支出!$D$4:$D$5000,总支出!$B$4:$B$5000,">="&DATE(VALUE(LEFT($A29,4)),VALUE(RIGHT($A29,2)),1),总支出!$B$4:$B$5000,"<"&DATE(VALUE(LEFT($A29,4)),VALUE(RIGHT($A29,2))+1,1),总支出!$H$4:$H$5000,"个人支出",总支出!$E$4:$E$5000,"住房") -> 3000 | J29: =B29-C29 -> 1600 | K29: =IF(OR(B29>0,C29>0),1,0) -> 1 | L29: =SUMIFS(总支出!$D$4:$D$5000,总支出!$B$4:$B$5000,">="&DATE(VALUE(LEFT($A29,4)),VALUE(RIGHT($A29,2)),1),总支出!$B$4:$B$5000,"<"&DATE(VALUE(LEFT($A29,4)),VALUE(RIGHT($A29,2))+1,1),总支出!$H$4:$H$5000,"房产支出") -> 0 | M29: =SUMIFS(总支出!$D$4:$D$5000,总支出!$B$4:$B$5000,">="&DATE(VALUE(LEFT($A29,4)),VALUE(RIGHT($A29,2)),1),总支出!$B$4:$B$5000,"<"&DATE(VALUE(LEFT($A29,4)),VALUE(RIGHT($A29,2))+1,1),总支出!$H$4:$H$5000,"投资转账") -> 0 | N29: =SUMIFS(总支出!$D$4:$D$5000,总支出!$B$4:$B$5000,">="&DATE(VALUE(LEFT($A29,4)),VALUE(RIGHT($A29,2)),1),总支出!$B$4:$B$5000,"<"&DATE(VALUE(LEFT($A29,4)),VALUE(RIGHT($A29,2))+1,1),总支出!$H$4:$H$5000,"内部转账") -> 0 | O29: =SUMIFS(税费计算明细!$S$4:$S$5000,税费计算明细!$C$4:$C$5000,$A29) -> 169.97065
A30: 2026-03 | B30: =SUMIFS(总收入!$D$4:$D$5000,总收入!$B$4:$B$5000,">="&DATE(VALUE(LEFT($A30,4)),VALUE(RIGHT($A30,2)),1),总收入!$B$4:$B$5000,"<"&DATE(VALUE(LEFT($A30,4)),VALUE(RIGHT($A30,2))+1,1)) -> 0 | C30: =SUMIFS(总支出!$D$4:$D$5000,总支出!$B$4:$B$5000,">="&DATE(VALUE(LEFT($A30,4)),VALUE(RIGHT($A30,2)),1),总支出!$B$4:$B$5000,"<"&DATE(VALUE(LEFT($A30,4)),VALUE(RIGHT($A30,2))+1,1),总支出!$H$4:$H$5000,"个人支出") -> 0 | D30: =SUMIFS(总支出!$D$4:$D$5000,总支出!$B$4:$B$5000,">="&DATE(VALUE(LEFT($A30,4)),VALUE(RIGHT($A30,2)),1),总支出!$B$4:$B$5000,"<"&DATE(VALUE(LEFT($A30,4)),VALUE(RIGHT($A30,2))+1,1),总支出!$H$4:$H$5000,"个人支出",总支出!$G$4:$G$5000,"必要") -> 0 | E30: =SUMIFS(总支出!$D$4:$D$5000,总支出!$B$4:$B$5000,">="&DATE(VALUE(LEFT($A30,4)),VALUE(RIGHT($A30,2)),1),总支出!$B$4:$B$5000,"<"&DATE(VALUE(LEFT($A30,4)),VALUE(RIGHT($A30,2))+1,1),总支出!$H$4:$H$5000,"个人支出",总支出!$G$4:$G$5000,"弹性") -> 0 | F30: =SUMIFS(总支出!$D$4:$D$5000,总支出!$B$4:$B$5000,">="&DATE(VALUE(LEFT($A30,4)),VALUE(RIGHT($A30,2)),1),总支出!$B$4:$B$5000,"<"&DATE(VALUE(LEFT($A30,4)),VALUE(RIGHT($A30,2))+1,1),总支出!$H$4:$H$5000,"个人支出",总支出!$F$4:$F$5000,"固定") -> 0 | G30: =SUMIFS(总支出!$D$4:$D$5000,总支出!$B$4:$B$5000,">="&DATE(VALUE(LEFT($A30,4)),VALUE(RIGHT($A30,2)),1),总支出!$B$4:$B$5000,"<"&DATE(VALUE(LEFT($A30,4)),VALUE(RIGHT($A30,2))+1,1),总支出!$H$4:$H$5000,"个人支出",总支出!$F$4:$F$5000,"可变") -> 0 | H30: =SUMIFS(总支出!$D$4:$D$5000,总支出!$B$4:$B$5000,">="&DATE(VALUE(LEFT($A30,4)),VALUE(RIGHT($A30,2)),1),总支出!$B$4:$B$5000,"<"&DATE(VALUE(LEFT($A30,4)),VALUE(RIGHT($A30,2))+1,1),总支出!$H$4:$H$5000,"个人支出",总支出!$F$4:$F$5000,"一次性") -> 0 | I30: =SUMIFS(总支出!$D$4:$D$5000,总支出!$B$4:$B$5000,">="&DATE(VALUE(LEFT($A30,4)),VALUE(RIGHT($A30,2)),1),总支出!$B$4:$B$5000,"<"&DATE(VALUE(LEFT($A30,4)),VALUE(RIGHT($A30,2))+1,1),总支出!$H$4:$H$5000,"个人支出",总支出!$E$4:$E$5000,"住房") -> 0 | J30: =B30-C30 -> 0 | K30: =IF(OR(B30>0,C30>0),1,0) -> 0 | L30: =SUMIFS(总支出!$D$4:$D$5000,总支出!$B$4:$B$5000,">="&DATE(VALUE(LEFT($A30,4)),VALUE(RIGHT($A30,2)),1),总支出!$B$4:$B$5000,"<"&DATE(VALUE(LEFT($A30,4)),VALUE(RIGHT($A30,2))+1,1),总支出!$H$4:$H$5000,"房产支出") -> 0 | M30: =SUMIFS(总支出!$D$4:$D$5000,总支出!$B$4:$B$5000,">="&DATE(VALUE(LEFT($A30,4)),VALUE(RIGHT($A30,2)),1),总支出!$B$4:$B$5000,"<"&DATE(VALUE(LEFT($A30,4)),VALUE(RIGHT($A30,2))+1,1),总支出!$H$4:$H$5000,"投资转账") -> 0 | N30: =SUMIFS(总支出!$D$4:$D$5000,总支出!$B$4:$B$5000,">="&DATE(VALUE(LEFT($A30,4)),VALUE(RIGHT($A30,2)),1),总支出!$B$4:$B$5000,"<"&DATE(VALUE(LEFT($A30,4)),VALUE(RIGHT($A30,2))+1,1),总支出!$H$4:$H$5000,"内部转账") -> 0 | O30: =SUMIFS(税费计算明细!$S$4:$S$5000,税费计算明细!$C$4:$C$5000,$A30) -> 0
A31: 2026-04 | B31: =SUMIFS(总收入!$D$4:$D$5000,总收入!$B$4:$B$5000,">="&DATE(VALUE(LEFT($A31,4)),VALUE(RIGHT($A31,2)),1),总收入!$B$4:$B$5000,"<"&DATE(VALUE(LEFT($A31,4)),VALUE(RIGHT($A31,2))+1,1)) -> 0 | C31: =SUMIFS(总支出!$D$4:$D$5000,总支出!$B$4:$B$5000,">="&DATE(VALUE(LEFT($A31,4)),VALUE(RIGHT($A31,2)),1),总支出!$B$4:$B$5000,"<"&DATE(VALUE(LEFT($A31,4)),VALUE(RIGHT($A31,2))+1,1),总支出!$H$4:$H$5000,"个人支出") -> 0 | D31: =SUMIFS(总支出!$D$4:$D$5000,总支出!$B$4:$B$5000,">="&DATE(VALUE(LEFT($A31,4)),VALUE(RIGHT($A31,2)),1),总支出!$B$4:$B$5000,"<"&DATE(VALUE(LEFT($A31,4)),VALUE(RIGHT($A31,2))+1,1),总支出!$H$4:$H$5000,"个人支出",总支出!$G$4:$G$5000,"必要") -> 0 | E31: =SUMIFS(总支出!$D$4:$D$5000,总支出!$B$4:$B$5000,">="&DATE(VALUE(LEFT($A31,4)),VALUE(RIGHT($A31,2)),1),总支出!$B$4:$B$5000,"<"&DATE(VALUE(LEFT($A31,4)),VALUE(RIGHT($A31,2))+1,1),总支出!$H$4:$H$5000,"个人支出",总支出!$G$4:$G$5000,"弹性") -> 0 | F31: =SUMIFS(总支出!$D$4:$D$5000,总支出!$B$4:$B$5000,">="&DATE(VALUE(LEFT($A31,4)),VALUE(RIGHT($A31,2)),1),总支出!$B$4:$B$5000,"<"&DATE(VALUE(LEFT($A31,4)),VALUE(RIGHT($A31,2))+1,1),总支出!$H$4:$H$5000,"个人支出",总支出!$F$4:$F$5000,"固定") -> 0 | G31: =SUMIFS(总支出!$D$4:$D$5000,总支出!$B$4:$B$5000,">="&DATE(VALUE(LEFT($A31,4)),VALUE(RIGHT($A31,2)),1),总支出!$B$4:$B$5000,"<"&DATE(VALUE(LEFT($A31,4)),VALUE(RIGHT($A31,2))+1,1),总支出!$H$4:$H$5000,"个人支出",总支出!$F$4:$F$5000,"可变") -> 0 | H31: =SUMIFS(总支出!$D$4:$D$5000,总支出!$B$4:$B$5000,">="&DATE(VALUE(LEFT($A31,4)),VALUE(RIGHT($A31,2)),1),总支出!$B$4:$B$5000,"<"&DATE(VALUE(LEFT($A31,4)),VALUE(RIGHT($A31,2))+1,1),总支出!$H$4:$H$5000,"个人支出",总支出!$F$4:$F$5000,"一次性") -> 0 | I31: =SUMIFS(总支出!$D$4:$D$5000,总支出!$B$4:$B$5000,">="&DATE(VALUE(LEFT($A31,4)),VALUE(RIGHT($A31,2)),1),总支出!$B$4:$B$5000,"<"&DATE(VALUE(LEFT($A31,4)),VALUE(RIGHT($A31,2))+1,1),总支出!$H$4:$H$5000,"个人支出",总支出!$E$4:$E$5000,"住房") -> 0 | J31: =B31-C31 -> 0 | K31: =IF(OR(B31>0,C31>0),1,0) -> 0 | L31: =SUMIFS(总支出!$D$4:$D$5000,总支出!$B$4:$B$5000,">="&DATE(VALUE(LEFT($A31,4)),VALUE(RIGHT($A31,2)),1),总支出!$B$4:$B$5000,"<"&DATE(VALUE(LEFT($A31,4)),VALUE(RIGHT($A31,2))+1,1),总支出!$H$4:$H$5000,"房产支出") -> 0 | M31: =SUMIFS(总支出!$D$4:$D$5000,总支出!$B$4:$B$5000,">="&DATE(VALUE(LEFT($A31,4)),VALUE(RIGHT($A31,2)),1),总支出!$B$4:$B$5000,"<"&DATE(VALUE(LEFT($A31,4)),VALUE(RIGHT($A31,2))+1,1),总支出!$H$4:$H$5000,"投资转账") -> 0 | N31: =SUMIFS(总支出!$D$4:$D$5000,总支出!$B$4:$B$5000,">="&DATE(VALUE(LEFT($A31,4)),VALUE(RIGHT($A31,2)),1),总支出!$B$4:$B$5000,"<"&DATE(VALUE(LEFT($A31,4)),VALUE(RIGHT($A31,2))+1,1),总支出!$H$4:$H$5000,"内部转账") -> 0 | O31: =SUMIFS(税费计算明细!$S$4:$S$5000,税费计算明细!$C$4:$C$5000,$A31) -> 0
A32: 2026-05 | B32: =SUMIFS(总收入!$D$4:$D$5000,总收入!$B$4:$B$5000,">="&DATE(VALUE(LEFT($A32,4)),VALUE(RIGHT($A32,2)),1),总收入!$B$4:$B$5000,"<"&DATE(VALUE(LEFT($A32,4)),VALUE(RIGHT($A32,2))+1,1)) -> 0 | C32: =SUMIFS(总支出!$D$4:$D$5000,总支出!$B$4:$B$5000,">="&DATE(VALUE(LEFT($A32,4)),VALUE(RIGHT($A32,2)),1),总支出!$B$4:$B$5000,"<"&DATE(VALUE(LEFT($A32,4)),VALUE(RIGHT($A32,2))+1,1),总支出!$H$4:$H$5000,"个人支出") -> 0 | D32: =SUMIFS(总支出!$D$4:$D$5000,总支出!$B$4:$B$5000,">="&DATE(VALUE(LEFT($A32,4)),VALUE(RIGHT($A32,2)),1),总支出!$B$4:$B$5000,"<"&DATE(VALUE(LEFT($A32,4)),VALUE(RIGHT($A32,2))+1,1),总支出!$H$4:$H$5000,"个人支出",总支出!$G$4:$G$5000,"必要") -> 0 | E32: =SUMIFS(总支出!$D$4:$D$5000,总支出!$B$4:$B$5000,">="&DATE(VALUE(LEFT($A32,4)),VALUE(RIGHT($A32,2)),1),总支出!$B$4:$B$5000,"<"&DATE(VALUE(LEFT($A32,4)),VALUE(RIGHT($A32,2))+1,1),总支出!$H$4:$H$5000,"个人支出",总支出!$G$4:$G$5000,"弹性") -> 0 | F32: =SUMIFS(总支出!$D$4:$D$5000,总支出!$B$4:$B$5000,">="&DATE(VALUE(LEFT($A32,4)),VALUE(RIGHT($A32,2)),1),总支出!$B$4:$B$5000,"<"&DATE(VALUE(LEFT($A32,4)),VALUE(RIGHT($A32,2))+1,1),总支出!$H$4:$H$5000,"个人支出",总支出!$F$4:$F$5000,"固定") -> 0 | G32: =SUMIFS(总支出!$D$4:$D$5000,总支出!$B$4:$B$5000,">="&DATE(VALUE(LEFT($A32,4)),VALUE(RIGHT($A32,2)),1),总支出!$B$4:$B$5000,"<"&DATE(VALUE(LEFT($A32,4)),VALUE(RIGHT($A32,2))+1,1),总支出!$H$4:$H$5000,"个人支出",总支出!$F$4:$F$5000,"可变") -> 0 | H32: =SUMIFS(总支出!$D$4:$D$5000,总支出!$B$4:$B$5000,">="&DATE(VALUE(LEFT($A32,4)),VALUE(RIGHT($A32,2)),1),总支出!$B$4:$B$5000,"<"&DATE(VALUE(LEFT($A32,4)),VALUE(RIGHT($A32,2))+1,1),总支出!$H$4:$H$5000,"个人支出",总支出!$F$4:$F$5000,"一次性") -> 0 | I32: =SUMIFS(总支出!$D$4:$D$5000,总支出!$B$4:$B$5000,">="&DATE(VALUE(LEFT($A32,4)),VALUE(RIGHT($A32,2)),1),总支出!$B$4:$B$5000,"<"&DATE(VALUE(LEFT($A32,4)),VALUE(RIGHT($A32,2))+1,1),总支出!$H$4:$H$5000,"个人支出",总支出!$E$4:$E$5000,"住房") -> 0 | J32: =B32-C32 -> 0 | K32: =IF(OR(B32>0,C32>0),1,0) -> 0 | L32: =SUMIFS(总支出!$D$4:$D$5000,总支出!$B$4:$B$5000,">="&DATE(VALUE(LEFT($A32,4)),VALUE(RIGHT($A32,2)),1),总支出!$B$4:$B$5000,"<"&DATE(VALUE(LEFT($A32,4)),VALUE(RIGHT($A32,2))+1,1),总支出!$H$4:$H$5000,"房产支出") -> 0 | M32: =SUMIFS(总支出!$D$4:$D$5000,总支出!$B$4:$B$5000,">="&DATE(VALUE(LEFT($A32,4)),VALUE(RIGHT($A32,2)),1),总支出!$B$4:$B$5000,"<"&DATE(VALUE(LEFT($A32,4)),VALUE(RIGHT($A32,2))+1,1),总支出!$H$4:$H$5000,"投资转账") -> 0 | N32: =SUMIFS(总支出!$D$4:$D$5000,总支出!$B$4:$B$5000,">="&DATE(VALUE(LEFT($A32,4)),VALUE(RIGHT($A32,2)),1),总支出!$B$4:$B$5000,"<"&DATE(VALUE(LEFT($A32,4)),VALUE(RIGHT($A32,2))+1,1),总支出!$H$4:$H$5000,"内部转账") -> 0 | O32: =SUMIFS(税费计算明细!$S$4:$S$5000,税费计算明细!$C$4:$C$5000,$A32) -> 0
A33: 2026-06 | B33: =SUMIFS(总收入!$D$4:$D$5000,总收入!$B$4:$B$5000,">="&DATE(VALUE(LEFT($A33,4)),VALUE(RIGHT($A33,2)),1),总收入!$B$4:$B$5000,"<"&DATE(VALUE(LEFT($A33,4)),VALUE(RIGHT($A33,2))+1,1)) -> 0 | C33: =SUMIFS(总支出!$D$4:$D$5000,总支出!$B$4:$B$5000,">="&DATE(VALUE(LEFT($A33,4)),VALUE(RIGHT($A33,2)),1),总支出!$B$4:$B$5000,"<"&DATE(VALUE(LEFT($A33,4)),VALUE(RIGHT($A33,2))+1,1),总支出!$H$4:$H$5000,"个人支出") -> 0 | D33: =SUMIFS(总支出!$D$4:$D$5000,总支出!$B$4:$B$5000,">="&DATE(VALUE(LEFT($A33,4)),VALUE(RIGHT($A33,2)),1),总支出!$B$4:$B$5000,"<"&DATE(VALUE(LEFT($A33,4)),VALUE(RIGHT($A33,2))+1,1),总支出!$H$4:$H$5000,"个人支出",总支出!$G$4:$G$5000,"必要") -> 0 | E33: =SUMIFS(总支出!$D$4:$D$5000,总支出!$B$4:$B$5000,">="&DATE(VALUE(LEFT($A33,4)),VALUE(RIGHT($A33,2)),1),总支出!$B$4:$B$5000,"<"&DATE(VALUE(LEFT($A33,4)),VALUE(RIGHT($A33,2))+1,1),总支出!$H$4:$H$5000,"个人支出",总支出!$G$4:$G$5000,"弹性") -> 0 | F33: =SUMIFS(总支出!$D$4:$D$5000,总支出!$B$4:$B$5000,">="&DATE(VALUE(LEFT($A33,4)),VALUE(RIGHT($A33,2)),1),总支出!$B$4:$B$5000,"<"&DATE(VALUE(LEFT($A33,4)),VALUE(RIGHT($A33,2))+1,1),总支出!$H$4:$H$5000,"个人支出",总支出!$F$4:$F$5000,"固定") -> 0 | G33: =SUMIFS(总支出!$D$4:$D$5000,总支出!$B$4:$B$5000,">="&DATE(VALUE(LEFT($A33,4)),VALUE(RIGHT($A33,2)),1),总支出!$B$4:$B$5000,"<"&DATE(VALUE(LEFT($A33,4)),VALUE(RIGHT($A33,2))+1,1),总支出!$H$4:$H$5000,"个人支出",总支出!$F$4:$F$5000,"可变") -> 0 | H33: =SUMIFS(总支出!$D$4:$D$5000,总支出!$B$4:$B$5000,">="&DATE(VALUE(LEFT($A33,4)),VALUE(RIGHT($A33,2)),1),总支出!$B$4:$B$5000,"<"&DATE(VALUE(LEFT($A33,4)),VALUE(RIGHT($A33,2))+1,1),总支出!$H$4:$H$5000,"个人支出",总支出!$F$4:$F$5000,"一次性") -> 0 | I33: =SUMIFS(总支出!$D$4:$D$5000,总支出!$B$4:$B$5000,">="&DATE(VALUE(LEFT($A33,4)),VALUE(RIGHT($A33,2)),1),总支出!$B$4:$B$5000,"<"&DATE(VALUE(LEFT($A33,4)),VALUE(RIGHT($A33,2))+1,1),总支出!$H$4:$H$5000,"个人支出",总支出!$E$4:$E$5000,"住房") -> 0 | J33: =B33-C33 -> 0 | K33: =IF(OR(B33>0,C33>0),1,0) -> 0 | L33: =SUMIFS(总支出!$D$4:$D$5000,总支出!$B$4:$B$5000,">="&DATE(VALUE(LEFT($A33,4)),VALUE(RIGHT($A33,2)),1),总支出!$B$4:$B$5000,"<"&DATE(VALUE(LEFT($A33,4)),VALUE(RIGHT($A33,2))+1,1),总支出!$H$4:$H$5000,"房产支出") -> 0 | M33: =SUMIFS(总支出!$D$4:$D$5000,总支出!$B$4:$B$5000,">="&DATE(VALUE(LEFT($A33,4)),VALUE(RIGHT($A33,2)),1),总支出!$B$4:$B$5000,"<"&DATE(VALUE(LEFT($A33,4)),VALUE(RIGHT($A33,2))+1,1),总支出!$H$4:$H$5000,"投资转账") -> 0 | N33: =SUMIFS(总支出!$D$4:$D$5000,总支出!$B$4:$B$5000,">="&DATE(VALUE(LEFT($A33,4)),VALUE(RIGHT($A33,2)),1),总支出!$B$4:$B$5000,"<"&DATE(VALUE(LEFT($A33,4)),VALUE(RIGHT($A33,2))+1,1),总支出!$H$4:$H$5000,"内部转账") -> 0 | O33: =SUMIFS(税费计算明细!$S$4:$S$5000,税费计算明细!$C$4:$C$5000,$A33) -> 0
A34: 2026-07 | B34: =SUMIFS(总收入!$D$4:$D$5000,总收入!$B$4:$B$5000,">="&DATE(VALUE(LEFT($A34,4)),VALUE(RIGHT($A34,2)),1),总收入!$B$4:$B$5000,"<"&DATE(VALUE(LEFT($A34,4)),VALUE(RIGHT($A34,2))+1,1)) -> 0 | C34: =SUMIFS(总支出!$D$4:$D$5000,总支出!$B$4:$B$5000,">="&DATE(VALUE(LEFT($A34,4)),VALUE(RIGHT($A34,2)),1),总支出!$B$4:$B$5000,"<"&DATE(VALUE(LEFT($A34,4)),VALUE(RIGHT($A34,2))+1,1),总支出!$H$4:$H$5000,"个人支出") -> 0 | D34: =SUMIFS(总支出!$D$4:$D$5000,总支出!$B$4:$B$5000,">="&DATE(VALUE(LEFT($A34,4)),VALUE(RIGHT($A34,2)),1),总支出!$B$4:$B$5000,"<"&DATE(VALUE(LEFT($A34,4)),VALUE(RIGHT($A34,2))+1,1),总支出!$H$4:$H$5000,"个人支出",总支出!$G$4:$G$5000,"必要") -> 0 | E34: =SUMIFS(总支出!$D$4:$D$5000,总支出!$B$4:$B$5000,">="&DATE(VALUE(LEFT($A34,4)),VALUE(RIGHT($A34,2)),1),总支出!$B$4:$B$5000,"<"&DATE(VALUE(LEFT($A34,4)),VALUE(RIGHT($A34,2))+1,1),总支出!$H$4:$H$5000,"个人支出",总支出!$G$4:$G$5000,"弹性") -> 0 | F34: =SUMIFS(总支出!$D$4:$D$5000,总支出!$B$4:$B$5000,">="&DATE(VALUE(LEFT($A34,4)),VALUE(RIGHT($A34,2)),1),总支出!$B$4:$B$5000,"<"&DATE(VALUE(LEFT($A34,4)),VALUE(RIGHT($A34,2))+1,1),总支出!$H$4:$H$5000,"个人支出",总支出!$F$4:$F$5000,"固定") -> 0 | G34: =SUMIFS(总支出!$D$4:$D$5000,总支出!$B$4:$B$5000,">="&DATE(VALUE(LEFT($A34,4)),VALUE(RIGHT($A34,2)),1),总支出!$B$4:$B$5000,"<"&DATE(VALUE(LEFT($A34,4)),VALUE(RIGHT($A34,2))+1,1),总支出!$H$4:$H$5000,"个人支出",总支出!$F$4:$F$5000,"可变") -> 0 | H34: =SUMIFS(总支出!$D$4:$D$5000,总支出!$B$4:$B$5000,">="&DATE(VALUE(LEFT($A34,4)),VALUE(RIGHT($A34,2)),1),总支出!$B$4:$B$5000,"<"&DATE(VALUE(LEFT($A34,4)),VALUE(RIGHT($A34,2))+1,1),总支出!$H$4:$H$5000,"个人支出",总支出!$F$4:$F$5000,"一次性") -> 0 | I34: =SUMIFS(总支出!$D$4:$D$5000,总支出!$B$4:$B$5000,">="&DATE(VALUE(LEFT($A34,4)),VALUE(RIGHT($A34,2)),1),总支出!$B$4:$B$5000,"<"&DATE(VALUE(LEFT($A34,4)),VALUE(RIGHT($A34,2))+1,1),总支出!$H$4:$H$5000,"个人支出",总支出!$E$4:$E$5000,"住房") -> 0 | J34: =B34-C34 -> 0 | K34: =IF(OR(B34>0,C34>0),1,0) -> 0 | L34: =SUMIFS(总支出!$D$4:$D$5000,总支出!$B$4:$B$5000,">="&DATE(VALUE(LEFT($A34,4)),VALUE(RIGHT($A34,2)),1),总支出!$B$4:$B$5000,"<"&DATE(VALUE(LEFT($A34,4)),VALUE(RIGHT($A34,2))+1,1),总支出!$H$4:$H$5000,"房产支出") -> 0 | M34: =SUMIFS(总支出!$D$4:$D$5000,总支出!$B$4:$B$5000,">="&DATE(VALUE(LEFT($A34,4)),VALUE(RIGHT($A34,2)),1),总支出!$B$4:$B$5000,"<"&DATE(VALUE(LEFT($A34,4)),VALUE(RIGHT($A34,2))+1,1),总支出!$H$4:$H$5000,"投资转账") -> 0 | N34: =SUMIFS(总支出!$D$4:$D$5000,总支出!$B$4:$B$5000,">="&DATE(VALUE(LEFT($A34,4)),VALUE(RIGHT($A34,2)),1),总支出!$B$4:$B$5000,"<"&DATE(VALUE(LEFT($A34,4)),VALUE(RIGHT($A34,2))+1,1),总支出!$H$4:$H$5000,"内部转账") -> 0 | O34: =SUMIFS(税费计算明细!$S$4:$S$5000,税费计算明细!$C$4:$C$5000,$A34) -> 0
A35: 2026-08 | B35: =SUMIFS(总收入!$D$4:$D$5000,总收入!$B$4:$B$5000,">="&DATE(VALUE(LEFT($A35,4)),VALUE(RIGHT($A35,2)),1),总收入!$B$4:$B$5000,"<"&DATE(VALUE(LEFT($A35,4)),VALUE(RIGHT($A35,2))+1,1)) -> 0 | C35: =SUMIFS(总支出!$D$4:$D$5000,总支出!$B$4:$B$5000,">="&DATE(VALUE(LEFT($A35,4)),VALUE(RIGHT($A35,2)),1),总支出!$B$4:$B$5000,"<"&DATE(VALUE(LEFT($A35,4)),VALUE(RIGHT($A35,2))+1,1),总支出!$H$4:$H$5000,"个人支出") -> 0 | D35: =SUMIFS(总支出!$D$4:$D$5000,总支出!$B$4:$B$5000,">="&DATE(VALUE(LEFT($A35,4)),VALUE(RIGHT($A35,2)),1),总支出!$B$4:$B$5000,"<"&DATE(VALUE(LEFT($A35,4)),VALUE(RIGHT($A35,2))+1,1),总支出!$H$4:$H$5000,"个人支出",总支出!$G$4:$G$5000,"必要") -> 0 | E35: =SUMIFS(总支出!$D$4:$D$5000,总支出!$B$4:$B$5000,">="&DATE(VALUE(LEFT($A35,4)),VALUE(RIGHT($A35,2)),1),总支出!$B$4:$B$5000,"<"&DATE(VALUE(LEFT($A35,4)),VALUE(RIGHT($A35,2))+1,1),总支出!$H$4:$H$5000,"个人支出",总支出!$G$4:$G$5000,"弹性") -> 0 | F35: =SUMIFS(总支出!$D$4:$D$5000,总支出!$B$4:$B$5000,">="&DATE(VALUE(LEFT($A35,4)),VALUE(RIGHT($A35,2)),1),总支出!$B$4:$B$5000,"<"&DATE(VALUE(LEFT($A35,4)),VALUE(RIGHT($A35,2))+1,1),总支出!$H$4:$H$5000,"个人支出",总支出!$F$4:$F$5000,"固定") -> 0 | G35: =SUMIFS(总支出!$D$4:$D$5000,总支出!$B$4:$B$5000,">="&DATE(VALUE(LEFT($A35,4)),VALUE(RIGHT($A35,2)),1),总支出!$B$4:$B$5000,"<"&DATE(VALUE(LEFT($A35,4)),VALUE(RIGHT($A35,2))+1,1),总支出!$H$4:$H$5000,"个人支出",总支出!$F$4:$F$5000,"可变") -> 0 | H35: =SUMIFS(总支出!$D$4:$D$5000,总支出!$B$4:$B$5000,">="&DATE(VALUE(LEFT($A35,4)),VALUE(RIGHT($A35,2)),1),总支出!$B$4:$B$5000,"<"&DATE(VALUE(LEFT($A35,4)),VALUE(RIGHT($A35,2))+1,1),总支出!$H$4:$H$5000,"个人支出",总支出!$F$4:$F$5000,"一次性") -> 0 | I35: =SUMIFS(总支出!$D$4:$D$5000,总支出!$B$4:$B$5000,">="&DATE(VALUE(LEFT($A35,4)),VALUE(RIGHT($A35,2)),1),总支出!$B$4:$B$5000,"<"&DATE(VALUE(LEFT($A35,4)),VALUE(RIGHT($A35,2))+1,1),总支出!$H$4:$H$5000,"个人支出",总支出!$E$4:$E$5000,"住房") -> 0 | J35: =B35-C35 -> 0 | K35: =IF(OR(B35>0,C35>0),1,0) -> 0 | L35: =SUMIFS(总支出!$D$4:$D$5000,总支出!$B$4:$B$5000,">="&DATE(VALUE(LEFT($A35,4)),VALUE(RIGHT($A35,2)),1),总支出!$B$4:$B$5000,"<"&DATE(VALUE(LEFT($A35,4)),VALUE(RIGHT($A35,2))+1,1),总支出!$H$4:$H$5000,"房产支出") -> 0 | M35: =SUMIFS(总支出!$D$4:$D$5000,总支出!$B$4:$B$5000,">="&DATE(VALUE(LEFT($A35,4)),VALUE(RIGHT($A35,2)),1),总支出!$B$4:$B$5000,"<"&DATE(VALUE(LEFT($A35,4)),VALUE(RIGHT($A35,2))+1,1),总支出!$H$4:$H$5000,"投资转账") -> 0 | N35: =SUMIFS(总支出!$D$4:$D$5000,总支出!$B$4:$B$5000,">="&DATE(VALUE(LEFT($A35,4)),VALUE(RIGHT($A35,2)),1),总支出!$B$4:$B$5000,"<"&DATE(VALUE(LEFT($A35,4)),VALUE(RIGHT($A35,2))+1,1),总支出!$H$4:$H$5000,"内部转账") -> 0 | O35: =SUMIFS(税费计算明细!$S$4:$S$5000,税费计算明细!$C$4:$C$5000,$A35) -> 0
A36: 2026-09 | B36: =SUMIFS(总收入!$D$4:$D$5000,总收入!$B$4:$B$5000,">="&DATE(VALUE(LEFT($A36,4)),VALUE(RIGHT($A36,2)),1),总收入!$B$4:$B$5000,"<"&DATE(VALUE(LEFT($A36,4)),VALUE(RIGHT($A36,2))+1,1)) -> 0 | C36: =SUMIFS(总支出!$D$4:$D$5000,总支出!$B$4:$B$5000,">="&DATE(VALUE(LEFT($A36,4)),VALUE(RIGHT($A36,2)),1),总支出!$B$4:$B$5000,"<"&DATE(VALUE(LEFT($A36,4)),VALUE(RIGHT($A36,2))+1,1),总支出!$H$4:$H$5000,"个人支出") -> 0 | D36: =SUMIFS(总支出!$D$4:$D$5000,总支出!$B$4:$B$5000,">="&DATE(VALUE(LEFT($A36,4)),VALUE(RIGHT($A36,2)),1),总支出!$B$4:$B$5000,"<"&DATE(VALUE(LEFT($A36,4)),VALUE(RIGHT($A36,2))+1,1),总支出!$H$4:$H$5000,"个人支出",总支出!$G$4:$G$5000,"必要") -> 0 | E36: =SUMIFS(总支出!$D$4:$D$5000,总支出!$B$4:$B$5000,">="&DATE(VALUE(LEFT($A36,4)),VALUE(RIGHT($A36,2)),1),总支出!$B$4:$B$5000,"<"&DATE(VALUE(LEFT($A36,4)),VALUE(RIGHT($A36,2))+1,1),总支出!$H$4:$H$5000,"个人支出",总支出!$G$4:$G$5000,"弹性") -> 0 | F36: =SUMIFS(总支出!$D$4:$D$5000,总支出!$B$4:$B$5000,">="&DATE(VALUE(LEFT($A36,4)),VALUE(RIGHT($A36,2)),1),总支出!$B$4:$B$5000,"<"&DATE(VALUE(LEFT($A36,4)),VALUE(RIGHT($A36,2))+1,1),总支出!$H$4:$H$5000,"个人支出",总支出!$F$4:$F$5000,"固定") -> 0 | G36: =SUMIFS(总支出!$D$4:$D$5000,总支出!$B$4:$B$5000,">="&DATE(VALUE(LEFT($A36,4)),VALUE(RIGHT($A36,2)),1),总支出!$B$4:$B$5000,"<"&DATE(VALUE(LEFT($A36,4)),VALUE(RIGHT($A36,2))+1,1),总支出!$H$4:$H$5000,"个人支出",总支出!$F$4:$F$5000,"可变") -> 0 | H36: =SUMIFS(总支出!$D$4:$D$5000,总支出!$B$4:$B$5000,">="&DATE(VALUE(LEFT($A36,4)),VALUE(RIGHT($A36,2)),1),总支出!$B$4:$B$5000,"<"&DATE(VALUE(LEFT($A36,4)),VALUE(RIGHT($A36,2))+1,1),总支出!$H$4:$H$5000,"个人支出",总支出!$F$4:$F$5000,"一次性") -> 0 | I36: =SUMIFS(总支出!$D$4:$D$5000,总支出!$B$4:$B$5000,">="&DATE(VALUE(LEFT($A36,4)),VALUE(RIGHT($A36,2)),1),总支出!$B$4:$B$5000,"<"&DATE(VALUE(LEFT($A36,4)),VALUE(RIGHT($A36,2))+1,1),总支出!$H$4:$H$5000,"个人支出",总支出!$E$4:$E$5000,"住房") -> 0 | J36: =B36-C36 -> 0 | K36: =IF(OR(B36>0,C36>0),1,0) -> 0 | L36: =SUMIFS(总支出!$D$4:$D$5000,总支出!$B$4:$B$5000,">="&DATE(VALUE(LEFT($A36,4)),VALUE(RIGHT($A36,2)),1),总支出!$B$4:$B$5000,"<"&DATE(VALUE(LEFT($A36,4)),VALUE(RIGHT($A36,2))+1,1),总支出!$H$4:$H$5000,"房产支出") -> 0 | M36: =SUMIFS(总支出!$D$4:$D$5000,总支出!$B$4:$B$5000,">="&DATE(VALUE(LEFT($A36,4)),VALUE(RIGHT($A36,2)),1),总支出!$B$4:$B$5000,"<"&DATE(VALUE(LEFT($A36,4)),VALUE(RIGHT($A36,2))+1,1),总支出!$H$4:$H$5000,"投资转账") -> 0 | N36: =SUMIFS(总支出!$D$4:$D$5000,总支出!$B$4:$B$5000,">="&DATE(VALUE(LEFT($A36,4)),VALUE(RIGHT($A36,2)),1),总支出!$B$4:$B$5000,"<"&DATE(VALUE(LEFT($A36,4)),VALUE(RIGHT($A36,2))+1,1),总支出!$H$4:$H$5000,"内部转账") -> 0 | O36: =SUMIFS(税费计算明细!$S$4:$S$5000,税费计算明细!$C$4:$C$5000,$A36) -> 0
A37: 2026-10 | B37: =SUMIFS(总收入!$D$4:$D$5000,总收入!$B$4:$B$5000,">="&DATE(VALUE(LEFT($A37,4)),VALUE(RIGHT($A37,2)),1),总收入!$B$4:$B$5000,"<"&DATE(VALUE(LEFT($A37,4)),VALUE(RIGHT($A37,2))+1,1)) -> 0 | C37: =SUMIFS(总支出!$D$4:$D$5000,总支出!$B$4:$B$5000,">="&DATE(VALUE(LEFT($A37,4)),VALUE(RIGHT($A37,2)),1),总支出!$B$4:$B$5000,"<"&DATE(VALUE(LEFT($A37,4)),VALUE(RIGHT($A37,2))+1,1),总支出!$H$4:$H$5000,"个人支出") -> 0 | D37: =SUMIFS(总支出!$D$4:$D$5000,总支出!$B$4:$B$5000,">="&DATE(VALUE(LEFT($A37,4)),VALUE(RIGHT($A37,2)),1),总支出!$B$4:$B$5000,"<"&DATE(VALUE(LEFT($A37,4)),VALUE(RIGHT($A37,2))+1,1),总支出!$H$4:$H$5000,"个人支出",总支出!$G$4:$G$5000,"必要") -> 0 | E37: =SUMIFS(总支出!$D$4:$D$5000,总支出!$B$4:$B$5000,">="&DATE(VALUE(LEFT($A37,4)),VALUE(RIGHT($A37,2)),1),总支出!$B$4:$B$5000,"<"&DATE(VALUE(LEFT($A37,4)),VALUE(RIGHT($A37,2))+1,1),总支出!$H$4:$H$5000,"个人支出",总支出!$G$4:$G$5000,"弹性") -> 0 | F37: =SUMIFS(总支出!$D$4:$D$5000,总支出!$B$4:$B$5000,">="&DATE(VALUE(LEFT($A37,4)),VALUE(RIGHT($A37,2)),1),总支出!$B$4:$B$5000,"<"&DATE(VALUE(LEFT($A37,4)),VALUE(RIGHT($A37,2))+1,1),总支出!$H$4:$H$5000,"个人支出",总支出!$F$4:$F$5000,"固定") -> 0 | G37: =SUMIFS(总支出!$D$4:$D$5000,总支出!$B$4:$B$5000,">="&DATE(VALUE(LEFT($A37,4)),VALUE(RIGHT($A37,2)),1),总支出!$B$4:$B$5000,"<"&DATE(VALUE(LEFT($A37,4)),VALUE(RIGHT($A37,2))+1,1),总支出!$H$4:$H$5000,"个人支出",总支出!$F$4:$F$5000,"可变") -> 0 | H37: =SUMIFS(总支出!$D$4:$D$5000,总支出!$B$4:$B$5000,">="&DATE(VALUE(LEFT($A37,4)),VALUE(RIGHT($A37,2)),1),总支出!$B$4:$B$5000,"<"&DATE(VALUE(LEFT($A37,4)),VALUE(RIGHT($A37,2))+1,1),总支出!$H$4:$H$5000,"个人支出",总支出!$F$4:$F$5000,"一次性") -> 0 | I37: =SUMIFS(总支出!$D$4:$D$5000,总支出!$B$4:$B$5000,">="&DATE(VALUE(LEFT($A37,4)),VALUE(RIGHT($A37,2)),1),总支出!$B$4:$B$5000,"<"&DATE(VALUE(LEFT($A37,4)),VALUE(RIGHT($A37,2))+1,1),总支出!$H$4:$H$5000,"个人支出",总支出!$E$4:$E$5000,"住房") -> 0 | J37: =B37-C37 -> 0 | K37: =IF(OR(B37>0,C37>0),1,0) -> 0 | L37: =SUMIFS(总支出!$D$4:$D$5000,总支出!$B$4:$B$5000,">="&DATE(VALUE(LEFT($A37,4)),VALUE(RIGHT($A37,2)),1),总支出!$B$4:$B$5000,"<"&DATE(VALUE(LEFT($A37,4)),VALUE(RIGHT($A37,2))+1,1),总支出!$H$4:$H$5000,"房产支出") -> 0 | M37: =SUMIFS(总支出!$D$4:$D$5000,总支出!$B$4:$B$5000,">="&DATE(VALUE(LEFT($A37,4)),VALUE(RIGHT($A37,2)),1),总支出!$B$4:$B$5000,"<"&DATE(VALUE(LEFT($A37,4)),VALUE(RIGHT($A37,2))+1,1),总支出!$H$4:$H$5000,"投资转账") -> 0 | N37: =SUMIFS(总支出!$D$4:$D$5000,总支出!$B$4:$B$5000,">="&DATE(VALUE(LEFT($A37,4)),VALUE(RIGHT($A37,2)),1),总支出!$B$4:$B$5000,"<"&DATE(VALUE(LEFT($A37,4)),VALUE(RIGHT($A37,2))+1,1),总支出!$H$4:$H$5000,"内部转账") -> 0 | O37: =SUMIFS(税费计算明细!$S$4:$S$5000,税费计算明细!$C$4:$C$5000,$A37) -> 0
A38: 2026-11 | B38: =SUMIFS(总收入!$D$4:$D$5000,总收入!$B$4:$B$5000,">="&DATE(VALUE(LEFT($A38,4)),VALUE(RIGHT($A38,2)),1),总收入!$B$4:$B$5000,"<"&DATE(VALUE(LEFT($A38,4)),VALUE(RIGHT($A38,2))+1,1)) -> 0 | C38: =SUMIFS(总支出!$D$4:$D$5000,总支出!$B$4:$B$5000,">="&DATE(VALUE(LEFT($A38,4)),VALUE(RIGHT($A38,2)),1),总支出!$B$4:$B$5000,"<"&DATE(VALUE(LEFT($A38,4)),VALUE(RIGHT($A38,2))+1,1),总支出!$H$4:$H$5000,"个人支出") -> 0 | D38: =SUMIFS(总支出!$D$4:$D$5000,总支出!$B$4:$B$5000,">="&DATE(VALUE(LEFT($A38,4)),VALUE(RIGHT($A38,2)),1),总支出!$B$4:$B$5000,"<"&DATE(VALUE(LEFT($A38,4)),VALUE(RIGHT($A38,2))+1,1),总支出!$H$4:$H$5000,"个人支出",总支出!$G$4:$G$5000,"必要") -> 0 | E38: =SUMIFS(总支出!$D$4:$D$5000,总支出!$B$4:$B$5000,">="&DATE(VALUE(LEFT($A38,4)),VALUE(RIGHT($A38,2)),1),总支出!$B$4:$B$5000,"<"&DATE(VALUE(LEFT($A38,4)),VALUE(RIGHT($A38,2))+1,1),总支出!$H$4:$H$5000,"个人支出",总支出!$G$4:$G$5000,"弹性") -> 0 | F38: =SUMIFS(总支出!$D$4:$D$5000,总支出!$B$4:$B$5000,">="&DATE(VALUE(LEFT($A38,4)),VALUE(RIGHT($A38,2)),1),总支出!$B$4:$B$5000,"<"&DATE(VALUE(LEFT($A38,4)),VALUE(RIGHT($A38,2))+1,1),总支出!$H$4:$H$5000,"个人支出",总支出!$F$4:$F$5000,"固定") -> 0 | G38: =SUMIFS(总支出!$D$4:$D$5000,总支出!$B$4:$B$5000,">="&DATE(VALUE(LEFT($A38,4)),VALUE(RIGHT($A38,2)),1),总支出!$B$4:$B$5000,"<"&DATE(VALUE(LEFT($A38,4)),VALUE(RIGHT($A38,2))+1,1),总支出!$H$4:$H$5000,"个人支出",总支出!$F$4:$F$5000,"可变") -> 0 | H38: =SUMIFS(总支出!$D$4:$D$5000,总支出!$B$4:$B$5000,">="&DATE(VALUE(LEFT($A38,4)),VALUE(RIGHT($A38,2)),1),总支出!$B$4:$B$5000,"<"&DATE(VALUE(LEFT($A38,4)),VALUE(RIGHT($A38,2))+1,1),总支出!$H$4:$H$5000,"个人支出",总支出!$F$4:$F$5000,"一次性") -> 0 | I38: =SUMIFS(总支出!$D$4:$D$5000,总支出!$B$4:$B$5000,">="&DATE(VALUE(LEFT($A38,4)),VALUE(RIGHT($A38,2)),1),总支出!$B$4:$B$5000,"<"&DATE(VALUE(LEFT($A38,4)),VALUE(RIGHT($A38,2))+1,1),总支出!$H$4:$H$5000,"个人支出",总支出!$E$4:$E$5000,"住房") -> 0 | J38: =B38-C38 -> 0 | K38: =IF(OR(B38>0,C38>0),1,0) -> 0 | L38: =SUMIFS(总支出!$D$4:$D$5000,总支出!$B$4:$B$5000,">="&DATE(VALUE(LEFT($A38,4)),VALUE(RIGHT($A38,2)),1),总支出!$B$4:$B$5000,"<"&DATE(VALUE(LEFT($A38,4)),VALUE(RIGHT($A38,2))+1,1),总支出!$H$4:$H$5000,"房产支出") -> 0 | M38: =SUMIFS(总支出!$D$4:$D$5000,总支出!$B$4:$B$5000,">="&DATE(VALUE(LEFT($A38,4)),VALUE(RIGHT($A38,2)),1),总支出!$B$4:$B$5000,"<"&DATE(VALUE(LEFT($A38,4)),VALUE(RIGHT($A38,2))+1,1),总支出!$H$4:$H$5000,"投资转账") -> 0 | N38: =SUMIFS(总支出!$D$4:$D$5000,总支出!$B$4:$B$5000,">="&DATE(VALUE(LEFT($A38,4)),VALUE(RIGHT($A38,2)),1),总支出!$B$4:$B$5000,"<"&DATE(VALUE(LEFT($A38,4)),VALUE(RIGHT($A38,2))+1,1),总支出!$H$4:$H$5000,"内部转账") -> 0 | O38: =SUMIFS(税费计算明细!$S$4:$S$5000,税费计算明细!$C$4:$C$5000,$A38) -> 0
A39: 2026-12 | B39: =SUMIFS(总收入!$D$4:$D$5000,总收入!$B$4:$B$5000,">="&DATE(VALUE(LEFT($A39,4)),VALUE(RIGHT($A39,2)),1),总收入!$B$4:$B$5000,"<"&DATE(VALUE(LEFT($A39,4)),VALUE(RIGHT($A39,2))+1,1)) -> 0 | C39: =SUMIFS(总支出!$D$4:$D$5000,总支出!$B$4:$B$5000,">="&DATE(VALUE(LEFT($A39,4)),VALUE(RIGHT($A39,2)),1),总支出!$B$4:$B$5000,"<"&DATE(VALUE(LEFT($A39,4)),VALUE(RIGHT($A39,2))+1,1),总支出!$H$4:$H$5000,"个人支出") -> 0 | D39: =SUMIFS(总支出!$D$4:$D$5000,总支出!$B$4:$B$5000,">="&DATE(VALUE(LEFT($A39,4)),VALUE(RIGHT($A39,2)),1),总支出!$B$4:$B$5000,"<"&DATE(VALUE(LEFT($A39,4)),VALUE(RIGHT($A39,2))+1,1),总支出!$H$4:$H$5000,"个人支出",总支出!$G$4:$G$5000,"必要") -> 0 | E39: =SUMIFS(总支出!$D$4:$D$5000,总支出!$B$4:$B$5000,">="&DATE(VALUE(LEFT($A39,4)),VALUE(RIGHT($A39,2)),1),总支出!$B$4:$B$5000,"<"&DATE(VALUE(LEFT($A39,4)),VALUE(RIGHT($A39,2))+1,1),总支出!$H$4:$H$5000,"个人支出",总支出!$G$4:$G$5000,"弹性") -> 0 | F39: =SUMIFS(总支出!$D$4:$D$5000,总支出!$B$4:$B$5000,">="&DATE(VALUE(LEFT($A39,4)),VALUE(RIGHT($A39,2)),1),总支出!$B$4:$B$5000,"<"&DATE(VALUE(LEFT($A39,4)),VALUE(RIGHT($A39,2))+1,1),总支出!$H$4:$H$5000,"个人支出",总支出!$F$4:$F$5000,"固定") -> 0 | G39: =SUMIFS(总支出!$D$4:$D$5000,总支出!$B$4:$B$5000,">="&DATE(VALUE(LEFT($A39,4)),VALUE(RIGHT($A39,2)),1),总支出!$B$4:$B$5000,"<"&DATE(VALUE(LEFT($A39,4)),VALUE(RIGHT($A39,2))+1,1),总支出!$H$4:$H$5000,"个人支出",总支出!$F$4:$F$5000,"可变") -> 0 | H39: =SUMIFS(总支出!$D$4:$D$5000,总支出!$B$4:$B$5000,">="&DATE(VALUE(LEFT($A39,4)),VALUE(RIGHT($A39,2)),1),总支出!$B$4:$B$5000,"<"&DATE(VALUE(LEFT($A39,4)),VALUE(RIGHT($A39,2))+1,1),总支出!$H$4:$H$5000,"个人支出",总支出!$F$4:$F$5000,"一次性") -> 0 | I39: =SUMIFS(总支出!$D$4:$D$5000,总支出!$B$4:$B$5000,">="&DATE(VALUE(LEFT($A39,4)),VALUE(RIGHT($A39,2)),1),总支出!$B$4:$B$5000,"<"&DATE(VALUE(LEFT($A39,4)),VALUE(RIGHT($A39,2))+1,1),总支出!$H$4:$H$5000,"个人支出",总支出!$E$4:$E$5000,"住房") -> 0 | J39: =B39-C39 -> 0 | K39: =IF(OR(B39>0,C39>0),1,0) -> 0 | L39: =SUMIFS(总支出!$D$4:$D$5000,总支出!$B$4:$B$5000,">="&DATE(VALUE(LEFT($A39,4)),VALUE(RIGHT($A39,2)),1),总支出!$B$4:$B$5000,"<"&DATE(VALUE(LEFT($A39,4)),VALUE(RIGHT($A39,2))+1,1),总支出!$H$4:$H$5000,"房产支出") -> 0 | M39: =SUMIFS(总支出!$D$4:$D$5000,总支出!$B$4:$B$5000,">="&DATE(VALUE(LEFT($A39,4)),VALUE(RIGHT($A39,2)),1),总支出!$B$4:$B$5000,"<"&DATE(VALUE(LEFT($A39,4)),VALUE(RIGHT($A39,2))+1,1),总支出!$H$4:$H$5000,"投资转账") -> 0 | N39: =SUMIFS(总支出!$D$4:$D$5000,总支出!$B$4:$B$5000,">="&DATE(VALUE(LEFT($A39,4)),VALUE(RIGHT($A39,2)),1),总支出!$B$4:$B$5000,"<"&DATE(VALUE(LEFT($A39,4)),VALUE(RIGHT($A39,2))+1,1),总支出!$H$4:$H$5000,"内部转账") -> 0 | O39: =SUMIFS(税费计算明细!$S$4:$S$5000,税费计算明细!$C$4:$C$5000,$A39) -> 0
A44: 主类别 | B44: 2026-01 | C44: 2026-02 | D44: 2026-03 | E44: 2026-04 | F44: 2026-05 | G44: 2026-06 | H44: 2026-07 | I44: 2026-08 | J44: 2026-09 | K44: 2026-10 | L44: 2026-11 | M44: 2026-12 | N44: 月均 | O44: 年化 | P44: 占个人月支出比例
A45: 住房 | B45: =SUMIFS(总支出!$D$4:$D$5000,总支出!$B$4:$B$5000,">="&DATE(VALUE(LEFT(B$44,4)),VALUE(RIGHT(B$44,2)),1),总支出!$B$4:$B$5000,"<"&DATE(VALUE(LEFT(B$44,4)),VALUE(RIGHT(B$44,2))+1,1),总支出!$H$4:$H$5000,"个人支出",总支出!$E$4:$E$5000,$A45) -> 3000 | C45: =SUMIFS(总支出!$D$4:$D$5000,总支出!$B$4:$B$5000,">="&DATE(VALUE(LEFT(C$44,4)),VALUE(RIGHT(C$44,2)),1),总支出!$B$4:$B$5000,"<"&DATE(VALUE(LEFT(C$44,4)),VALUE(RIGHT(C$44,2))+1,1),总支出!$H$4:$H$5000,"个人支出",总支出!$E$4:$E$5000,$A45) -> 3000 | D45: =SUMIFS(总支出!$D$4:$D$5000,总支出!$B$4:$B$5000,">="&DATE(VALUE(LEFT(D$44,4)),VALUE(RIGHT(D$44,2)),1),总支出!$B$4:$B$5000,"<"&DATE(VALUE(LEFT(D$44,4)),VALUE(RIGHT(D$44,2))+1,1),总支出!$H$4:$H$5000,"个人支出",总支出!$E$4:$E$5000,$A45) -> 0 | E45: =SUMIFS(总支出!$D$4:$D$5000,总支出!$B$4:$B$5000,">="&DATE(VALUE(LEFT(E$44,4)),VALUE(RIGHT(E$44,2)),1),总支出!$B$4:$B$5000,"<"&DATE(VALUE(LEFT(E$44,4)),VALUE(RIGHT(E$44,2))+1,1),总支出!$H$4:$H$5000,"个人支出",总支出!$E$4:$E$5000,$A45) -> 0 | F45: =SUMIFS(总支出!$D$4:$D$5000,总支出!$B$4:$B$5000,">="&DATE(VALUE(LEFT(F$44,4)),VALUE(RIGHT(F$44,2)),1),总支出!$B$4:$B$5000,"<"&DATE(VALUE(LEFT(F$44,4)),VALUE(RIGHT(F$44,2))+1,1),总支出!$H$4:$H$5000,"个人支出",总支出!$E$4:$E$5000,$A45) -> 0 | G45: =SUMIFS(总支出!$D$4:$D$5000,总支出!$B$4:$B$5000,">="&DATE(VALUE(LEFT(G$44,4)),VALUE(RIGHT(G$44,2)),1),总支出!$B$4:$B$5000,"<"&DATE(VALUE(LEFT(G$44,4)),VALUE(RIGHT(G$44,2))+1,1),总支出!$H$4:$H$5000,"个人支出",总支出!$E$4:$E$5000,$A45) -> 0 | H45: =SUMIFS(总支出!$D$4:$D$5000,总支出!$B$4:$B$5000,">="&DATE(VALUE(LEFT(H$44,4)),VALUE(RIGHT(H$44,2)),1),总支出!$B$4:$B$5000,"<"&DATE(VALUE(LEFT(H$44,4)),VALUE(RIGHT(H$44,2))+1,1),总支出!$H$4:$H$5000,"个人支出",总支出!$E$4:$E$5000,$A45) -> 0 | I45: =SUMIFS(总支出!$D$4:$D$5000,总支出!$B$4:$B$5000,">="&DATE(VALUE(LEFT(I$44,4)),VALUE(RIGHT(I$44,2)),1),总支出!$B$4:$B$5000,"<"&DATE(VALUE(LEFT(I$44,4)),VALUE(RIGHT(I$44,2))+1,1),总支出!$H$4:$H$5000,"个人支出",总支出!$E$4:$E$5000,$A45) -> 0 | ... M45: =SUMIFS(总支出!$D$4:$D$5000,总支出!$B$4:$B$5000,">="&DATE(VALUE(LEFT(M$44,4)),VALUE(RIGHT(M$44,2)),1),总支出!$B$4:$B$5000,"<"&DATE(VALUE(LEFT(M$44,4)),VALUE(RIGHT(M$44,2))+1,1),总支出!$H$4:$H$5000,"个人支出",总支出!$E$4:$E$5000,$A45) -> 0 | N45: =IF($B$4=0,0,SUM(B45:M45)/$B$4) -> 3000 | O45: =N45*12 -> 36000 | P45: =IFERROR(N45/$B$7,0) -> 0.58252427
A46: 餐饮 | B46: =SUMIFS(总支出!$D$4:$D$5000,总支出!$B$4:$B$5000,">="&DATE(VALUE(LEFT(B$44,4)),VALUE(RIGHT(B$44,2)),1),总支出!$B$4:$B$5000,"<"&DATE(VALUE(LEFT(B$44,4)),VALUE(RIGHT(B$44,2))+1,1),总支出!$H$4:$H$5000,"个人支出",总支出!$E$4:$E$5000,$A46) -> 770 | C46: =SUMIFS(总支出!$D$4:$D$5000,总支出!$B$4:$B$5000,">="&DATE(VALUE(LEFT(C$44,4)),VALUE(RIGHT(C$44,2)),1),总支出!$B$4:$B$5000,"<"&DATE(VALUE(LEFT(C$44,4)),VALUE(RIGHT(C$44,2))+1,1),总支出!$H$4:$H$5000,"个人支出",总支出!$E$4:$E$5000,$A46) -> 870 | D46: =SUMIFS(总支出!$D$4:$D$5000,总支出!$B$4:$B$5000,">="&DATE(VALUE(LEFT(D$44,4)),VALUE(RIGHT(D$44,2)),1),总支出!$B$4:$B$5000,"<"&DATE(VALUE(LEFT(D$44,4)),VALUE(RIGHT(D$44,2))+1,1),总支出!$H$4:$H$5000,"个人支出",总支出!$E$4:$E$5000,$A46) -> 0 | E46: =SUMIFS(总支出!$D$4:$D$5000,总支出!$B$4:$B$5000,">="&DATE(VALUE(LEFT(E$44,4)),VALUE(RIGHT(E$44,2)),1),总支出!$B$4:$B$5000,"<"&DATE(VALUE(LEFT(E$44,4)),VALUE(RIGHT(E$44,2))+1,1),总支出!$H$4:$H$5000,"个人支出",总支出!$E$4:$E$5000,$A46) -> 0 | F46: =SUMIFS(总支出!$D$4:$D$5000,总支出!$B$4:$B$5000,">="&DATE(VALUE(LEFT(F$44,4)),VALUE(RIGHT(F$44,2)),1),总支出!$B$4:$B$5000,"<"&DATE(VALUE(LEFT(F$44,4)),VALUE(RIGHT(F$44,2))+1,1),总支出!$H$4:$H$5000,"个人支出",总支出!$E$4:$E$5000,$A46) -> 0 | G46: =SUMIFS(总支出!$D$4:$D$5000,总支出!$B$4:$B$5000,">="&DATE(VALUE(LEFT(G$44,4)),VALUE(RIGHT(G$44,2)),1),总支出!$B$4:$B$5000,"<"&DATE(VALUE(LEFT(G$44,4)),VALUE(RIGHT(G$44,2))+1,1),总支出!$H$4:$H$5000,"个人支出",总支出!$E$4:$E$5000,$A46) -> 0 | H46: =SUMIFS(总支出!$D$4:$D$5000,总支出!$B$4:$B$5000,">="&DATE(VALUE(LEFT(H$44,4)),VALUE(RIGHT(H$44,2)),1),总支出!$B$4:$B$5000,"<"&DATE(VALUE(LEFT(H$44,4)),VALUE(RIGHT(H$44,2))+1,1),总支出!$H$4:$H$5000,"个人支出",总支出!$E$4:$E$5000,$A46) -> 0 | I46: =SUMIFS(总支出!$D$4:$D$5000,总支出!$B$4:$B$5000,">="&DATE(VALUE(LEFT(I$44,4)),VALUE(RIGHT(I$44,2)),1),总支出!$B$4:$B$5000,"<"&DATE(VALUE(LEFT(I$44,4)),VALUE(RIGHT(I$44,2))+1,1),总支出!$H$4:$H$5000,"个人支出",总支出!$E$4:$E$5000,$A46) -> 0 | ... M46: =SUMIFS(总支出!$D$4:$D$5000,总支出!$B$4:$B$5000,">="&DATE(VALUE(LEFT(M$44,4)),VALUE(RIGHT(M$44,2)),1),总支出!$B$4:$B$5000,"<"&DATE(VALUE(LEFT(M$44,4)),VALUE(RIGHT(M$44,2))+1,1),总支出!$H$4:$H$5000,"个人支出",总支出!$E$4:$E$5000,$A46) -> 0 | N46: =IF($B$4=0,0,SUM(B46:M46)/$B$4) -> 820 | O46: =N46*12 -> 9840 | P46: =IFERROR(N46/$B$7,0) -> 0.1592233
...

Sheet 税费计算明细
A1: 税费计算明细
A2: 本页由公式自动从“总支出”和“税费设置”读取。用户通常不需要修改。
A3: 记录编号 | B3: 日期 | C3: 月份 | D3: 支出内容 | E3: 支出金额 | F3: 主类别 | G3: 分析口径 | H3: 用户税费类型 | I3: 默认税费类型 | J3: 最终税费类型 | K3: 纳入估算 | L3: 应税消费 | M3: 零税率消费 | N3: 免税消费 | O3: 其他/不适用 | P3: 税前金额 | Q3: 联邦税估算 | R3: 省级税估算 | S3: 消费税合计
A4: =IF(总支出!A4="","",总支出!A4) -> 支出-0001 | B4: =IF(总支出!B4="","",总支出!B4) -> 46023 | C4: =IF(B4="","",TEXT(B4,"yyyy-mm")) -> 2026-01 | D4: =IF(总支出!C4="","",总支出!C4) -> 房租 | E4: =IF(总支出!D4="","",总支出!D4) -> 3000 | F4: =IF(总支出!E4="","",总支出!E4) -> 住房 | G4: =IF(总支出!H4="","",总支出!H4) -> 个人支出 | H4: =IF(总支出!I4="","自动",总支出!I4) -> 免税 | I4: =IF(F4="","",IFERROR(VLOOKUP(F4,税费设置!$A$15:$B$27,2,FALSE),"含税不明")) -> 免税 | J4: =IF(D4="","",IF(H4="自动",I4,H4)) -> 免税 | K4: =IF(AND(税费设置!$B$5="是",G4="个人支出",J4="应税"),"是","否") -> 否 | L4: =IF(K4="是",E4,0) -> 0 | M4: =IF(AND(G4="个人支出",J4="零税率"),E4,0) -> 0 | N4: =IF(AND(G4="个人支出",J4="免税"),E4,0) -> 3000 | O4: =IF(AND(G4="个人支出",OR(J4="含税不明",J4="不适用")),E4,0) -> 0 | P4: =IF(K4<>"是",0,IF(税费设置!$B$6="是",E4/(1+税费设置!$B$10),E4)) -> 0 | Q4: =IF(K4<>"是",0,P4*税费设置!$B$8) -> 0 | R4: =IF(K4<>"是",0,P4*税费设置!$B$9) -> 0 | S4: =Q4+R4 -> 0
