Workbook

Sheet Instructions
A1: Personal Finance Analysis Template: Minimal Input + Canadian Sales Tax Estimator
A2: Fill only Expense_Input, Income_Input, Input_Settings, and Sales_Tax_Settings. Other sheets calculate automatically.
A3: Item | B3: Description
A4: Purpose | B4: Track personal income/expenses and automatically generate monthly cash flow, category mix, annual spending projection, emergency fund, investable cash, and sales tax estimates.
A5: Monthly Maintenance | B5: Append new rows and update current cash or tax assumptions only when they change.
A6: Amount Rule | B6: Enter expense and income amounts as positive numbers.
A7: Tax Rule | B7: Tax Type can be Auto, Zero-rated, Taxable, Exempt, Tax Unknown, or Not Applicable.
A8: Sample Data | B8: January and February 2026 sample data are included.
A10: Workflow
A11: 1. Add expense rows in Expense_Input.
A12: 2. Add income rows in Income_Input.
A13: 3. Update Input_Settings and Sales_Tax_Settings when assumptions change.
A14: 4. Review Dashboard first.
A15: 5. Sales tax estimates are approximate and are not refund, credit, or deductible amounts.

Sheet Dashboard
A1: Personal Finance Dashboard
A2: Main review page; all figures reference Formula_Hub.
A3: Average Monthly Expense | D3: Essential Monthly Expense | G3: Discretionary Monthly Expense | J3: Normal One-Year Reserve
A4: =Formula_Hub!$B$7 -> 5150 | D4: =Formula_Hub!$B$8 -> 4000 | G4: =Formula_Hub!$B$9 -> 1150 | J4: =Formula_Hub!$B$17 -> 61800
A7: Cash Coverage Months | D7: Suggested Investable Cash | G7: Estimated Annual Sales Tax | J7: Sales Tax Estimate Status
A8: =Formula_Hub!$B$16 -> 5.8252427 | D8: =Formula_Hub!$B$21 -> 0 | G8: =Formula_Hub!$B$24 -> 318.45075 | J8: =Formula_Hub!$B$25 -> Enabled
A12: Decision Summary
A13: Cash Safety Level | B13: =Formula_Hub!$B$23 -> Tight
A14: Cash Allocation Note | B14: =IF(Formula_Hub!$B$22>0,"Current cash reserve has a shortfall; prioritize rebuilding the reserve",IF(Formula_Hub!$B$21>0,"There is a potential amount to invest gradually","Enter current cash in Input_Settings first")) -> Current cash reserve has a shortfall; prioritize rebuilding the reserve
A15: Sales Tax Note | B15: =IF(Sales_Tax_Settings!$B$5="Yes","Sales tax estimate is enabled; this is not a refund, credit, or deductible amount","Sales tax estimate is disabled") -> Sales tax estimate is enabled; this is not a refund, credit, or deductible amount
A19: Chart Data: Monthly Cash Flow and Sales Tax | G19: Chart Data: Category Monthly Avg and Share
A20: Month | B20: Income | C20: Personal Expense | D20: Estimated Sales Tax | E20: Net Cash Flow | G20: Category | H20: Monthly Avg | I20: Share
A21: =Monthly_Summary!A4 -> 2026-01 | B21: =Monthly_Summary!B4 -> 6000 | C21: =Monthly_Summary!C4 -> 5000 | D21: =Formula_Hub!O28 -> 148.4801 | E21: =Formula_Hub!J28 -> 1000 | G21: =Category_Summary!A4 -> Housing | H21: =Category_Summary!N4 -> 3000 | I21: =Category_Summary!P4 -> 0.58252427
A22: =Monthly_Summary!A5 -> 2026-02 | B22: =Monthly_Summary!B5 -> 6900 | C22: =Monthly_Summary!C5 -> 5300 | D22: =Formula_Hub!O29 -> 169.97065 | E22: =Formula_Hub!J29 -> 1600 | G22: =Category_Summary!A5 -> Food & Dining | H22: =Category_Summary!N5 -> 820 | I22: =Category_Summary!P5 -> 0.1592233
A23: =Monthly_Summary!A6 -> 2026-03 | B23: =Monthly_Summary!B6 -> 0 | C23: =Monthly_Summary!C6 -> 0 | D23: =Formula_Hub!O30 -> 0 | E23: =Formula_Hub!J30 -> 0 | G23: =Category_Summary!A6 -> Transportation | H23: =Category_Summary!N6 -> 240 | I23: =Category_Summary!P6 -> 0.046601942
A24: =Monthly_Summary!A7 -> 2026-04 | B24: =Monthly_Summary!B7 -> 0 | C24: =Monthly_Summary!C7 -> 0 | D24: =Formula_Hub!O31 -> 0 | E24: =Formula_Hub!J31 -> 0 | G24: =Category_Summary!A7 -> Telecom | H24: =Category_Summary!N7 -> 60 | I24: =Category_Summary!P7 -> 0.011650485
A25: =Monthly_Summary!A8 -> 2026-05 | B25: =Monthly_Summary!B8 -> 0 | C25: =Monthly_Summary!C8 -> 0 | D25: =Formula_Hub!O32 -> 0 | E25: =Formula_Hub!J32 -> 0 | G25: =Category_Summary!A8 -> Subscriptions | H25: =Category_Summary!N8 -> 37.5 | I25: =Category_Summary!P8 -> 0.0072815534
A26: =Monthly_Summary!A9 -> 2026-06 | B26: =Monthly_Summary!B9 -> 0 | C26: =Monthly_Summary!C9 -> 0 | D26: =Formula_Hub!O33 -> 0 | E26: =Formula_Hub!J33 -> 0 | G26: =Category_Summary!A9 -> Shopping | H26: =Category_Summary!N9 -> 275 | I26: =Category_Summary!P9 -> 0.053398058
A27: =Monthly_Summary!A10 -> 2026-07 | B27: =Monthly_Summary!B10 -> 0 | C27: =Monthly_Summary!C10 -> 0 | D27: =Formula_Hub!O34 -> 0 | E27: =Formula_Hub!J34 -> 0 | G27: =Category_Summary!A10 -> Medical | H27: =Category_Summary!N10 -> 90 | I27: =Category_Summary!P10 -> 0.017475728
A28: =Monthly_Summary!A11 -> 2026-08 | B28: =Monthly_Summary!B11 -> 0 | C28: =Monthly_Summary!C11 -> 0 | D28: =Formula_Hub!O35 -> 0 | E28: =Formula_Hub!J35 -> 0 | G28: =Category_Summary!A11 -> Fitness | H28: =Category_Summary!N11 -> 70 | I28: =Category_Summary!P11 -> 0.013592233
A29: =Monthly_Summary!A12 -> 2026-09 | B29: =Monthly_Summary!B12 -> 0 | C29: =Monthly_Summary!C12 -> 0 | D29: =Formula_Hub!O36 -> 0 | E29: =Formula_Hub!J36 -> 0 | G29: =Category_Summary!A12 -> Education | H29: =Category_Summary!N12 -> 130 | I29: =Category_Summary!P12 -> 0.025242718
A30: =Monthly_Summary!A13 -> 2026-10 | B30: =Monthly_Summary!B13 -> 0 | C30: =Monthly_Summary!C13 -> 0 | D30: =Formula_Hub!O37 -> 0 | E30: =Formula_Hub!J37 -> 0 | G30: =Category_Summary!A13 -> Pet | H30: =Category_Summary!N13 -> 95 | I30: =Category_Summary!P13 -> 0.018446602
A31: =Monthly_Summary!A14 -> 2026-11 | B31: =Monthly_Summary!B14 -> 0 | C31: =Monthly_Summary!C14 -> 0 | D31: =Formula_Hub!O38 -> 0 | E31: =Formula_Hub!J38 -> 0 | G31: =Category_Summary!A14 -> Entertainment | H31: =Category_Summary!N14 -> 110 | I31: =Category_Summary!P14 -> 0.021359223
A32: =Monthly_Summary!A15 -> 2026-12 | B32: =Monthly_Summary!B15 -> 0 | C32: =Monthly_Summary!C15 -> 0 | D32: =Formula_Hub!O39 -> 0 | E32: =Formula_Hub!J39 -> 0 | G32: =Category_Summary!A15 -> Taxes & Gov Fees | H32: =Category_Summary!N15 -> 125 | I32: =Category_Summary!P15 -> 0.024271845
G33: =Category_Summary!A16 -> Other | H33: =Category_Summary!N16 -> 97.5 | I33: =Category_Summary!P16 -> 0.018932039

Sheet Expense_Input
A1: Total Expenses
A2: Formula ranges cover rows 4:500. Enter expense amounts as positive numbers.
A3: Record ID | B3: Date | C3: Expense Description | D3: Expense Amount | E3: Main Category | F3: Expense Nature | G3: Necessity | H3: Analysis Scope | I3: Tax Type | J3: Notes
A4: EXP-0001 | B4: 46023 | C4: Rent | D4: 3000 | E4: Housing | F4: Fixed | G4: Essential | H4: Personal Expense | I4: Exempt | J4: Sample rent
A5: EXP-0002 | B5: 46025 | C5: Basic groceries | D5: 450 | E5: Food & Dining | F5: Variable | G5: Essential | H5: Personal Expense | I5: Zero-rated | J5: Basic groceries
A6: EXP-0003 | B6: 46027 | C6: Restaurant dining | D6: 320 | E6: Food & Dining | F6: Variable | G6: Discretionary | H6: Personal Expense | I6: Taxable
A7: EXP-0004 | B7: 46029 | C7: Gas | D7: 220 | E7: Transportation | F7: Variable | G7: Essential | H7: Personal Expense | I7: Taxable
A8: EXP-0005 | B8: 46030 | C8: Mobile phone plan | D8: 60 | E8: Telecom | F8: Fixed | G8: Essential | H8: Personal Expense | I8: Taxable
A9: EXP-0006 | B9: 46031 | C9: Cloud subscription | D9: 30 | E9: Subscriptions | F9: Fixed | G9: Discretionary | H9: Personal Expense | I9: Taxable
A10: EXP-0007 | B10: 46032 | C10: Shopping | D10: 250 | E10: Shopping | F10: Variable | G10: Discretionary | H10: Personal Expense | I10: Taxable
A11: EXP-0008 | B11: 46034 | C11: Medical supplies | D11: 80 | E11: Medical | F11: Variable | G11: Essential | H11: Personal Expense | I11: Exempt
A12: EXP-0009 | B12: 46037 | C12: Gym membership | D12: 70 | E12: Fitness | F12: Fixed | G12: Discretionary | H12: Personal Expense | I12: Taxable
A13: EXP-0010 | B13: 46038 | C13: Courses and books | D13: 120 | E13: Education | F13: One-time | G13: Discretionary | H13: Personal Expense | I13: Tax Unknown
A14: EXP-0011 | B14: 46040 | C14: Pet supplies | D14: 90 | E14: Pet | F14: Variable | G14: Discretionary | H14: Personal Expense | I14: Taxable
A15: EXP-0012 | B15: 46042 | C15: Entertainment | D15: 100 | E15: Entertainment | F15: Variable | G15: Discretionary | H15: Personal Expense | I15: Taxable
A16: EXP-0013 | B16: 46047 | C16: Government fee | D16: 100 | E16: Taxes & Gov Fees | F16: One-time | G16: Essential | H16: Personal Expense | I16: Not Applicable
A17: EXP-0014 | B17: 46050 | C17: Miscellaneous | D17: 110 | E17: Other | F17: Variable | G17: Discretionary | H17: Personal Expense | I17: Tax Unknown
... A31: EXP-0028 | B31: 46079 | C31: Miscellaneous | D31: 85 | E31: Other | F31: Variable | G31: Discretionary | H31: Personal Expense | I31: Tax Unknown

Sheet Income_Input
A1: Total Income
A2: Formula ranges cover rows 4:500. Enter income amounts as positive numbers.
A3: Record ID | B3: Date | C3: Income Source | D3: Income Amount | E3: Income Type | F3: Notes
A4: INC-0001 | B4: 46030 | C4: Salary | D4: 6000 | E4: Salary | F4: Sample income
A5: INC-0002 | B5: 46061 | C5: Salary | D5: 6700 | E5: Salary | F5: Sample income
A6: INC-0003 | B6: 46073 | C6: Refund | D6: 200 | E6: Refund | F6: Example refund

Sheet Input_Settings
A1: Input Settings
A2: Manual variable area.
A4: Setting | B4: Current Value | C4: Description
A5: Current Available Cash | B5: 30000 | C5: Used to calculate cash coverage months and investable cash
A6: Extra Safety Buffer | B6: 1000 | C6: Additional cash held above recommended reserve
A7: Risk Preference | B7: Balanced | C7: Conservative, Balanced, or Growth
A8: Emergency Fund Months | B8: 12 | C8: Recommended reserve = average monthly expense × months
A9: Minimum Cash Reserve Floor | B9: 15000 | C9: Minimum cash reserve floor
A12: Optional: Monthly Housing Baseline
B13: 2026-01 | C13: 2026-02 | D13: 2026-03 | E13: 2026-04 | F13: 2026-05 | G13: 2026-06 | H13: 2026-07 | I13: 2026-08 | J13: 2026-09 | K13: 2026-10 | L13: 2026-11 | M13: 2026-12
A14: Housing Baseline | B14: 3000 | C14: 3000 | D14: 3000 | E14: 3000 | F14: 3000 | G14: 3000 | H14: 3000 | I14: 3000 | J14: 3000 | K14: 3000 | L14: 3000 | M14: 3000

Sheet Sales_Tax_Settings
A1: Sales Tax Settings
A2: Sales tax estimates are approximate and editable.
A4: Setting | B4: Current Value | C4: Description
A5: Enable Sales Tax Estimate | B5: Yes | C5: If No, estimated tax is 0
A6: Expense Amounts Include Tax | B6: Yes | C6: Most personal records are tax-included cash outflows
A7: Region | B7: Quebec | C7: Default GST/QST example
A8: Federal Sales Tax Rate | B8: 0.05 | C8: GST
A9: Provincial Sales Tax Rate | B9: 0.09975 | C9: QST
A10: Combined Sales Tax Rate | B10: =B8+B9 -> 0.14975 | C10: Used to back out included tax
A13: Default Tax Type by Main Category
A14: Main Category | B14: Default Tax Type | C14: Notes
A15: Housing | B15: Exempt | C15: Residential rent is usually outside sales tax estimate
A16: Food & Dining | B16: Taxable | C16: Restaurants/takeout taxable; basic groceries zero-rated
A17: Transportation | B17: Taxable | C17: Gas, parking, repair usually taxable
A18: Telecom | B18: Taxable | C18: Mobile/internet usually taxable
A19: Subscriptions | B19: Taxable | C19: Software/streaming usually taxable
A20: Shopping | B20: Taxable | C20: Goods usually taxable
A21: Medical | B21: Exempt | C21: Medical varies
A22: Fitness | B22: Taxable | C22: Gym usually taxable
A23: Education | B23: Tax Unknown | C23: Books/courses vary
A24: Pet | B24: Taxable | C24: Pet items usually taxable
A25: Entertainment | B25: Taxable | C25: Games/events usually taxable
... A27: Other | B27: Tax Unknown | C27: Use receipt
A30: Sources
A31: Topic | B31: Link
A32: Quebec sales tax calculation rules | B32: https://www.revenuquebec.ca/en/businesses/consumption-taxes/gsthst-and-qst/collecting-gst-and-qst/calculating-the-taxes/
A33: Quebec GST/QST rate tables | B33: https://www.revenuquebec.ca/en/businesses/consumption-taxes/gsthst-and-qst/basic-rules-for-applying-the-gsthst-and-qst/tables-of-gst-and-qst-rates/
A34: Examples of taxable supplies | B34: https://www.revenuquebec.ca/en/businesses/consumption-taxes/gsthst-and-qst/basic-rules-for-applying-the-gsthst-and-qst/types-of-supplies/taxable-supplies/
A35: Federal GST/HST credit overview | B35: https://www.canada.ca/en/revenue-agency/services/child-family-benefits/gst-hst-credit.html

Sheet Monthly_Summary
A1: Monthly Summary
A2: Display sheet: references Formula_Hub.
A3: Month | B3: Total Income | C3: Personal Expense | D3: Essential Expense | E3: Discretionary Expense | F3: Fixed Expense | G3: Variable Expense | H3: One-time Expense | I3: Housing Expense | J3: Net Cash Flow | K3: Included in Average | L3: Property Expense | M3: Investment Transfer | N3: Internal Transfer | O3: Estimated Sales Tax
A4: =Formula_Hub!A28 -> 2026-01 | B4: =Formula_Hub!B28 -> 6000 | C4: =Formula_Hub!C28 -> 5000 | D4: =Formula_Hub!D28 -> 3910 | E4: =Formula_Hub!E28 -> 1090 | F4: =Formula_Hub!F28 -> 3160 | G4: =Formula_Hub!G28 -> 1620 | H4: =Formula_Hub!H28 -> 220 | ... O4: =Formula_Hub!O28 -> 148.4801
A5: =Formula_Hub!A29 -> 2026-02 | B5: =Formula_Hub!B29 -> 6900 | C5: =Formula_Hub!C29 -> 5300 | D5: =Formula_Hub!D29 -> 4090 | E5: =Formula_Hub!E29 -> 1210 | F5: =Formula_Hub!F29 -> 3175 | G5: =Formula_Hub!G29 -> 1835 | H5: =Formula_Hub!H29 -> 290 | ... O5: =Formula_Hub!O29 -> 169.97065
A6: =Formula_Hub!A30 -> 2026-03 | B6: =Formula_Hub!B30 -> 0 | C6: =Formula_Hub!C30 -> 0 | D6: =Formula_Hub!D30 -> 0 | E6: =Formula_Hub!E30 -> 0 | F6: =Formula_Hub!F30 -> 0 | G6: =Formula_Hub!G30 -> 0 | H6: =Formula_Hub!H30 -> 0 | ... O6: =Formula_Hub!O30 -> 0
A7: =Formula_Hub!A31 -> 2026-04 | B7: =Formula_Hub!B31 -> 0 | C7: =Formula_Hub!C31 -> 0 | D7: =Formula_Hub!D31 -> 0 | E7: =Formula_Hub!E31 -> 0 | F7: =Formula_Hub!F31 -> 0 | G7: =Formula_Hub!G31 -> 0 | H7: =Formula_Hub!H31 -> 0 | ... O7: =Formula_Hub!O31 -> 0
A8: =Formula_Hub!A32 -> 2026-05 | B8: =Formula_Hub!B32 -> 0 | C8: =Formula_Hub!C32 -> 0 | D8: =Formula_Hub!D32 -> 0 | E8: =Formula_Hub!E32 -> 0 | F8: =Formula_Hub!F32 -> 0 | G8: =Formula_Hub!G32 -> 0 | H8: =Formula_Hub!H32 -> 0 | ... O8: =Formula_Hub!O32 -> 0
A9: =Formula_Hub!A33 -> 2026-06 | B9: =Formula_Hub!B33 -> 0 | C9: =Formula_Hub!C33 -> 0 | D9: =Formula_Hub!D33 -> 0 | E9: =Formula_Hub!E33 -> 0 | F9: =Formula_Hub!F33 -> 0 | G9: =Formula_Hub!G33 -> 0 | H9: =Formula_Hub!H33 -> 0 | ... O9: =Formula_Hub!O33 -> 0
A10: =Formula_Hub!A34 -> 2026-07 | B10: =Formula_Hub!B34 -> 0 | C10: =Formula_Hub!C34 -> 0 | D10: =Formula_Hub!D34 -> 0 | E10: =Formula_Hub!E34 -> 0 | F10: =Formula_Hub!F34 -> 0 | G10: =Formula_Hub!G34 -> 0 | H10: =Formula_Hub!H34 -> 0 | ... O10: =Formula_Hub!O34 -> 0
A11: =Formula_Hub!A35 -> 2026-08 | B11: =Formula_Hub!B35 -> 0 | C11: =Formula_Hub!C35 -> 0 | D11: =Formula_Hub!D35 -> 0 | E11: =Formula_Hub!E35 -> 0 | F11: =Formula_Hub!F35 -> 0 | G11: =Formula_Hub!G35 -> 0 | H11: =Formula_Hub!H35 -> 0 | ... O11: =Formula_Hub!O35 -> 0
A12: =Formula_Hub!A36 -> 2026-09 | B12: =Formula_Hub!B36 -> 0 | C12: =Formula_Hub!C36 -> 0 | D12: =Formula_Hub!D36 -> 0 | E12: =Formula_Hub!E36 -> 0 | F12: =Formula_Hub!F36 -> 0 | G12: =Formula_Hub!G36 -> 0 | H12: =Formula_Hub!H36 -> 0 | ... O12: =Formula_Hub!O36 -> 0
A13: =Formula_Hub!A37 -> 2026-10 | B13: =Formula_Hub!B37 -> 0 | C13: =Formula_Hub!C37 -> 0 | D13: =Formula_Hub!D37 -> 0 | E13: =Formula_Hub!E37 -> 0 | F13: =Formula_Hub!F37 -> 0 | G13: =Formula_Hub!G37 -> 0 | H13: =Formula_Hub!H37 -> 0 | ... O13: =Formula_Hub!O37 -> 0
A14: =Formula_Hub!A38 -> 2026-11 | B14: =Formula_Hub!B38 -> 0 | C14: =Formula_Hub!C38 -> 0 | D14: =Formula_Hub!D38 -> 0 | E14: =Formula_Hub!E38 -> 0 | F14: =Formula_Hub!F38 -> 0 | G14: =Formula_Hub!G38 -> 0 | H14: =Formula_Hub!H38 -> 0 | ... O14: =Formula_Hub!O38 -> 0
A15: =Formula_Hub!A39 -> 2026-12 | B15: =Formula_Hub!B39 -> 0 | C15: =Formula_Hub!C39 -> 0 | D15: =Formula_Hub!D39 -> 0 | E15: =Formula_Hub!E39 -> 0 | F15: =Formula_Hub!F39 -> 0 | G15: =Formula_Hub!G39 -> 0 | H15: =Formula_Hub!H39 -> 0 | ... O15: =Formula_Hub!O39 -> 0

Sheet Category_Summary
A1: Category Summary
A2: Display sheet: references Formula_Hub.
A3: Main Category | B3: 2026-01 | C3: 2026-02 | D3: 2026-03 | E3: 2026-04 | F3: 2026-05 | G3: 2026-06 | H3: 2026-07 | I3: 2026-08 | J3: 2026-09 | K3: 2026-10 | L3: 2026-11 | M3: 2026-12 | N3: Monthly Avg | O3: Annualized | P3: Share of Personal Monthly Expense
A4: =Formula_Hub!A45 -> Housing | B4: =Formula_Hub!B45 -> 3000 | C4: =Formula_Hub!C45 -> 3000 | D4: =Formula_Hub!D45 -> 0 | E4: =Formula_Hub!E45 -> 0 | F4: =Formula_Hub!F45 -> 0 | G4: =Formula_Hub!G45 -> 0 | H4: =Formula_Hub!H45 -> 0 | ... P4: =Formula_Hub!P45 -> 0.58252427
A5: =Formula_Hub!A46 -> Food & Dining | B5: =Formula_Hub!B46 -> 770 | C5: =Formula_Hub!C46 -> 870 | D5: =Formula_Hub!D46 -> 0 | E5: =Formula_Hub!E46 -> 0 | F5: =Formula_Hub!F46 -> 0 | G5: =Formula_Hub!G46 -> 0 | H5: =Formula_Hub!H46 -> 0 | ... P5: =Formula_Hub!P46 -> 0.1592233
A6: =Formula_Hub!A47 -> Transportation | B6: =Formula_Hub!B47 -> 220 | C6: =Formula_Hub!C47 -> 260 | D6: =Formula_Hub!D47 -> 0 | E6: =Formula_Hub!E47 -> 0 | F6: =Formula_Hub!F47 -> 0 | G6: =Formula_Hub!G47 -> 0 | H6: =Formula_Hub!H47 -> 0 | ... P6: =Formula_Hub!P47 -> 0.046601942
A7: =Formula_Hub!A48 -> Telecom | B7: =Formula_Hub!B48 -> 60 | C7: =Formula_Hub!C48 -> 60 | D7: =Formula_Hub!D48 -> 0 | E7: =Formula_Hub!E48 -> 0 | F7: =Formula_Hub!F48 -> 0 | G7: =Formula_Hub!G48 -> 0 | H7: =Formula_Hub!H48 -> 0 | ... P7: =Formula_Hub!P48 -> 0.011650485
A8: =Formula_Hub!A49 -> Subscriptions | B8: =Formula_Hub!B49 -> 30 | C8: =Formula_Hub!C49 -> 45 | D8: =Formula_Hub!D49 -> 0 | E8: =Formula_Hub!E49 -> 0 | F8: =Formula_Hub!F49 -> 0 | G8: =Formula_Hub!G49 -> 0 | H8: =Formula_Hub!H49 -> 0 | ... P8: =Formula_Hub!P49 -> 0.0072815534
A9: =Formula_Hub!A50 -> Shopping | B9: =Formula_Hub!B50 -> 250 | C9: =Formula_Hub!C50 -> 300 | D9: =Formula_Hub!D50 -> 0 | E9: =Formula_Hub!E50 -> 0 | F9: =Formula_Hub!F50 -> 0 | G9: =Formula_Hub!G50 -> 0 | H9: =Formula_Hub!H50 -> 0 | ... P9: =Formula_Hub!P50 -> 0.053398058
A10: =Formula_Hub!A51 -> Medical | B10: =Formula_Hub!B51 -> 80 | C10: =Formula_Hub!C51 -> 100 | D10: =Formula_Hub!D51 -> 0 | E10: =Formula_Hub!E51 -> 0 | F10: =Formula_Hub!F51 -> 0 | G10: =Formula_Hub!G51 -> 0 | H10: =Formula_Hub!H51 -> 0 | ... P10: =Formula_Hub!P51 -> 0.017475728
A11: =Formula_Hub!A52 -> Fitness | B11: =Formula_Hub!B52 -> 70 | C11: =Formula_Hub!C52 -> 70 | D11: =Formula_Hub!D52 -> 0 | E11: =Formula_Hub!E52 -> 0 | F11: =Formula_Hub!F52 -> 0 | G11: =Formula_Hub!G52 -> 0 | H11: =Formula_Hub!H52 -> 0 | ... P11: =Formula_Hub!P52 -> 0.013592233
A12: =Formula_Hub!A53 -> Education | B12: =Formula_Hub!B53 -> 120 | C12: =Formula_Hub!C53 -> 140 | D12: =Formula_Hub!D53 -> 0 | E12: =Formula_Hub!E53 -> 0 | F12: =Formula_Hub!F53 -> 0 | G12: =Formula_Hub!G53 -> 0 | H12: =Formula_Hub!H53 -> 0 | ... P12: =Formula_Hub!P53 -> 0.025242718
A13: =Formula_Hub!A54 -> Pet | B13: =Formula_Hub!B54 -> 90 | C13: =Formula_Hub!C54 -> 100 | D13: =Formula_Hub!D54 -> 0 | E13: =Formula_Hub!E54 -> 0 | F13: =Formula_Hub!F54 -> 0 | G13: =Formula_Hub!G54 -> 0 | H13: =Formula_Hub!H54 -> 0 | ... P13: =Formula_Hub!P54 -> 0.018446602
A14: =Formula_Hub!A55 -> Entertainment | B14: =Formula_Hub!B55 -> 100 | C14: =Formula_Hub!C55 -> 120 | D14: =Formula_Hub!D55 -> 0 | E14: =Formula_Hub!E55 -> 0 | F14: =Formula_Hub!F55 -> 0 | G14: =Formula_Hub!G55 -> 0 | H14: =Formula_Hub!H55 -> 0 | ... P14: =Formula_Hub!P55 -> 0.021359223
A15: =Formula_Hub!A56 -> Taxes & Gov Fees | B15: =Formula_Hub!B56 -> 100 | C15: =Formula_Hub!C56 -> 150 | D15: =Formula_Hub!D56 -> 0 | E15: =Formula_Hub!E56 -> 0 | F15: =Formula_Hub!F56 -> 0 | G15: =Formula_Hub!G56 -> 0 | H15: =Formula_Hub!H56 -> 0 | ... P15: =Formula_Hub!P56 -> 0.024271845
A16: =Formula_Hub!A57 -> Other | B16: =Formula_Hub!B57 -> 110 | C16: =Formula_Hub!C57 -> 85 | D16: =Formula_Hub!D57 -> 0 | E16: =Formula_Hub!E57 -> 0 | F16: =Formula_Hub!F57 -> 0 | G16: =Formula_Hub!G57 -> 0 | H16: =Formula_Hub!H57 -> 0 | ... P16: =Formula_Hub!P57 -> 0.018932039

Sheet Sales_Tax_Analysis
A1: Sales Tax Analysis
A2: Summarizes estimated sales tax by month.
A3: Month | B3: Taxable Spending | C3: Zero-rated Spending | D3: Exempt Spending | E3: Other / N.A. | F3: Pre-tax Amount | G3: Federal Tax Estimate | H3: Provincial Tax Estimate | I3: Estimated Sales Tax | J3: Note
A4: 2026-01 | B4: =SUMIFS(Sales_Tax_Detail!$L$4:$L$500,Sales_Tax_Detail!$C$4:$C$500,$A4) -> 1140 | C4: =SUMIFS(Sales_Tax_Detail!$M$4:$M$500,Sales_Tax_Detail!$C$4:$C$500,$A4) -> 450 | D4: =SUMIFS(Sales_Tax_Detail!$N$4:$N$500,Sales_Tax_Detail!$C$4:$C$500,$A4) -> 3080 | E4: =SUMIFS(Sales_Tax_Detail!$O$4:$O$500,Sales_Tax_Detail!$C$4:$C$500,$A4) -> 330 | F4: =SUMIFS(Sales_Tax_Detail!$P$4:$P$500,Sales_Tax_Detail!$C$4:$C$500,$A4) -> 991.5199 | G4: =SUMIFS(Sales_Tax_Detail!$Q$4:$Q$500,Sales_Tax_Detail!$C$4:$C$500,$A4) -> 49.575995 | H4: =SUMIFS(Sales_Tax_Detail!$R$4:$R$500,Sales_Tax_Detail!$C$4:$C$500,$A4) -> 98.90411 | I4: =SUMIFS(Sales_Tax_Detail!$S$4:$S$500,Sales_Tax_Detail!$C$4:$C$500,$A4) -> 148.4801 | J4: =IF(I4>0,"Estimated","No estimated tax") -> Estimated
A5: 2026-02 | B5: =SUMIFS(Sales_Tax_Detail!$L$4:$L$500,Sales_Tax_Detail!$C$4:$C$500,$A5) -> 1305 | C5: =SUMIFS(Sales_Tax_Detail!$M$4:$M$500,Sales_Tax_Detail!$C$4:$C$500,$A5) -> 520 | D5: =SUMIFS(Sales_Tax_Detail!$N$4:$N$500,Sales_Tax_Detail!$C$4:$C$500,$A5) -> 3100 | E5: =SUMIFS(Sales_Tax_Detail!$O$4:$O$500,Sales_Tax_Detail!$C$4:$C$500,$A5) -> 375 | F5: =SUMIFS(Sales_Tax_Detail!$P$4:$P$500,Sales_Tax_Detail!$C$4:$C$500,$A5) -> 1135.0294 | G5: =SUMIFS(Sales_Tax_Detail!$Q$4:$Q$500,Sales_Tax_Detail!$C$4:$C$500,$A5) -> 56.751468 | H5: =SUMIFS(Sales_Tax_Detail!$R$4:$R$500,Sales_Tax_Detail!$C$4:$C$500,$A5) -> 113.21918 | I5: =SUMIFS(Sales_Tax_Detail!$S$4:$S$500,Sales_Tax_Detail!$C$4:$C$500,$A5) -> 169.97065 | J5: =IF(I5>0,"Estimated","No estimated tax") -> Estimated
A6: 2026-03 | B6: =SUMIFS(Sales_Tax_Detail!$L$4:$L$500,Sales_Tax_Detail!$C$4:$C$500,$A6) -> 0 | C6: =SUMIFS(Sales_Tax_Detail!$M$4:$M$500,Sales_Tax_Detail!$C$4:$C$500,$A6) -> 0 | D6: =SUMIFS(Sales_Tax_Detail!$N$4:$N$500,Sales_Tax_Detail!$C$4:$C$500,$A6) -> 0 | E6: =SUMIFS(Sales_Tax_Detail!$O$4:$O$500,Sales_Tax_Detail!$C$4:$C$500,$A6) -> 0 | F6: =SUMIFS(Sales_Tax_Detail!$P$4:$P$500,Sales_Tax_Detail!$C$4:$C$500,$A6) -> 0 | G6: =SUMIFS(Sales_Tax_Detail!$Q$4:$Q$500,Sales_Tax_Detail!$C$4:$C$500,$A6) -> 0 | H6: =SUMIFS(Sales_Tax_Detail!$R$4:$R$500,Sales_Tax_Detail!$C$4:$C$500,$A6) -> 0 | I6: =SUMIFS(Sales_Tax_Detail!$S$4:$S$500,Sales_Tax_Detail!$C$4:$C$500,$A6) -> 0 | J6: =IF(I6>0,"Estimated","No estimated tax") -> No estimated tax
A7: 2026-04 | B7: =SUMIFS(Sales_Tax_Detail!$L$4:$L$500,Sales_Tax_Detail!$C$4:$C$500,$A7) -> 0 | C7: =SUMIFS(Sales_Tax_Detail!$M$4:$M$500,Sales_Tax_Detail!$C$4:$C$500,$A7) -> 0 | D7: =SUMIFS(Sales_Tax_Detail!$N$4:$N$500,Sales_Tax_Detail!$C$4:$C$500,$A7) -> 0 | E7: =SUMIFS(Sales_Tax_Detail!$O$4:$O$500,Sales_Tax_Detail!$C$4:$C$500,$A7) -> 0 | F7: =SUMIFS(Sales_Tax_Detail!$P$4:$P$500,Sales_Tax_Detail!$C$4:$C$500,$A7) -> 0 | G7: =SUMIFS(Sales_Tax_Detail!$Q$4:$Q$500,Sales_Tax_Detail!$C$4:$C$500,$A7) -> 0 | H7: =SUMIFS(Sales_Tax_Detail!$R$4:$R$500,Sales_Tax_Detail!$C$4:$C$500,$A7) -> 0 | I7: =SUMIFS(Sales_Tax_Detail!$S$4:$S$500,Sales_Tax_Detail!$C$4:$C$500,$A7) -> 0 | J7: =IF(I7>0,"Estimated","No estimated tax") -> No estimated tax
A8: 2026-05 | B8: =SUMIFS(Sales_Tax_Detail!$L$4:$L$500,Sales_Tax_Detail!$C$4:$C$500,$A8) -> 0 | C8: =SUMIFS(Sales_Tax_Detail!$M$4:$M$500,Sales_Tax_Detail!$C$4:$C$500,$A8) -> 0 | D8: =SUMIFS(Sales_Tax_Detail!$N$4:$N$500,Sales_Tax_Detail!$C$4:$C$500,$A8) -> 0 | E8: =SUMIFS(Sales_Tax_Detail!$O$4:$O$500,Sales_Tax_Detail!$C$4:$C$500,$A8) -> 0 | F8: =SUMIFS(Sales_Tax_Detail!$P$4:$P$500,Sales_Tax_Detail!$C$4:$C$500,$A8) -> 0 | G8: =SUMIFS(Sales_Tax_Detail!$Q$4:$Q$500,Sales_Tax_Detail!$C$4:$C$500,$A8) -> 0 | H8: =SUMIFS(Sales_Tax_Detail!$R$4:$R$500,Sales_Tax_Detail!$C$4:$C$500,$A8) -> 0 | I8: =SUMIFS(Sales_Tax_Detail!$S$4:$S$500,Sales_Tax_Detail!$C$4:$C$500,$A8) -> 0 | J8: =IF(I8>0,"Estimated","No estimated tax") -> No estimated tax
A9: 2026-06 | B9: =SUMIFS(Sales_Tax_Detail!$L$4:$L$500,Sales_Tax_Detail!$C$4:$C$500,$A9) -> 0 | C9: =SUMIFS(Sales_Tax_Detail!$M$4:$M$500,Sales_Tax_Detail!$C$4:$C$500,$A9) -> 0 | D9: =SUMIFS(Sales_Tax_Detail!$N$4:$N$500,Sales_Tax_Detail!$C$4:$C$500,$A9) -> 0 | E9: =SUMIFS(Sales_Tax_Detail!$O$4:$O$500,Sales_Tax_Detail!$C$4:$C$500,$A9) -> 0 | F9: =SUMIFS(Sales_Tax_Detail!$P$4:$P$500,Sales_Tax_Detail!$C$4:$C$500,$A9) -> 0 | G9: =SUMIFS(Sales_Tax_Detail!$Q$4:$Q$500,Sales_Tax_Detail!$C$4:$C$500,$A9) -> 0 | H9: =SUMIFS(Sales_Tax_Detail!$R$4:$R$500,Sales_Tax_Detail!$C$4:$C$500,$A9) -> 0 | I9: =SUMIFS(Sales_Tax_Detail!$S$4:$S$500,Sales_Tax_Detail!$C$4:$C$500,$A9) -> 0 | J9: =IF(I9>0,"Estimated","No estimated tax") -> No estimated tax
A10: 2026-07 | B10: =SUMIFS(Sales_Tax_Detail!$L$4:$L$500,Sales_Tax_Detail!$C$4:$C$500,$A10) -> 0 | C10: =SUMIFS(Sales_Tax_Detail!$M$4:$M$500,Sales_Tax_Detail!$C$4:$C$500,$A10) -> 0 | D10: =SUMIFS(Sales_Tax_Detail!$N$4:$N$500,Sales_Tax_Detail!$C$4:$C$500,$A10) -> 0 | E10: =SUMIFS(Sales_Tax_Detail!$O$4:$O$500,Sales_Tax_Detail!$C$4:$C$500,$A10) -> 0 | F10: =SUMIFS(Sales_Tax_Detail!$P$4:$P$500,Sales_Tax_Detail!$C$4:$C$500,$A10) -> 0 | G10: =SUMIFS(Sales_Tax_Detail!$Q$4:$Q$500,Sales_Tax_Detail!$C$4:$C$500,$A10) -> 0 | H10: =SUMIFS(Sales_Tax_Detail!$R$4:$R$500,Sales_Tax_Detail!$C$4:$C$500,$A10) -> 0 | I10: =SUMIFS(Sales_Tax_Detail!$S$4:$S$500,Sales_Tax_Detail!$C$4:$C$500,$A10) -> 0 | J10: =IF(I10>0,"Estimated","No estimated tax") -> No estimated tax
A11: 2026-08 | B11: =SUMIFS(Sales_Tax_Detail!$L$4:$L$500,Sales_Tax_Detail!$C$4:$C$500,$A11) -> 0 | C11: =SUMIFS(Sales_Tax_Detail!$M$4:$M$500,Sales_Tax_Detail!$C$4:$C$500,$A11) -> 0 | D11: =SUMIFS(Sales_Tax_Detail!$N$4:$N$500,Sales_Tax_Detail!$C$4:$C$500,$A11) -> 0 | E11: =SUMIFS(Sales_Tax_Detail!$O$4:$O$500,Sales_Tax_Detail!$C$4:$C$500,$A11) -> 0 | F11: =SUMIFS(Sales_Tax_Detail!$P$4:$P$500,Sales_Tax_Detail!$C$4:$C$500,$A11) -> 0 | G11: =SUMIFS(Sales_Tax_Detail!$Q$4:$Q$500,Sales_Tax_Detail!$C$4:$C$500,$A11) -> 0 | H11: =SUMIFS(Sales_Tax_Detail!$R$4:$R$500,Sales_Tax_Detail!$C$4:$C$500,$A11) -> 0 | I11: =SUMIFS(Sales_Tax_Detail!$S$4:$S$500,Sales_Tax_Detail!$C$4:$C$500,$A11) -> 0 | J11: =IF(I11>0,"Estimated","No estimated tax") -> No estimated tax
A12: 2026-09 | B12: =SUMIFS(Sales_Tax_Detail!$L$4:$L$500,Sales_Tax_Detail!$C$4:$C$500,$A12) -> 0 | C12: =SUMIFS(Sales_Tax_Detail!$M$4:$M$500,Sales_Tax_Detail!$C$4:$C$500,$A12) -> 0 | D12: =SUMIFS(Sales_Tax_Detail!$N$4:$N$500,Sales_Tax_Detail!$C$4:$C$500,$A12) -> 0 | E12: =SUMIFS(Sales_Tax_Detail!$O$4:$O$500,Sales_Tax_Detail!$C$4:$C$500,$A12) -> 0 | F12: =SUMIFS(Sales_Tax_Detail!$P$4:$P$500,Sales_Tax_Detail!$C$4:$C$500,$A12) -> 0 | G12: =SUMIFS(Sales_Tax_Detail!$Q$4:$Q$500,Sales_Tax_Detail!$C$4:$C$500,$A12) -> 0 | H12: =SUMIFS(Sales_Tax_Detail!$R$4:$R$500,Sales_Tax_Detail!$C$4:$C$500,$A12) -> 0 | I12: =SUMIFS(Sales_Tax_Detail!$S$4:$S$500,Sales_Tax_Detail!$C$4:$C$500,$A12) -> 0 | J12: =IF(I12>0,"Estimated","No estimated tax") -> No estimated tax
A13: 2026-10 | B13: =SUMIFS(Sales_Tax_Detail!$L$4:$L$500,Sales_Tax_Detail!$C$4:$C$500,$A13) -> 0 | C13: =SUMIFS(Sales_Tax_Detail!$M$4:$M$500,Sales_Tax_Detail!$C$4:$C$500,$A13) -> 0 | D13: =SUMIFS(Sales_Tax_Detail!$N$4:$N$500,Sales_Tax_Detail!$C$4:$C$500,$A13) -> 0 | E13: =SUMIFS(Sales_Tax_Detail!$O$4:$O$500,Sales_Tax_Detail!$C$4:$C$500,$A13) -> 0 | F13: =SUMIFS(Sales_Tax_Detail!$P$4:$P$500,Sales_Tax_Detail!$C$4:$C$500,$A13) -> 0 | G13: =SUMIFS(Sales_Tax_Detail!$Q$4:$Q$500,Sales_Tax_Detail!$C$4:$C$500,$A13) -> 0 | H13: =SUMIFS(Sales_Tax_Detail!$R$4:$R$500,Sales_Tax_Detail!$C$4:$C$500,$A13) -> 0 | I13: =SUMIFS(Sales_Tax_Detail!$S$4:$S$500,Sales_Tax_Detail!$C$4:$C$500,$A13) -> 0 | J13: =IF(I13>0,"Estimated","No estimated tax") -> No estimated tax
A14: 2026-11 | B14: =SUMIFS(Sales_Tax_Detail!$L$4:$L$500,Sales_Tax_Detail!$C$4:$C$500,$A14) -> 0 | C14: =SUMIFS(Sales_Tax_Detail!$M$4:$M$500,Sales_Tax_Detail!$C$4:$C$500,$A14) -> 0 | D14: =SUMIFS(Sales_Tax_Detail!$N$4:$N$500,Sales_Tax_Detail!$C$4:$C$500,$A14) -> 0 | E14: =SUMIFS(Sales_Tax_Detail!$O$4:$O$500,Sales_Tax_Detail!$C$4:$C$500,$A14) -> 0 | F14: =SUMIFS(Sales_Tax_Detail!$P$4:$P$500,Sales_Tax_Detail!$C$4:$C$500,$A14) -> 0 | G14: =SUMIFS(Sales_Tax_Detail!$Q$4:$Q$500,Sales_Tax_Detail!$C$4:$C$500,$A14) -> 0 | H14: =SUMIFS(Sales_Tax_Detail!$R$4:$R$500,Sales_Tax_Detail!$C$4:$C$500,$A14) -> 0 | I14: =SUMIFS(Sales_Tax_Detail!$S$4:$S$500,Sales_Tax_Detail!$C$4:$C$500,$A14) -> 0 | J14: =IF(I14>0,"Estimated","No estimated tax") -> No estimated tax
A15: 2026-12 | B15: =SUMIFS(Sales_Tax_Detail!$L$4:$L$500,Sales_Tax_Detail!$C$4:$C$500,$A15) -> 0 | C15: =SUMIFS(Sales_Tax_Detail!$M$4:$M$500,Sales_Tax_Detail!$C$4:$C$500,$A15) -> 0 | D15: =SUMIFS(Sales_Tax_Detail!$N$4:$N$500,Sales_Tax_Detail!$C$4:$C$500,$A15) -> 0 | E15: =SUMIFS(Sales_Tax_Detail!$O$4:$O$500,Sales_Tax_Detail!$C$4:$C$500,$A15) -> 0 | F15: =SUMIFS(Sales_Tax_Detail!$P$4:$P$500,Sales_Tax_Detail!$C$4:$C$500,$A15) -> 0 | G15: =SUMIFS(Sales_Tax_Detail!$Q$4:$Q$500,Sales_Tax_Detail!$C$4:$C$500,$A15) -> 0 | H15: =SUMIFS(Sales_Tax_Detail!$R$4:$R$500,Sales_Tax_Detail!$C$4:$C$500,$A15) -> 0 | I15: =SUMIFS(Sales_Tax_Detail!$S$4:$S$500,Sales_Tax_Detail!$C$4:$C$500,$A15) -> 0 | J15: =IF(I15>0,"Estimated","No estimated tax") -> No estimated tax
A17: Annual Total | B17: =SUM(B4:B15) -> 2445 | C17: =SUM(C4:C15) -> 970 | D17: =SUM(D4:D15) -> 6180 | E17: =SUM(E4:E15) -> 705 | F17: =SUM(F4:F15) -> 2126.5492 | G17: =SUM(G4:G15) -> 106.32746 | H17: =SUM(H4:H15) -> 212.12329 | I17: =SUM(I4:I15) -> 318.45075
A18: Sales tax as % of personal expense | B18: =IFERROR(I17/Formula_Hub!$B$6,0) -> 0.030917549

Sheet Formula_Hub
A1: Formula Hub
A2: All core calculations are centralized here.
A4: Included Analysis Months | B4: =SUM($K$28:$K$39) -> 2
A5: Total Income | B5: =SUM($B$28:$B$39) -> 12900
A6: Total Personal Expense | B6: =SUM($C$28:$C$39) -> 10300
A7: Average Monthly Personal Expense | B7: =IF($B$4=0,0,$B$6/$B$4) -> 5150
A8: Average Monthly Essential Expense | B8: =IF($B$4=0,0,SUM($D$28:$D$39)/$B$4) -> 4000
A9: Average Monthly Discretionary Expense | B9: =IF($B$4=0,0,SUM($E$28:$E$39)/$B$4) -> 1150
A10: Average Monthly Fixed Expense | B10: =IF($B$4=0,0,SUM($F$28:$F$39)/$B$4) -> 3167.5
A11: Average Monthly Variable Expense | B11: =IF($B$4=0,0,SUM($G$28:$G$39)/$B$4) -> 1727.5
A12: Average Monthly One-time Expense | B12: =IF($B$4=0,0,SUM($H$28:$H$39)/$B$4) -> 255
A13: Average Monthly Housing Expense | B13: =IF($B$4=0,0,SUM($I$28:$I$39)/$B$4) -> 3000
A14: Housing Expense Ratio | B14: =IFERROR($B$13/$B$7,0) -> 0.58252427
A15: Savings Rate | B15: =IFERROR(($B$5-$B$6)/$B$5,0) -> 0.20155039
A16: Cash Coverage Months | B16: =IFERROR(Input_Settings!$B$5/$B$7,0) -> 5.8252427
A17: Normal One-Year Living Reserve | B17: =B7*12 -> 61800
A18: Essential One-Year Living Reserve | B18: =B8*12 -> 48000
A19: Conservative One-Year Living Reserve | B19: =MAX($C$28:$C$39)*12 -> 63600
A20: Recommended Cash Reserve | B20: =MAX($B$7*Input_Settings!$B$8,Input_Settings!$B$9)+Input_Settings!$B$6 -> 62800
A21: Suggested Investable Cash | B21: =MAX(0,Input_Settings!$B$5-$B$20) -> 0
A22: Cash Shortfall | B22: =MAX(0,$B$20-Input_Settings!$B$5) -> 32800
A23: Cash Safety Level | B23: =IF($B$16>=12,"Safe",IF($B$16>=6,"Moderately Safe","Tight")) -> Tight
A24: Estimated Annual Sales Tax | B24: =Sales_Tax_Analysis!$I$17 -> 318.45075
A25: Sales Tax Estimate Status | B25: =IF(Sales_Tax_Settings!$B$5="Yes","Enabled","Disabled") -> Enabled
A27: Month | B27: Total Income | C27: Personal Expense | D27: Essential Expense | E27: Discretionary Expense | F27: Fixed Expense | G27: Variable Expense | H27: One-time Expense | I27: Housing Expense | J27: Net Cash Flow | K27: Included in Average | L27: Property Expense | M27: Investment Transfer | N27: Internal Transfer | O27: Estimated Sales Tax
A28: 2026-01 | B28: =SUMIFS(Income_Input!$D$4:$D$500,Income_Input!$B$4:$B$500,">="&DATE(VALUE(LEFT($A28,4)),VALUE(RIGHT($A28,2)),1),Income_Input!$B$4:$B$500,"<"&DATE(VALUE(LEFT($A28,4)),VALUE(RIGHT($A28,2))+1,1)) -> 6000 | C28: =SUMIFS(Expense_Input!$D$4:$D$500,Expense_Input!$B$4:$B$500,">="&DATE(VALUE(LEFT($A28,4)),VALUE(RIGHT($A28,2)),1),Expense_Input!$B$4:$B$500,"<"&DATE(VALUE(LEFT($A28,4)),VALUE(RIGHT($A28,2))+1,1),Expense_Input!$H$4:$H$500,"Personal Expense") -> 5000 | D28: =SUMIFS(Expense_Input!$D$4:$D$500,Expense_Input!$B$4:$B$500,">="&DATE(VALUE(LEFT($A28,4)),VALUE(RIGHT($A28,2)),1),Expense_Input!$B$4:$B$500,"<"&DATE(VALUE(LEFT($A28,4)),VALUE(RIGHT($A28,2))+1,1),Expense_Input!$H$4:$H$500,"Personal Expense",Expense_Input!$G$4:$G$500,"Essential") -> 3910 | E28: =SUMIFS(Expense_Input!$D$4:$D$500,Expense_Input!$B$4:$B$500,">="&DATE(VALUE(LEFT($A28,4)),VALUE(RIGHT($A28,2)),1),Expense_Input!$B$4:$B$500,"<"&DATE(VALUE(LEFT($A28,4)),VALUE(RIGHT($A28,2))+1,1),Expense_Input!$H$4:$H$500,"Personal Expense",Expense_Input!$G$4:$G$500,"Discretionary") -> 1090 | F28: =SUMIFS(Expense_Input!$D$4:$D$500,Expense_Input!$B$4:$B$500,">="&DATE(VALUE(LEFT($A28,4)),VALUE(RIGHT($A28,2)),1),Expense_Input!$B$4:$B$500,"<"&DATE(VALUE(LEFT($A28,4)),VALUE(RIGHT($A28,2))+1,1),Expense_Input!$H$4:$H$500,"Personal Expense",Expense_Input!$F$4:$F$500,"Fixed") -> 3160 | G28: =SUMIFS(Expense_Input!$D$4:$D$500,Expense_Input!$B$4:$B$500,">="&DATE(VALUE(LEFT($A28,4)),VALUE(RIGHT($A28,2)),1),Expense_Input!$B$4:$B$500,"<"&DATE(VALUE(LEFT($A28,4)),VALUE(RIGHT($A28,2))+1,1),Expense_Input!$H$4:$H$500,"Personal Expense",Expense_Input!$F$4:$F$500,"Variable") -> 1620 | H28: =SUMIFS(Expense_Input!$D$4:$D$500,Expense_Input!$B$4:$B$500,">="&DATE(VALUE(LEFT($A28,4)),VALUE(RIGHT($A28,2)),1),Expense_Input!$B$4:$B$500,"<"&DATE(VALUE(LEFT($A28,4)),VALUE(RIGHT($A28,2))+1,1),Expense_Input!$H$4:$H$500,"Personal Expense",Expense_Input!$F$4:$F$500,"One-time") -> 220 | I28: =SUMIFS(Expense_Input!$D$4:$D$500,Expense_Input!$B$4:$B$500,">="&DATE(VALUE(LEFT($A28,4)),VALUE(RIGHT($A28,2)),1),Expense_Input!$B$4:$B$500,"<"&DATE(VALUE(LEFT($A28,4)),VALUE(RIGHT($A28,2))+1,1),Expense_Input!$H$4:$H$500,"Personal Expense",Expense_Input!$E$4:$E$500,"Housing") -> 3000 | J28: =B28-C28 -> 1000 | K28: =IF(C28>0,1,0) -> 1 | L28: =SUMIFS(Expense_Input!$D$4:$D$500,Expense_Input!$B$4:$B$500,">="&DATE(VALUE(LEFT($A28,4)),VALUE(RIGHT($A28,2)),1),Expense_Input!$B$4:$B$500,"<"&DATE(VALUE(LEFT($A28,4)),VALUE(RIGHT($A28,2))+1,1),Expense_Input!$H$4:$H$500,"Property Expense") -> 0 | M28: =SUMIFS(Expense_Input!$D$4:$D$500,Expense_Input!$B$4:$B$500,">="&DATE(VALUE(LEFT($A28,4)),VALUE(RIGHT($A28,2)),1),Expense_Input!$B$4:$B$500,"<"&DATE(VALUE(LEFT($A28,4)),VALUE(RIGHT($A28,2))+1,1),Expense_Input!$H$4:$H$500,"Investment Transfer") -> 0 | N28: =SUMIFS(Expense_Input!$D$4:$D$500,Expense_Input!$B$4:$B$500,">="&DATE(VALUE(LEFT($A28,4)),VALUE(RIGHT($A28,2)),1),Expense_Input!$B$4:$B$500,"<"&DATE(VALUE(LEFT($A28,4)),VALUE(RIGHT($A28,2))+1,1),Expense_Input!$H$4:$H$500,"Internal Transfer") -> 0 | O28: =SUMIFS(Sales_Tax_Detail!$S$4:$S$500,Sales_Tax_Detail!$C$4:$C$500,$A28) -> 148.4801
A29: 2026-02 | B29: =SUMIFS(Income_Input!$D$4:$D$500,Income_Input!$B$4:$B$500,">="&DATE(VALUE(LEFT($A29,4)),VALUE(RIGHT($A29,2)),1),Income_Input!$B$4:$B$500,"<"&DATE(VALUE(LEFT($A29,4)),VALUE(RIGHT($A29,2))+1,1)) -> 6900 | C29: =SUMIFS(Expense_Input!$D$4:$D$500,Expense_Input!$B$4:$B$500,">="&DATE(VALUE(LEFT($A29,4)),VALUE(RIGHT($A29,2)),1),Expense_Input!$B$4:$B$500,"<"&DATE(VALUE(LEFT($A29,4)),VALUE(RIGHT($A29,2))+1,1),Expense_Input!$H$4:$H$500,"Personal Expense") -> 5300 | D29: =SUMIFS(Expense_Input!$D$4:$D$500,Expense_Input!$B$4:$B$500,">="&DATE(VALUE(LEFT($A29,4)),VALUE(RIGHT($A29,2)),1),Expense_Input!$B$4:$B$500,"<"&DATE(VALUE(LEFT($A29,4)),VALUE(RIGHT($A29,2))+1,1),Expense_Input!$H$4:$H$500,"Personal Expense",Expense_Input!$G$4:$G$500,"Essential") -> 4090 | E29: =SUMIFS(Expense_Input!$D$4:$D$500,Expense_Input!$B$4:$B$500,">="&DATE(VALUE(LEFT($A29,4)),VALUE(RIGHT($A29,2)),1),Expense_Input!$B$4:$B$500,"<"&DATE(VALUE(LEFT($A29,4)),VALUE(RIGHT($A29,2))+1,1),Expense_Input!$H$4:$H$500,"Personal Expense",Expense_Input!$G$4:$G$500,"Discretionary") -> 1210 | F29: =SUMIFS(Expense_Input!$D$4:$D$500,Expense_Input!$B$4:$B$500,">="&DATE(VALUE(LEFT($A29,4)),VALUE(RIGHT($A29,2)),1),Expense_Input!$B$4:$B$500,"<"&DATE(VALUE(LEFT($A29,4)),VALUE(RIGHT($A29,2))+1,1),Expense_Input!$H$4:$H$500,"Personal Expense",Expense_Input!$F$4:$F$500,"Fixed") -> 3175 | G29: =SUMIFS(Expense_Input!$D$4:$D$500,Expense_Input!$B$4:$B$500,">="&DATE(VALUE(LEFT($A29,4)),VALUE(RIGHT($A29,2)),1),Expense_Input!$B$4:$B$500,"<"&DATE(VALUE(LEFT($A29,4)),VALUE(RIGHT($A29,2))+1,1),Expense_Input!$H$4:$H$500,"Personal Expense",Expense_Input!$F$4:$F$500,"Variable") -> 1835 | H29: =SUMIFS(Expense_Input!$D$4:$D$500,Expense_Input!$B$4:$B$500,">="&DATE(VALUE(LEFT($A29,4)),VALUE(RIGHT($A29,2)),1),Expense_Input!$B$4:$B$500,"<"&DATE(VALUE(LEFT($A29,4)),VALUE(RIGHT($A29,2))+1,1),Expense_Input!$H$4:$H$500,"Personal Expense",Expense_Input!$F$4:$F$500,"One-time") -> 290 | I29: =SUMIFS(Expense_Input!$D$4:$D$500,Expense_Input!$B$4:$B$500,">="&DATE(VALUE(LEFT($A29,4)),VALUE(RIGHT($A29,2)),1),Expense_Input!$B$4:$B$500,"<"&DATE(VALUE(LEFT($A29,4)),VALUE(RIGHT($A29,2))+1,1),Expense_Input!$H$4:$H$500,"Personal Expense",Expense_Input!$E$4:$E$500,"Housing") -> 3000 | J29: =B29-C29 -> 1600 | K29: =IF(C29>0,1,0) -> 1 | L29: =SUMIFS(Expense_Input!$D$4:$D$500,Expense_Input!$B$4:$B$500,">="&DATE(VALUE(LEFT($A29,4)),VALUE(RIGHT($A29,2)),1),Expense_Input!$B$4:$B$500,"<"&DATE(VALUE(LEFT($A29,4)),VALUE(RIGHT($A29,2))+1,1),Expense_Input!$H$4:$H$500,"Property Expense") -> 0 | M29: =SUMIFS(Expense_Input!$D$4:$D$500,Expense_Input!$B$4:$B$500,">="&DATE(VALUE(LEFT($A29,4)),VALUE(RIGHT($A29,2)),1),Expense_Input!$B$4:$B$500,"<"&DATE(VALUE(LEFT($A29,4)),VALUE(RIGHT($A29,2))+1,1),Expense_Input!$H$4:$H$500,"Investment Transfer") -> 0 | N29: =SUMIFS(Expense_Input!$D$4:$D$500,Expense_Input!$B$4:$B$500,">="&DATE(VALUE(LEFT($A29,4)),VALUE(RIGHT($A29,2)),1),Expense_Input!$B$4:$B$500,"<"&DATE(VALUE(LEFT($A29,4)),VALUE(RIGHT($A29,2))+1,1),Expense_Input!$H$4:$H$500,"Internal Transfer") -> 0 | O29: =SUMIFS(Sales_Tax_Detail!$S$4:$S$500,Sales_Tax_Detail!$C$4:$C$500,$A29) -> 169.97065
A30: 2026-03 | B30: =SUMIFS(Income_Input!$D$4:$D$500,Income_Input!$B$4:$B$500,">="&DATE(VALUE(LEFT($A30,4)),VALUE(RIGHT($A30,2)),1),Income_Input!$B$4:$B$500,"<"&DATE(VALUE(LEFT($A30,4)),VALUE(RIGHT($A30,2))+1,1)) -> 0 | C30: =SUMIFS(Expense_Input!$D$4:$D$500,Expense_Input!$B$4:$B$500,">="&DATE(VALUE(LEFT($A30,4)),VALUE(RIGHT($A30,2)),1),Expense_Input!$B$4:$B$500,"<"&DATE(VALUE(LEFT($A30,4)),VALUE(RIGHT($A30,2))+1,1),Expense_Input!$H$4:$H$500,"Personal Expense") -> 0 | D30: =SUMIFS(Expense_Input!$D$4:$D$500,Expense_Input!$B$4:$B$500,">="&DATE(VALUE(LEFT($A30,4)),VALUE(RIGHT($A30,2)),1),Expense_Input!$B$4:$B$500,"<"&DATE(VALUE(LEFT($A30,4)),VALUE(RIGHT($A30,2))+1,1),Expense_Input!$H$4:$H$500,"Personal Expense",Expense_Input!$G$4:$G$500,"Essential") -> 0 | E30: =SUMIFS(Expense_Input!$D$4:$D$500,Expense_Input!$B$4:$B$500,">="&DATE(VALUE(LEFT($A30,4)),VALUE(RIGHT($A30,2)),1),Expense_Input!$B$4:$B$500,"<"&DATE(VALUE(LEFT($A30,4)),VALUE(RIGHT($A30,2))+1,1),Expense_Input!$H$4:$H$500,"Personal Expense",Expense_Input!$G$4:$G$500,"Discretionary") -> 0 | F30: =SUMIFS(Expense_Input!$D$4:$D$500,Expense_Input!$B$4:$B$500,">="&DATE(VALUE(LEFT($A30,4)),VALUE(RIGHT($A30,2)),1),Expense_Input!$B$4:$B$500,"<"&DATE(VALUE(LEFT($A30,4)),VALUE(RIGHT($A30,2))+1,1),Expense_Input!$H$4:$H$500,"Personal Expense",Expense_Input!$F$4:$F$500,"Fixed") -> 0 | G30: =SUMIFS(Expense_Input!$D$4:$D$500,Expense_Input!$B$4:$B$500,">="&DATE(VALUE(LEFT($A30,4)),VALUE(RIGHT($A30,2)),1),Expense_Input!$B$4:$B$500,"<"&DATE(VALUE(LEFT($A30,4)),VALUE(RIGHT($A30,2))+1,1),Expense_Input!$H$4:$H$500,"Personal Expense",Expense_Input!$F$4:$F$500,"Variable") -> 0 | H30: =SUMIFS(Expense_Input!$D$4:$D$500,Expense_Input!$B$4:$B$500,">="&DATE(VALUE(LEFT($A30,4)),VALUE(RIGHT($A30,2)),1),Expense_Input!$B$4:$B$500,"<"&DATE(VALUE(LEFT($A30,4)),VALUE(RIGHT($A30,2))+1,1),Expense_Input!$H$4:$H$500,"Personal Expense",Expense_Input!$F$4:$F$500,"One-time") -> 0 | I30: =SUMIFS(Expense_Input!$D$4:$D$500,Expense_Input!$B$4:$B$500,">="&DATE(VALUE(LEFT($A30,4)),VALUE(RIGHT($A30,2)),1),Expense_Input!$B$4:$B$500,"<"&DATE(VALUE(LEFT($A30,4)),VALUE(RIGHT($A30,2))+1,1),Expense_Input!$H$4:$H$500,"Personal Expense",Expense_Input!$E$4:$E$500,"Housing") -> 0 | J30: =B30-C30 -> 0 | K30: =IF(C30>0,1,0) -> 0 | L30: =SUMIFS(Expense_Input!$D$4:$D$500,Expense_Input!$B$4:$B$500,">="&DATE(VALUE(LEFT($A30,4)),VALUE(RIGHT($A30,2)),1),Expense_Input!$B$4:$B$500,"<"&DATE(VALUE(LEFT($A30,4)),VALUE(RIGHT($A30,2))+1,1),Expense_Input!$H$4:$H$500,"Property Expense") -> 0 | M30: =SUMIFS(Expense_Input!$D$4:$D$500,Expense_Input!$B$4:$B$500,">="&DATE(VALUE(LEFT($A30,4)),VALUE(RIGHT($A30,2)),1),Expense_Input!$B$4:$B$500,"<"&DATE(VALUE(LEFT($A30,4)),VALUE(RIGHT($A30,2))+1,1),Expense_Input!$H$4:$H$500,"Investment Transfer") -> 0 | N30: =SUMIFS(Expense_Input!$D$4:$D$500,Expense_Input!$B$4:$B$500,">="&DATE(VALUE(LEFT($A30,4)),VALUE(RIGHT($A30,2)),1),Expense_Input!$B$4:$B$500,"<"&DATE(VALUE(LEFT($A30,4)),VALUE(RIGHT($A30,2))+1,1),Expense_Input!$H$4:$H$500,"Internal Transfer") -> 0 | O30: =SUMIFS(Sales_Tax_Detail!$S$4:$S$500,Sales_Tax_Detail!$C$4:$C$500,$A30) -> 0
A31: 2026-04 | B31: =SUMIFS(Income_Input!$D$4:$D$500,Income_Input!$B$4:$B$500,">="&DATE(VALUE(LEFT($A31,4)),VALUE(RIGHT($A31,2)),1),Income_Input!$B$4:$B$500,"<"&DATE(VALUE(LEFT($A31,4)),VALUE(RIGHT($A31,2))+1,1)) -> 0 | C31: =SUMIFS(Expense_Input!$D$4:$D$500,Expense_Input!$B$4:$B$500,">="&DATE(VALUE(LEFT($A31,4)),VALUE(RIGHT($A31,2)),1),Expense_Input!$B$4:$B$500,"<"&DATE(VALUE(LEFT($A31,4)),VALUE(RIGHT($A31,2))+1,1),Expense_Input!$H$4:$H$500,"Personal Expense") -> 0 | D31: =SUMIFS(Expense_Input!$D$4:$D$500,Expense_Input!$B$4:$B$500,">="&DATE(VALUE(LEFT($A31,4)),VALUE(RIGHT($A31,2)),1),Expense_Input!$B$4:$B$500,"<"&DATE(VALUE(LEFT($A31,4)),VALUE(RIGHT($A31,2))+1,1),Expense_Input!$H$4:$H$500,"Personal Expense",Expense_Input!$G$4:$G$500,"Essential") -> 0 | E31: =SUMIFS(Expense_Input!$D$4:$D$500,Expense_Input!$B$4:$B$500,">="&DATE(VALUE(LEFT($A31,4)),VALUE(RIGHT($A31,2)),1),Expense_Input!$B$4:$B$500,"<"&DATE(VALUE(LEFT($A31,4)),VALUE(RIGHT($A31,2))+1,1),Expense_Input!$H$4:$H$500,"Personal Expense",Expense_Input!$G$4:$G$500,"Discretionary") -> 0 | F31: =SUMIFS(Expense_Input!$D$4:$D$500,Expense_Input!$B$4:$B$500,">="&DATE(VALUE(LEFT($A31,4)),VALUE(RIGHT($A31,2)),1),Expense_Input!$B$4:$B$500,"<"&DATE(VALUE(LEFT($A31,4)),VALUE(RIGHT($A31,2))+1,1),Expense_Input!$H$4:$H$500,"Personal Expense",Expense_Input!$F$4:$F$500,"Fixed") -> 0 | G31: =SUMIFS(Expense_Input!$D$4:$D$500,Expense_Input!$B$4:$B$500,">="&DATE(VALUE(LEFT($A31,4)),VALUE(RIGHT($A31,2)),1),Expense_Input!$B$4:$B$500,"<"&DATE(VALUE(LEFT($A31,4)),VALUE(RIGHT($A31,2))+1,1),Expense_Input!$H$4:$H$500,"Personal Expense",Expense_Input!$F$4:$F$500,"Variable") -> 0 | H31: =SUMIFS(Expense_Input!$D$4:$D$500,Expense_Input!$B$4:$B$500,">="&DATE(VALUE(LEFT($A31,4)),VALUE(RIGHT($A31,2)),1),Expense_Input!$B$4:$B$500,"<"&DATE(VALUE(LEFT($A31,4)),VALUE(RIGHT($A31,2))+1,1),Expense_Input!$H$4:$H$500,"Personal Expense",Expense_Input!$F$4:$F$500,"One-time") -> 0 | I31: =SUMIFS(Expense_Input!$D$4:$D$500,Expense_Input!$B$4:$B$500,">="&DATE(VALUE(LEFT($A31,4)),VALUE(RIGHT($A31,2)),1),Expense_Input!$B$4:$B$500,"<"&DATE(VALUE(LEFT($A31,4)),VALUE(RIGHT($A31,2))+1,1),Expense_Input!$H$4:$H$500,"Personal Expense",Expense_Input!$E$4:$E$500,"Housing") -> 0 | J31: =B31-C31 -> 0 | K31: =IF(C31>0,1,0) -> 0 | L31: =SUMIFS(Expense_Input!$D$4:$D$500,Expense_Input!$B$4:$B$500,">="&DATE(VALUE(LEFT($A31,4)),VALUE(RIGHT($A31,2)),1),Expense_Input!$B$4:$B$500,"<"&DATE(VALUE(LEFT($A31,4)),VALUE(RIGHT($A31,2))+1,1),Expense_Input!$H$4:$H$500,"Property Expense") -> 0 | M31: =SUMIFS(Expense_Input!$D$4:$D$500,Expense_Input!$B$4:$B$500,">="&DATE(VALUE(LEFT($A31,4)),VALUE(RIGHT($A31,2)),1),Expense_Input!$B$4:$B$500,"<"&DATE(VALUE(LEFT($A31,4)),VALUE(RIGHT($A31,2))+1,1),Expense_Input!$H$4:$H$500,"Investment Transfer") -> 0 | N31: =SUMIFS(Expense_Input!$D$4:$D$500,Expense_Input!$B$4:$B$500,">="&DATE(VALUE(LEFT($A31,4)),VALUE(RIGHT($A31,2)),1),Expense_Input!$B$4:$B$500,"<"&DATE(VALUE(LEFT($A31,4)),VALUE(RIGHT($A31,2))+1,1),Expense_Input!$H$4:$H$500,"Internal Transfer") -> 0 | O31: =SUMIFS(Sales_Tax_Detail!$S$4:$S$500,Sales_Tax_Detail!$C$4:$C$500,$A31) -> 0
A32: 2026-05 | B32: =SUMIFS(Income_Input!$D$4:$D$500,Income_Input!$B$4:$B$500,">="&DATE(VALUE(LEFT($A32,4)),VALUE(RIGHT($A32,2)),1),Income_Input!$B$4:$B$500,"<"&DATE(VALUE(LEFT($A32,4)),VALUE(RIGHT($A32,2))+1,1)) -> 0 | C32: =SUMIFS(Expense_Input!$D$4:$D$500,Expense_Input!$B$4:$B$500,">="&DATE(VALUE(LEFT($A32,4)),VALUE(RIGHT($A32,2)),1),Expense_Input!$B$4:$B$500,"<"&DATE(VALUE(LEFT($A32,4)),VALUE(RIGHT($A32,2))+1,1),Expense_Input!$H$4:$H$500,"Personal Expense") -> 0 | D32: =SUMIFS(Expense_Input!$D$4:$D$500,Expense_Input!$B$4:$B$500,">="&DATE(VALUE(LEFT($A32,4)),VALUE(RIGHT($A32,2)),1),Expense_Input!$B$4:$B$500,"<"&DATE(VALUE(LEFT($A32,4)),VALUE(RIGHT($A32,2))+1,1),Expense_Input!$H$4:$H$500,"Personal Expense",Expense_Input!$G$4:$G$500,"Essential") -> 0 | E32: =SUMIFS(Expense_Input!$D$4:$D$500,Expense_Input!$B$4:$B$500,">="&DATE(VALUE(LEFT($A32,4)),VALUE(RIGHT($A32,2)),1),Expense_Input!$B$4:$B$500,"<"&DATE(VALUE(LEFT($A32,4)),VALUE(RIGHT($A32,2))+1,1),Expense_Input!$H$4:$H$500,"Personal Expense",Expense_Input!$G$4:$G$500,"Discretionary") -> 0 | F32: =SUMIFS(Expense_Input!$D$4:$D$500,Expense_Input!$B$4:$B$500,">="&DATE(VALUE(LEFT($A32,4)),VALUE(RIGHT($A32,2)),1),Expense_Input!$B$4:$B$500,"<"&DATE(VALUE(LEFT($A32,4)),VALUE(RIGHT($A32,2))+1,1),Expense_Input!$H$4:$H$500,"Personal Expense",Expense_Input!$F$4:$F$500,"Fixed") -> 0 | G32: =SUMIFS(Expense_Input!$D$4:$D$500,Expense_Input!$B$4:$B$500,">="&DATE(VALUE(LEFT($A32,4)),VALUE(RIGHT($A32,2)),1),Expense_Input!$B$4:$B$500,"<"&DATE(VALUE(LEFT($A32,4)),VALUE(RIGHT($A32,2))+1,1),Expense_Input!$H$4:$H$500,"Personal Expense",Expense_Input!$F$4:$F$500,"Variable") -> 0 | H32: =SUMIFS(Expense_Input!$D$4:$D$500,Expense_Input!$B$4:$B$500,">="&DATE(VALUE(LEFT($A32,4)),VALUE(RIGHT($A32,2)),1),Expense_Input!$B$4:$B$500,"<"&DATE(VALUE(LEFT($A32,4)),VALUE(RIGHT($A32,2))+1,1),Expense_Input!$H$4:$H$500,"Personal Expense",Expense_Input!$F$4:$F$500,"One-time") -> 0 | I32: =SUMIFS(Expense_Input!$D$4:$D$500,Expense_Input!$B$4:$B$500,">="&DATE(VALUE(LEFT($A32,4)),VALUE(RIGHT($A32,2)),1),Expense_Input!$B$4:$B$500,"<"&DATE(VALUE(LEFT($A32,4)),VALUE(RIGHT($A32,2))+1,1),Expense_Input!$H$4:$H$500,"Personal Expense",Expense_Input!$E$4:$E$500,"Housing") -> 0 | J32: =B32-C32 -> 0 | K32: =IF(C32>0,1,0) -> 0 | L32: =SUMIFS(Expense_Input!$D$4:$D$500,Expense_Input!$B$4:$B$500,">="&DATE(VALUE(LEFT($A32,4)),VALUE(RIGHT($A32,2)),1),Expense_Input!$B$4:$B$500,"<"&DATE(VALUE(LEFT($A32,4)),VALUE(RIGHT($A32,2))+1,1),Expense_Input!$H$4:$H$500,"Property Expense") -> 0 | M32: =SUMIFS(Expense_Input!$D$4:$D$500,Expense_Input!$B$4:$B$500,">="&DATE(VALUE(LEFT($A32,4)),VALUE(RIGHT($A32,2)),1),Expense_Input!$B$4:$B$500,"<"&DATE(VALUE(LEFT($A32,4)),VALUE(RIGHT($A32,2))+1,1),Expense_Input!$H$4:$H$500,"Investment Transfer") -> 0 | N32: =SUMIFS(Expense_Input!$D$4:$D$500,Expense_Input!$B$4:$B$500,">="&DATE(VALUE(LEFT($A32,4)),VALUE(RIGHT($A32,2)),1),Expense_Input!$B$4:$B$500,"<"&DATE(VALUE(LEFT($A32,4)),VALUE(RIGHT($A32,2))+1,1),Expense_Input!$H$4:$H$500,"Internal Transfer") -> 0 | O32: =SUMIFS(Sales_Tax_Detail!$S$4:$S$500,Sales_Tax_Detail!$C$4:$C$500,$A32) -> 0
A33: 2026-06 | B33: =SUMIFS(Income_Input!$D$4:$D$500,Income_Input!$B$4:$B$500,">="&DATE(VALUE(LEFT($A33,4)),VALUE(RIGHT($A33,2)),1),Income_Input!$B$4:$B$500,"<"&DATE(VALUE(LEFT($A33,4)),VALUE(RIGHT($A33,2))+1,1)) -> 0 | C33: =SUMIFS(Expense_Input!$D$4:$D$500,Expense_Input!$B$4:$B$500,">="&DATE(VALUE(LEFT($A33,4)),VALUE(RIGHT($A33,2)),1),Expense_Input!$B$4:$B$500,"<"&DATE(VALUE(LEFT($A33,4)),VALUE(RIGHT($A33,2))+1,1),Expense_Input!$H$4:$H$500,"Personal Expense") -> 0 | D33: =SUMIFS(Expense_Input!$D$4:$D$500,Expense_Input!$B$4:$B$500,">="&DATE(VALUE(LEFT($A33,4)),VALUE(RIGHT($A33,2)),1),Expense_Input!$B$4:$B$500,"<"&DATE(VALUE(LEFT($A33,4)),VALUE(RIGHT($A33,2))+1,1),Expense_Input!$H$4:$H$500,"Personal Expense",Expense_Input!$G$4:$G$500,"Essential") -> 0 | E33: =SUMIFS(Expense_Input!$D$4:$D$500,Expense_Input!$B$4:$B$500,">="&DATE(VALUE(LEFT($A33,4)),VALUE(RIGHT($A33,2)),1),Expense_Input!$B$4:$B$500,"<"&DATE(VALUE(LEFT($A33,4)),VALUE(RIGHT($A33,2))+1,1),Expense_Input!$H$4:$H$500,"Personal Expense",Expense_Input!$G$4:$G$500,"Discretionary") -> 0 | F33: =SUMIFS(Expense_Input!$D$4:$D$500,Expense_Input!$B$4:$B$500,">="&DATE(VALUE(LEFT($A33,4)),VALUE(RIGHT($A33,2)),1),Expense_Input!$B$4:$B$500,"<"&DATE(VALUE(LEFT($A33,4)),VALUE(RIGHT($A33,2))+1,1),Expense_Input!$H$4:$H$500,"Personal Expense",Expense_Input!$F$4:$F$500,"Fixed") -> 0 | G33: =SUMIFS(Expense_Input!$D$4:$D$500,Expense_Input!$B$4:$B$500,">="&DATE(VALUE(LEFT($A33,4)),VALUE(RIGHT($A33,2)),1),Expense_Input!$B$4:$B$500,"<"&DATE(VALUE(LEFT($A33,4)),VALUE(RIGHT($A33,2))+1,1),Expense_Input!$H$4:$H$500,"Personal Expense",Expense_Input!$F$4:$F$500,"Variable") -> 0 | H33: =SUMIFS(Expense_Input!$D$4:$D$500,Expense_Input!$B$4:$B$500,">="&DATE(VALUE(LEFT($A33,4)),VALUE(RIGHT($A33,2)),1),Expense_Input!$B$4:$B$500,"<"&DATE(VALUE(LEFT($A33,4)),VALUE(RIGHT($A33,2))+1,1),Expense_Input!$H$4:$H$500,"Personal Expense",Expense_Input!$F$4:$F$500,"One-time") -> 0 | I33: =SUMIFS(Expense_Input!$D$4:$D$500,Expense_Input!$B$4:$B$500,">="&DATE(VALUE(LEFT($A33,4)),VALUE(RIGHT($A33,2)),1),Expense_Input!$B$4:$B$500,"<"&DATE(VALUE(LEFT($A33,4)),VALUE(RIGHT($A33,2))+1,1),Expense_Input!$H$4:$H$500,"Personal Expense",Expense_Input!$E$4:$E$500,"Housing") -> 0 | J33: =B33-C33 -> 0 | K33: =IF(C33>0,1,0) -> 0 | L33: =SUMIFS(Expense_Input!$D$4:$D$500,Expense_Input!$B$4:$B$500,">="&DATE(VALUE(LEFT($A33,4)),VALUE(RIGHT($A33,2)),1),Expense_Input!$B$4:$B$500,"<"&DATE(VALUE(LEFT($A33,4)),VALUE(RIGHT($A33,2))+1,1),Expense_Input!$H$4:$H$500,"Property Expense") -> 0 | M33: =SUMIFS(Expense_Input!$D$4:$D$500,Expense_Input!$B$4:$B$500,">="&DATE(VALUE(LEFT($A33,4)),VALUE(RIGHT($A33,2)),1),Expense_Input!$B$4:$B$500,"<"&DATE(VALUE(LEFT($A33,4)),VALUE(RIGHT($A33,2))+1,1),Expense_Input!$H$4:$H$500,"Investment Transfer") -> 0 | N33: =SUMIFS(Expense_Input!$D$4:$D$500,Expense_Input!$B$4:$B$500,">="&DATE(VALUE(LEFT($A33,4)),VALUE(RIGHT($A33,2)),1),Expense_Input!$B$4:$B$500,"<"&DATE(VALUE(LEFT($A33,4)),VALUE(RIGHT($A33,2))+1,1),Expense_Input!$H$4:$H$500,"Internal Transfer") -> 0 | O33: =SUMIFS(Sales_Tax_Detail!$S$4:$S$500,Sales_Tax_Detail!$C$4:$C$500,$A33) -> 0
A34: 2026-07 | B34: =SUMIFS(Income_Input!$D$4:$D$500,Income_Input!$B$4:$B$500,">="&DATE(VALUE(LEFT($A34,4)),VALUE(RIGHT($A34,2)),1),Income_Input!$B$4:$B$500,"<"&DATE(VALUE(LEFT($A34,4)),VALUE(RIGHT($A34,2))+1,1)) -> 0 | C34: =SUMIFS(Expense_Input!$D$4:$D$500,Expense_Input!$B$4:$B$500,">="&DATE(VALUE(LEFT($A34,4)),VALUE(RIGHT($A34,2)),1),Expense_Input!$B$4:$B$500,"<"&DATE(VALUE(LEFT($A34,4)),VALUE(RIGHT($A34,2))+1,1),Expense_Input!$H$4:$H$500,"Personal Expense") -> 0 | D34: =SUMIFS(Expense_Input!$D$4:$D$500,Expense_Input!$B$4:$B$500,">="&DATE(VALUE(LEFT($A34,4)),VALUE(RIGHT($A34,2)),1),Expense_Input!$B$4:$B$500,"<"&DATE(VALUE(LEFT($A34,4)),VALUE(RIGHT($A34,2))+1,1),Expense_Input!$H$4:$H$500,"Personal Expense",Expense_Input!$G$4:$G$500,"Essential") -> 0 | E34: =SUMIFS(Expense_Input!$D$4:$D$500,Expense_Input!$B$4:$B$500,">="&DATE(VALUE(LEFT($A34,4)),VALUE(RIGHT($A34,2)),1),Expense_Input!$B$4:$B$500,"<"&DATE(VALUE(LEFT($A34,4)),VALUE(RIGHT($A34,2))+1,1),Expense_Input!$H$4:$H$500,"Personal Expense",Expense_Input!$G$4:$G$500,"Discretionary") -> 0 | F34: =SUMIFS(Expense_Input!$D$4:$D$500,Expense_Input!$B$4:$B$500,">="&DATE(VALUE(LEFT($A34,4)),VALUE(RIGHT($A34,2)),1),Expense_Input!$B$4:$B$500,"<"&DATE(VALUE(LEFT($A34,4)),VALUE(RIGHT($A34,2))+1,1),Expense_Input!$H$4:$H$500,"Personal Expense",Expense_Input!$F$4:$F$500,"Fixed") -> 0 | G34: =SUMIFS(Expense_Input!$D$4:$D$500,Expense_Input!$B$4:$B$500,">="&DATE(VALUE(LEFT($A34,4)),VALUE(RIGHT($A34,2)),1),Expense_Input!$B$4:$B$500,"<"&DATE(VALUE(LEFT($A34,4)),VALUE(RIGHT($A34,2))+1,1),Expense_Input!$H$4:$H$500,"Personal Expense",Expense_Input!$F$4:$F$500,"Variable") -> 0 | H34: =SUMIFS(Expense_Input!$D$4:$D$500,Expense_Input!$B$4:$B$500,">="&DATE(VALUE(LEFT($A34,4)),VALUE(RIGHT($A34,2)),1),Expense_Input!$B$4:$B$500,"<"&DATE(VALUE(LEFT($A34,4)),VALUE(RIGHT($A34,2))+1,1),Expense_Input!$H$4:$H$500,"Personal Expense",Expense_Input!$F$4:$F$500,"One-time") -> 0 | I34: =SUMIFS(Expense_Input!$D$4:$D$500,Expense_Input!$B$4:$B$500,">="&DATE(VALUE(LEFT($A34,4)),VALUE(RIGHT($A34,2)),1),Expense_Input!$B$4:$B$500,"<"&DATE(VALUE(LEFT($A34,4)),VALUE(RIGHT($A34,2))+1,1),Expense_Input!$H$4:$H$500,"Personal Expense",Expense_Input!$E$4:$E$500,"Housing") -> 0 | J34: =B34-C34 -> 0 | K34: =IF(C34>0,1,0) -> 0 | L34: =SUMIFS(Expense_Input!$D$4:$D$500,Expense_Input!$B$4:$B$500,">="&DATE(VALUE(LEFT($A34,4)),VALUE(RIGHT($A34,2)),1),Expense_Input!$B$4:$B$500,"<"&DATE(VALUE(LEFT($A34,4)),VALUE(RIGHT($A34,2))+1,1),Expense_Input!$H$4:$H$500,"Property Expense") -> 0 | M34: =SUMIFS(Expense_Input!$D$4:$D$500,Expense_Input!$B$4:$B$500,">="&DATE(VALUE(LEFT($A34,4)),VALUE(RIGHT($A34,2)),1),Expense_Input!$B$4:$B$500,"<"&DATE(VALUE(LEFT($A34,4)),VALUE(RIGHT($A34,2))+1,1),Expense_Input!$H$4:$H$500,"Investment Transfer") -> 0 | N34: =SUMIFS(Expense_Input!$D$4:$D$500,Expense_Input!$B$4:$B$500,">="&DATE(VALUE(LEFT($A34,4)),VALUE(RIGHT($A34,2)),1),Expense_Input!$B$4:$B$500,"<"&DATE(VALUE(LEFT($A34,4)),VALUE(RIGHT($A34,2))+1,1),Expense_Input!$H$4:$H$500,"Internal Transfer") -> 0 | O34: =SUMIFS(Sales_Tax_Detail!$S$4:$S$500,Sales_Tax_Detail!$C$4:$C$500,$A34) -> 0
A35: 2026-08 | B35: =SUMIFS(Income_Input!$D$4:$D$500,Income_Input!$B$4:$B$500,">="&DATE(VALUE(LEFT($A35,4)),VALUE(RIGHT($A35,2)),1),Income_Input!$B$4:$B$500,"<"&DATE(VALUE(LEFT($A35,4)),VALUE(RIGHT($A35,2))+1,1)) -> 0 | C35: =SUMIFS(Expense_Input!$D$4:$D$500,Expense_Input!$B$4:$B$500,">="&DATE(VALUE(LEFT($A35,4)),VALUE(RIGHT($A35,2)),1),Expense_Input!$B$4:$B$500,"<"&DATE(VALUE(LEFT($A35,4)),VALUE(RIGHT($A35,2))+1,1),Expense_Input!$H$4:$H$500,"Personal Expense") -> 0 | D35: =SUMIFS(Expense_Input!$D$4:$D$500,Expense_Input!$B$4:$B$500,">="&DATE(VALUE(LEFT($A35,4)),VALUE(RIGHT($A35,2)),1),Expense_Input!$B$4:$B$500,"<"&DATE(VALUE(LEFT($A35,4)),VALUE(RIGHT($A35,2))+1,1),Expense_Input!$H$4:$H$500,"Personal Expense",Expense_Input!$G$4:$G$500,"Essential") -> 0 | E35: =SUMIFS(Expense_Input!$D$4:$D$500,Expense_Input!$B$4:$B$500,">="&DATE(VALUE(LEFT($A35,4)),VALUE(RIGHT($A35,2)),1),Expense_Input!$B$4:$B$500,"<"&DATE(VALUE(LEFT($A35,4)),VALUE(RIGHT($A35,2))+1,1),Expense_Input!$H$4:$H$500,"Personal Expense",Expense_Input!$G$4:$G$500,"Discretionary") -> 0 | F35: =SUMIFS(Expense_Input!$D$4:$D$500,Expense_Input!$B$4:$B$500,">="&DATE(VALUE(LEFT($A35,4)),VALUE(RIGHT($A35,2)),1),Expense_Input!$B$4:$B$500,"<"&DATE(VALUE(LEFT($A35,4)),VALUE(RIGHT($A35,2))+1,1),Expense_Input!$H$4:$H$500,"Personal Expense",Expense_Input!$F$4:$F$500,"Fixed") -> 0 | G35: =SUMIFS(Expense_Input!$D$4:$D$500,Expense_Input!$B$4:$B$500,">="&DATE(VALUE(LEFT($A35,4)),VALUE(RIGHT($A35,2)),1),Expense_Input!$B$4:$B$500,"<"&DATE(VALUE(LEFT($A35,4)),VALUE(RIGHT($A35,2))+1,1),Expense_Input!$H$4:$H$500,"Personal Expense",Expense_Input!$F$4:$F$500,"Variable") -> 0 | H35: =SUMIFS(Expense_Input!$D$4:$D$500,Expense_Input!$B$4:$B$500,">="&DATE(VALUE(LEFT($A35,4)),VALUE(RIGHT($A35,2)),1),Expense_Input!$B$4:$B$500,"<"&DATE(VALUE(LEFT($A35,4)),VALUE(RIGHT($A35,2))+1,1),Expense_Input!$H$4:$H$500,"Personal Expense",Expense_Input!$F$4:$F$500,"One-time") -> 0 | I35: =SUMIFS(Expense_Input!$D$4:$D$500,Expense_Input!$B$4:$B$500,">="&DATE(VALUE(LEFT($A35,4)),VALUE(RIGHT($A35,2)),1),Expense_Input!$B$4:$B$500,"<"&DATE(VALUE(LEFT($A35,4)),VALUE(RIGHT($A35,2))+1,1),Expense_Input!$H$4:$H$500,"Personal Expense",Expense_Input!$E$4:$E$500,"Housing") -> 0 | J35: =B35-C35 -> 0 | K35: =IF(C35>0,1,0) -> 0 | L35: =SUMIFS(Expense_Input!$D$4:$D$500,Expense_Input!$B$4:$B$500,">="&DATE(VALUE(LEFT($A35,4)),VALUE(RIGHT($A35,2)),1),Expense_Input!$B$4:$B$500,"<"&DATE(VALUE(LEFT($A35,4)),VALUE(RIGHT($A35,2))+1,1),Expense_Input!$H$4:$H$500,"Property Expense") -> 0 | M35: =SUMIFS(Expense_Input!$D$4:$D$500,Expense_Input!$B$4:$B$500,">="&DATE(VALUE(LEFT($A35,4)),VALUE(RIGHT($A35,2)),1),Expense_Input!$B$4:$B$500,"<"&DATE(VALUE(LEFT($A35,4)),VALUE(RIGHT($A35,2))+1,1),Expense_Input!$H$4:$H$500,"Investment Transfer") -> 0 | N35: =SUMIFS(Expense_Input!$D$4:$D$500,Expense_Input!$B$4:$B$500,">="&DATE(VALUE(LEFT($A35,4)),VALUE(RIGHT($A35,2)),1),Expense_Input!$B$4:$B$500,"<"&DATE(VALUE(LEFT($A35,4)),VALUE(RIGHT($A35,2))+1,1),Expense_Input!$H$4:$H$500,"Internal Transfer") -> 0 | O35: =SUMIFS(Sales_Tax_Detail!$S$4:$S$500,Sales_Tax_Detail!$C$4:$C$500,$A35) -> 0
A36: 2026-09 | B36: =SUMIFS(Income_Input!$D$4:$D$500,Income_Input!$B$4:$B$500,">="&DATE(VALUE(LEFT($A36,4)),VALUE(RIGHT($A36,2)),1),Income_Input!$B$4:$B$500,"<"&DATE(VALUE(LEFT($A36,4)),VALUE(RIGHT($A36,2))+1,1)) -> 0 | C36: =SUMIFS(Expense_Input!$D$4:$D$500,Expense_Input!$B$4:$B$500,">="&DATE(VALUE(LEFT($A36,4)),VALUE(RIGHT($A36,2)),1),Expense_Input!$B$4:$B$500,"<"&DATE(VALUE(LEFT($A36,4)),VALUE(RIGHT($A36,2))+1,1),Expense_Input!$H$4:$H$500,"Personal Expense") -> 0 | D36: =SUMIFS(Expense_Input!$D$4:$D$500,Expense_Input!$B$4:$B$500,">="&DATE(VALUE(LEFT($A36,4)),VALUE(RIGHT($A36,2)),1),Expense_Input!$B$4:$B$500,"<"&DATE(VALUE(LEFT($A36,4)),VALUE(RIGHT($A36,2))+1,1),Expense_Input!$H$4:$H$500,"Personal Expense",Expense_Input!$G$4:$G$500,"Essential") -> 0 | E36: =SUMIFS(Expense_Input!$D$4:$D$500,Expense_Input!$B$4:$B$500,">="&DATE(VALUE(LEFT($A36,4)),VALUE(RIGHT($A36,2)),1),Expense_Input!$B$4:$B$500,"<"&DATE(VALUE(LEFT($A36,4)),VALUE(RIGHT($A36,2))+1,1),Expense_Input!$H$4:$H$500,"Personal Expense",Expense_Input!$G$4:$G$500,"Discretionary") -> 0 | F36: =SUMIFS(Expense_Input!$D$4:$D$500,Expense_Input!$B$4:$B$500,">="&DATE(VALUE(LEFT($A36,4)),VALUE(RIGHT($A36,2)),1),Expense_Input!$B$4:$B$500,"<"&DATE(VALUE(LEFT($A36,4)),VALUE(RIGHT($A36,2))+1,1),Expense_Input!$H$4:$H$500,"Personal Expense",Expense_Input!$F$4:$F$500,"Fixed") -> 0 | G36: =SUMIFS(Expense_Input!$D$4:$D$500,Expense_Input!$B$4:$B$500,">="&DATE(VALUE(LEFT($A36,4)),VALUE(RIGHT($A36,2)),1),Expense_Input!$B$4:$B$500,"<"&DATE(VALUE(LEFT($A36,4)),VALUE(RIGHT($A36,2))+1,1),Expense_Input!$H$4:$H$500,"Personal Expense",Expense_Input!$F$4:$F$500,"Variable") -> 0 | H36: =SUMIFS(Expense_Input!$D$4:$D$500,Expense_Input!$B$4:$B$500,">="&DATE(VALUE(LEFT($A36,4)),VALUE(RIGHT($A36,2)),1),Expense_Input!$B$4:$B$500,"<"&DATE(VALUE(LEFT($A36,4)),VALUE(RIGHT($A36,2))+1,1),Expense_Input!$H$4:$H$500,"Personal Expense",Expense_Input!$F$4:$F$500,"One-time") -> 0 | I36: =SUMIFS(Expense_Input!$D$4:$D$500,Expense_Input!$B$4:$B$500,">="&DATE(VALUE(LEFT($A36,4)),VALUE(RIGHT($A36,2)),1),Expense_Input!$B$4:$B$500,"<"&DATE(VALUE(LEFT($A36,4)),VALUE(RIGHT($A36,2))+1,1),Expense_Input!$H$4:$H$500,"Personal Expense",Expense_Input!$E$4:$E$500,"Housing") -> 0 | J36: =B36-C36 -> 0 | K36: =IF(C36>0,1,0) -> 0 | L36: =SUMIFS(Expense_Input!$D$4:$D$500,Expense_Input!$B$4:$B$500,">="&DATE(VALUE(LEFT($A36,4)),VALUE(RIGHT($A36,2)),1),Expense_Input!$B$4:$B$500,"<"&DATE(VALUE(LEFT($A36,4)),VALUE(RIGHT($A36,2))+1,1),Expense_Input!$H$4:$H$500,"Property Expense") -> 0 | M36: =SUMIFS(Expense_Input!$D$4:$D$500,Expense_Input!$B$4:$B$500,">="&DATE(VALUE(LEFT($A36,4)),VALUE(RIGHT($A36,2)),1),Expense_Input!$B$4:$B$500,"<"&DATE(VALUE(LEFT($A36,4)),VALUE(RIGHT($A36,2))+1,1),Expense_Input!$H$4:$H$500,"Investment Transfer") -> 0 | N36: =SUMIFS(Expense_Input!$D$4:$D$500,Expense_Input!$B$4:$B$500,">="&DATE(VALUE(LEFT($A36,4)),VALUE(RIGHT($A36,2)),1),Expense_Input!$B$4:$B$500,"<"&DATE(VALUE(LEFT($A36,4)),VALUE(RIGHT($A36,2))+1,1),Expense_Input!$H$4:$H$500,"Internal Transfer") -> 0 | O36: =SUMIFS(Sales_Tax_Detail!$S$4:$S$500,Sales_Tax_Detail!$C$4:$C$500,$A36) -> 0
